Workbook

Sheet 摘要 Summary
A1: 加息及地緣政治 3 日觀察清單 R2.00
A2: 基準：2026-09-17 美東收市 · 涵蓋交易日：2026-09-18（五）、09-21（一）、09-22（二） · 生成：2026-09-18 09:00 HKT · claude-opus-5 / high
A4: 一、當前 regime：三個同時發生的衝擊
A5: 面向 | B5: 事件 | C5: 關鍵數字 | G5: 對股票的傳導
A6: 貨幣政策 | B6: 9/16 FOMC 加息 25bp 至 3.75–4.00%（2023 年 7 月以來首次，票數 12-0，主席 Kevin Warsh）。9/18 日本央行預期加息 25bp 至 1.25%，1993 年以來最高 | D6: 點陣圖：18 人中 16 人預期年內再加一次。但 9/17 十年期由 5.04% 的 19 年高位回落至 5.01%，**8 連升中斷**；兩年期 4.744% 仍為 2024 年 7 月以來最高 | G6: 9/16 與 9/17 是兩種相反的息率日：前者殺長久期資產，後者令同一批資產單日彈 1.3–8.0%。對息率方向下注 = 對這兩日的順序下注
A7: 地緣政治 | B7: 沙特 East–West 輸油管（Hormuz 的替代路線）9/10 遇襲後關閉。Aramco 繞過受損段，數日內恢復約一半運能，全面復原約需六週；同時改以 Hormuz 外 Sohar 附近船對船轉運補充亞洲買家 | D7: 9/17 Brent −$1.01 收 $104.82、WTI −$0.52 收 $101.91。美伊進入「油輪換油輪」互擊，停火談判多次破裂；戰爭險保費為船體價值 7.5–10%（戰前 0.25%） | G7: 原油供應在恢復，煉油產能沒有 —— 中東逾 20% 煉油產能實體損毀。這個落差就是裂解價差，也是本清單第①組的全部理由
A8: 成品油 | B8: 柴油裂解價差本月創歷史新高（$102–108/桶，正常夏季約 $20）。俄羅斯柴油出口禁令延至 9/30，8 月煉油量 380 萬桶/日為二十年最低；烏克蘭無人機已打掉約 280 萬桶俄煉油產能 | D8: 美國煉廠開工率 >97%；MPC 年內 +157%、VLO +152%，兩者股價均高於分析員共識目標價，評級以 Hold 居多 | G8: 機制最強但估值已伸展 —— 本版維持第①組但把「未伸展度」由 4 分降至 2 分
A10: 二、核心判斷
A11: • R1.01 的 3 日窗口第一日（9/17）已有結果：兩個「兩態皆贏」的判斷完全兌現（煉油 +2.53% 名次升至第 2、診斷工具 +3.08% 連續兩版第 1），但四個依賴「息率續升」的判斷全部落空，而被列為迴避的長久期資產反而是當日最大贏家（SMR +8.01%、量子 +7.99%、數位資產 +5.30%）。逐項對照見「判斷記分卡」頁。
A12: • 結構性教訓：上一版把「收保費 vs 持久期」（保險 vs 銀行）當成兩態皆贏的價差，其實它不是 —— 它是對息率方向的單邊下注，只在息率續升時成立。真正的兩態價差只有一個：裂解價差 vs 原油。
A13: • 因此本版只在兩態皆贏的部位上維持信心（第①②組），把依賴息率方向的部位兩邊都減注（第⑦組防守、B 類中性），並把 9/17 證明自己的組別升級（第③晶圓代工、④太空、⑤鋼鐵）。
A14: • 未來 3 日的分岔點不再是油價，而是息率：9/18 日本央行若鷹派加息觸發日圓套息平倉，就回到 9/16 的形態；若被消化，9/17 的長久期反彈會延續。同日是四巫日，倉位驅動的急升最易在此回吐。
A16: 三、清單統計（公式即時計算，隨清單頁改動更新）
A17: 指標 | B17: 數值 | D17: 指標 | E17: 數值 | G17: 說明
A18: 受惠股檔數 | B18: =COUNT('3日受惠清單 Watchlist'!Q9:Q28) -> 20 | D18: 迴避股檔數 | E18: =COUNTA('迴避清單 Avoid'!B9:B33) -> 25 | G18: 兩表合計覆蓋的美股檔數
A19: 受惠股平均綜合分 | B19: =AVERAGE('3日受惠清單 Watchlist'!Q9:Q28) -> 77.65 | D19: 受惠股 9/16 平均漲跌 | E19: =AVERAGE('3日受惠清單 Watchlist'!H9:H28) -> 0.020369016 | G19: 綜合分為 0–100，權重可於清單頁黃色格調整
A20: 綜合分 ≥ 80 檔數 | B20: =COUNTIF('3日受惠清單 Watchlist'!Q9:Q28,">=80") -> 10 | D20: 迴避股 9/16 平均漲跌 | E20: =AVERAGE('迴避清單 Avoid'!G9:G33) -> 0.021485284 | G20: 當日兩表平均表現差距即為輪動幅度
A21: 9/16 全市中位漲跌 | B21: 0.0023921569 | D21: 9/16 市場面板檔數 | E21: 1109 | G21: 來源：SubSector 資金流向 R12 引擎（本次重跑） 平衡市場面板
A23: 四、R1.01 判斷在 9/17 的結果與本版修正（逐項見「判斷記分卡」頁）
A24: R1.01 的判斷類別 | C24: 9/17 實際結果 | E24: 為何如此 | G24: 本版如何修正
A25: 兩態皆贏的判斷（煉油、診斷工具） | C25: 煉油 +2.53%、廣度 1.00、名次 4→2；診斷工具 +3.08%、廣度 1.00、連續兩版第 1 | E25: 這兩組的多頭邏輯不需要猜息率或油價方向：一個做多裂解價差、一個沒有油品投入也沒有久期 | G25: 維持核心；煉油因估值已高於共識目標，未伸展度由 4 降至 2
A26: 依賴「息率續升」的判斷（醫院、產險、電網） | C26: 醫院 −0.63% 廣度 0.00、名次 3→20；產險 −0.10% 廣度 0.00、名次 6→16；電網 +0.90% 名次 14→21 | E26: 這些被寫成「防守」與「收息受惠」，實際是對息率方向的單邊下注。9/17 息率一停升，三組同時失去相對優勢 | G26: 全部降級：醫院與產險移至第⑦組（只在狀態 B 成立），電網降至第⑥組
A27: 被低估的判斷（AI 半導體、鋼鐵） | C27: 晶圓代工 +6.43% 名次 38→9；EDA +3.20% 名次 37→23；鋼鐵 +2.81% 廣度 1.00 名次 11→6 | E27: 上一版把 AI 半導體列為「戰術小注、不建議追」，鋼鐵列為「觀察不建倉」。兩者都是當日前列，鋼鐵更是升勢有廣度且未伸展 | G27: AI 半導體升為第③組、鋼鐵升為第⑤組
A28: 被推翻的迴避（SMR、數位資產、建商、鈾、稀土、再生能源） | C28: SMR +8.01% 名次 108→54；量子 +7.99% 名次 69→15；數位資產 +5.30% 名次 104→51；建商 +1.29% 廣度 1.00 名次 44→17 | E28: 迴避理由是「長久期、無盈利、加息周期最先被殺」。這個理由在息率上升時正確，在息率暫停時反向成立 —— 被殺得最重的，反彈也最烈 | G28: 改列 B 類中性：不建議新倉，亦不再視為迴避；孳息若重上 5.1%，迴避理由即時恢復
A29: 已驗證的迴避（電信、油服、區域銀行、貨運） | C29: 電信 −3.43% 廣度 0.00，為 9/17 全 111 組最差，名次 33→100；油服反彈日仍 −0.42%；區域銀行 +0.33%；貨運 +0.76% | E29: 這四組在全巿反彈日依然落後 —— 機制不隨息率方向改變，是真正的結構性迴避 | G29: 維持 A 類迴避
A31: 本表為研究紀錄，非投資建議。所有判斷分數為分析員主觀評分，方法與限制見「數據來源與限制」頁。

Sheet 判斷記分卡 Scorecard
A1: R1.01 判斷記分卡（3 日窗口第 1 日：2026-09-17）
A2: D–H 欄直接讀自本次重跑的資金流數據，非人手填寫 · 名次為 111 個子板塊的 5 日綜合排名（1 = 最強）
A8: R1.01 類別 | B8: 子板塊 | C8: R1.01 當時的判斷 | D8: 9-17 漲跌% | E8: 9-17 廣度 | F8: R11 名次 | G8: R12 名次 | H8: 名次 變化 | I8: 判定 | J8: 本版如何處理
A9: ① 最高信心 | B9: 煉油與成品油 | C9: 做多裂解價差、做空原油；兩態皆贏 | D9: 0.02526658 | E9: 1 | F9: 4 | G9: 2 | H9: =F9-G9 -> 2 | I9: ✓ 正確 | J9: 維持第①組；未伸展度由 4 降至 2（VLO 年內 +152%、MPC +157%，已高於共識目標價）
A10: ② 高信心 | B10: 診斷與生命科學工具 | C10: 無油品投入、本土收入、無久期 | D10: 0.030787182 | E10: 1 | F10: 1 | G10: 1 | H10: =F10-G10 -> 0 | I10: ✓ 正確 | J10: 維持第②組；已伸展（5 日 +11.46%），改以 DHR 作為未追高的參與方式
A11: ② 高信心 | B11: 醫院與醫療服務 | C11: 資金流最確認的防守配置 | D11: -0.0062990703 | E11: 0 | F11: 3 | G11: 20 | H11: =F11-G11 -> -17 | I11: ✗ 錯誤 | J11: 降級至第⑦組。這其實是對息率方向的下注，不是對機制的下注
A12: ③ 買入 | B12: 電氣設備與電網 | C12: AI 用電中有訂單、有定價權的一邊 | D12: 0.0090420111 | E12: 0.6 | F12: 14 | G12: 21 | H12: =F12-G12 -> -7 | I12: ✗ 偏錯 | J12: 降至第⑥組；只有 ETN 單隻走強，組別廣度 0.60
A13: ④ 買入 | B13: 產險與再保 | C13: 唯一「想要」5% 孳息的金融 | D13: -0.00097026441 | E13: 0 | F13: 6 | G13: 16 | H13: =F13-G13 -> -10 | I13: ✗ 錯誤 | J13: 降級至第⑦組；浮存金邏輯在孳息見頂時失去邊際動力
A14: ⑤ 戰術小注 | B14: 晶圓代工/IDM | C14: 列為「反彈非趨勢、不建議追」 | D14: 0.064280367 | E14: 1 | F14: 38 | G14: 9 | H14: =F14-G14 -> 29 | I14: ✗ 低估 | J14: 升為第③組；9/17 為當日第 4 強，5 日綜合升 29 位
A15: ⑤ 戰術小注 | B15: EDA與半導體IP | C15: 同上 | D15: 0.032002718 | E15: 1 | F15: 37 | G15: 23 | H15: =F15-G15 -> 14 | I15: ✗ 低估 | J15: 升為第③組
A16: ⑥ 觀察不建倉 | B16: 鋼鐵 | C16: 「方向未確立」 | D16: 0.028115285 | E16: 1 | F16: 11 | G16: 6 | H16: =F16-G16 -> 5 | I16: ✗ 低估 | J16: 升為第⑤組；升勢有廣度（9/17 廣度 1.00）且未伸展
A17: 未列入 | B17: 太空與衛星 | C17: R1.01 完全未提及 | D17: 0.063567483 | E17: 1 | F17: 40 | G17: 8 | H17: =F17-G17 -> 32 | I17: ✗ 遺漏 | J17: 新增為第④組；斜率 +0.62 為全表第二高
A18: ✕ 迴避 | B18: 電信營運商 | C18: 5% 無風險利率壓縮股息吸引力 | D18: -0.034337513 | E18: 0 | F18: 33 | G18: 100 | H18: =F18-G18 -> -67 | I18: ✓ 完全正確 | J18: 維持 A 類迴避；9/17 為全 111 組最差
A19: ✕ 迴避 | B19: 油田服務 | C19: 擁擠多倉解除 | D19: -0.0042154099 | E19: 0.25 | F19: 101 | G19: 103 | H19: =F19-G19 -> -2 | I19: ✓ 正確 | J19: 維持 A 類迴避；反彈日仍然下跌
A20: ✕ 迴避 | B20: 區域與社區銀行 | C20: 持債虧損 + 存款成本 + CRE | D20: 0.0032847186 | E20: 0.4 | F20: 89 | G20: 104 | H20: =F20-G20 -> -15 | I20: ✓ 正確 | J20: 維持 A 類迴避
... A31: ✕ 迴避 | B31: 頁岩E&P勘探生產 | C31: 擁擠多倉在 8.31x 成交量下爆掉 | D31: 0.0048255952 | E31: 0.6 | F31: 45 | G31: 44 | H31: =F31-G31 -> 1 | I31: ○ 中性 | J31: 9/17 只 +0.48%，名次 45→44；擠擁已解除，但未見新買盤
B33: 判定統計
B34: ✓ 正確 | C34: =COUNTIF(I9:I31,"✓*") -> 8 | D34: =C34/COUNTA($I$9:$I$31) -> 0.34782609
B35: ✗ 錯誤 | C35: =COUNTIF(I9:I31,"✗*") -> 14 | D35: =C35/COUNTA($I$9:$I$31) -> 0.60869565
B36: ○ 中性 | C36: =COUNTIF(I9:I31,"○*") -> 1 | D36: =C36/COUNTA($I$9:$I$31) -> 0.043478261
B38: 本頁存在的理由：一份 3 日清單如果沒有逐日對照，就永遠不會知道自己錯在哪裡。9/17 的結論很集中 —— 凡是「不需要猜息率方向」的判斷全部正確（煉油、診斷工具，以及五組結構性迴避），凡是「押注息率續升」的判斷全部落空（醫院、產險、電網），而凡是「因為息率上升而迴避」的，在息率一停升時就全部反彈。

Sheet 3日受惠清單 Watchlist
A1: 3 日受惠股清單 Rate-Hike & Geopolitical 3-Day Watchlist R2.00
A2: 基準 2026-09-17 美東收市 · H/I/L/Q 欄為公式，黑字＝公式、藍字＝輸入值、黃底＝可調整假設 · 代號可點擊開 TradingView 圖表
M4: 綜合分權重（黃底＝可調整輸入，改動後 Q 欄即時重算）
M5: 機制強度 | N5: 資金流確認 | O5: 未伸展度 | P5: 廣度 | Q5: 合計
M6: 0.4 | N6: 0.25 | O6: 0.2 | P6: 0.15 | Q6: =SUM(M6:P6) -> 1
A8: 組別 | B8: 主題板塊 | C8: 代號 | D8: 公司 | E8: 收市 09-17 | F8: 前收 09-16 | G8: 5日前收 09-10 | H8: 09-17 漲跌% | I8: 5日 漲跌% | J8: 09-17 成交量 | K8: 20日 中位量 | L8: 相對量 | M8: 機制 0-5 | N8: 資金流 0-5 | O8: 未伸展 0-5 | P8: 廣度 0-5 | Q8: 綜合分 0-100 | R8: 受惠機制（為何這 3 日會贏） | S8: 狀態A：油續跌 | T8: 狀態B：油再爆 | U8: 失效條件 / 注意
A9: ① | B9: 煉油與成品油 | C9: VLO | D9: Valero Energy | E9: 412.33 | F9: 403.28 | G9: 385.43 | H9: =E9/F9-1 -> 0.022440984 | I9: =E9/G9-1 -> 0.06979218 | J9: 2741747 | K9: 2735900 | L9: =J9/K9 -> 1.0021371 | M9: 5 | N9: 5 | O9: 2 | P9: 5 | Q9: =(M9*$M$6+N9*$N$6+O9*$O$6+P9*$P$6)*20 -> 88 | R9: 做多裂解價差、做空原油。9/17 組別 +2.53%、廣度 1.00，5 日綜合由第 4 升至第 2，斜率 +0.62。機制未變：Aramco 只能在數日內恢復約一半管線運能，全面復原約需六週；中東逾 20% 煉油產能實體損毀不會隨管線修復而回來 | S9: 強（原料成本回落、裂解維持） | T9: 強（成品油價領先原油） | U9: ⚠ 已伸展：VLO 年內 +152%、MPC +157%，均高於分析員目標價（VLO $355 對 $405、MPC $370 對 $413），評級以 Hold 居多。俄羅斯柴油出口禁令 9/30 到期不續則裂解回落
A10: ① | B10: 煉油與成品油 | C10: MPC | D10: Marathon Petroleum | E10: 422.22 | F10: 413.92 | G10: 392.42 | H10: =E10/F10-1 -> 0.020052184 | I10: =E10/G10-1 -> 0.075939045 | J10: 1918111 | K10: 2367300 | L10: =J10/K10 -> 0.81025261 | M10: 5 | N10: 5 | O10: 2 | P10: 5 | Q10: =(M10*$M$6+N10*$N$6+O10*$O$6+P10*$P$6)*20 -> 88 | R10: 美國煉油產能最大；9/17 同組齊升，5 日 +7.21% | S10: 強 | T10: 強 | U10: 同上；年內 +157%，估值已高於共識目標
A11: ① | B11: 煉油與成品油 | C11: DINO | D11: HF Sinclair | E11: 116.58 | F11: 113.97 | G11: 107.72 | H11: =E11/F11-1 -> 0.022900763 | I11: =E11/G11-1 -> 0.082250278 | J11: 2043292 | K11: 2268100 | L11: =J11/K11 -> 0.90088268 | M11: 5 | N11: 5 | O11: 2 | P11: 5 | Q11: =(M11*$M$6+N11*$N$6+O11*$O$6+P11*$P$6)*20 -> 88 | R11: 柴油佔比高，直接對應柴油裂解價差的歷史高位（本月曾見 $102–108/桶，正常夏季約 $20） | S11: 強 | T11: 強 | U11: 同上；小型股波幅較大
A12: ① | B12: 煉油與成品油 | C12: PSX | D12: Phillips 66 | E12: 274.07 | F12: 264.63 | G12: 258.51 | H12: =E12/F12-1 -> 0.035672448 | I12: =E12/G12-1 -> 0.060191095 | J12: 2527722 | K12: 2662400 | L12: =J12/K12 -> 0.94941481 | M12: 4 | N12: 4 | O12: 3 | P12: 5 | Q12: =(M12*$M$6+N12*$N$6+O12*$O$6+P12*$P$6)*20 -> 79 | R12: 中游與化工佔比較高，純煉油度較低，相對未伸展 | S12: 中強 | T12: 中 | U12: 中游業務對沖掉部分裂解上行
A13: ② | B13: 診斷與生命科學工具 | C13: TMO | D13: Thermo Fisher Scientific | E13: 658.26 | F13: 648.43 | G13: 603.18 | H13: =E13/F13-1 -> 0.015159693 | I13: =E13/G13-1 -> 0.091316025 | J13: 2593716 | K13: 1672050 | L13: =J13/K13 -> 1.5512192 | M13: 4 | N13: 5 | O13: 1 | P13: 5 | Q13: =(M13*$M$6+N13*$N$6+O13*$O$6+P13*$P$6)*20 -> 76 | R13: 5 日綜合連續兩版排第 1；9/17 +3.08%、廣度 1.00。零石油投入、收入本土、近期盈利無久期 —— 在 9/16（息率急升）與 9/17（息率回落）兩種日子都上升，是本清單少數真正兩態皆贏的組別 | S13: 強 | T13: 強 | U13: ⚠ 組別 5 日已 +11.46%，為 111 組最大升幅之一，追價風險高
A14: ② | B14: 診斷與生命科學工具 | C14: A | D14: Agilent Technologies | E14: 156.35 | F14: 153.69 | G14: 143.12 | H14: =E14/F14-1 -> 0.017307567 | I14: =E14/G14-1 -> 0.092439911 | J14: 1734708 | K14: 2611600 | L14: =J14/K14 -> 0.66423189 | M14: 4 | N14: 5 | O14: 2 | P14: 5 | Q14: =(M14*$M$6+N14*$N$6+O14*$O$6+P14*$P$6)*20 -> 80 | R14: 同組，9/17 同步上升；相對 TMO 較未伸展 | S14: 強 | T14: 強 | U14: 同組伸展風險
A15: ② | B15: 診斷與生命科學工具 | C15: DHR | D15: Danaher | E15: 212.51 | F15: 208.36 | G15: 200.53 | H15: =E15/F15-1 -> 0.019917451 | I15: =E15/G15-1 -> 0.059741685 | J15: 5375812 | K15: 3085150 | L15: =J15/K15 -> 1.7424799 | M15: 4 | N15: 4 | O15: 3 | P15: 5 | Q15: =(M15*$M$6+N15*$N$6+O15*$O$6+P15*$P$6)*20 -> 79 | R15: 組內最落後的一隻，是參與該組而不追高的方式 | S15: 強 | T15: 中強 | U15: 中國採購與 NIH 預算消息
A16: ③ | B16: 晶圓代工與AI半導體 | C16: TSM | D16: Taiwan Semiconductor | E16: 430.14 | F16: 417.72 | G16: 428.03 | H16: =E16/F16-1 -> 0.029732835 | I16: =E16/G16-1 -> 0.004929561 | J16: 7894769 | K16: 8922050 | L16: =J16/K16 -> 0.88486043 | M16: 4 | N16: 5 | O16: 3 | P16: 5 | Q16: =(M16*$M$6+N16*$N$6+O16*$O$6+P16*$P$6)*20 -> 84 | R16: 9/17 晶圓代工 +6.43%、廣度 1.00，5 日綜合由第 38 急升至第 9，斜率 +0.44。息率 8 連升中斷當日，AI 資本開支的利率免疫性被重新定價 | S16: 強（息率見頂則最大受惠） | T16: 弱（高 beta，久期衝擊時最先被拋） | U16: ⚠ 9/18 四巫日 + 日本央行議息：單日 +6% 之後撞正到期日，回吐風險高
A17: ③ | B17: 晶圓代工與AI半導體 | C17: SNPS | D17: Synopsys | E17: 381.18 | F17: 378.47 | G17: 397.17 | H17: =E17/F17-1 -> 0.007160409 | I17: =E17/G17-1 -> -0.040259838 | J17: 1224298 | K17: 1700650 | L17: =J17/K17 -> 0.71990004 | M17: 4 | N17: 5 | O17: 3 | P17: 4 | Q17: =(M17*$M$6+N17*$N$6+O17*$O$6+P17*$P$6)*20 -> 81 | R17: EDA：現金流最穩、波幅最小的參與方式；9/17 +3.20%、廣度 1.00 | S17: 強 | T17: 中 | U17: 同上
A18: ③ | B18: 晶圓代工與AI半導體 | C18: CDNS | D18: Cadence Design Systems | E18: 280.78 | F18: 279.9 | G18: 284.95 | H18: =E18/F18-1 -> 0.00314398 | I18: =E18/G18-1 -> -0.014634146 | J18: 1484302 | K18: 2291050 | L18: =J18/K18 -> 0.64786975 | M18: 4 | N18: 5 | O18: 3 | P18: 4 | Q18: =(M18*$M$6+N18*$N$6+O18*$O$6+P18*$P$6)*20 -> 81 | R18: 同上，EDA 雙雄 | S18: 強 | T18: 中 | U18: 同上
A19: ④ | B19: 太空與衛星 | C19: RKLB | D19: Rocket Lab | E19: 67.805 | F19: 63.7 | G19: 61.96 | H19: =E19/F19-1 -> 0.0644427 | I19: =E19/G19-1 -> 0.094335055 | J19: 18977980 | K19: 15903100 | L19: =J19/K19 -> 1.193351 | M19: 4 | N19: 5 | O19: 3 | P19: 4 | Q19: =(M19*$M$6+N19*$N$6+O19*$O$6+P19*$P$6)*20 -> 81 | R19: 9/17 +6.36%、廣度 1.00，5 日綜合由第 40 升至第 8，斜率 +0.62（全表第二高）。地緣衝突持續下的國防與衛星需求，加上息率回落對長久期成長股的解壓 | S19: 強 | T19: 中（衝突升級有利訂單，但高 beta） | U19: 小型高 beta，四巫日波幅放大；訂單消息驅動，單一合約新聞即可逆轉
A20: ④ | B20: 太空與衛星 | C20: ASTS | D20: AST SpaceMobile | E20: 62.71 | F20: 59.27 | G20: 59.91 | H20: =E20/F20-1 -> 0.05803948 | I20: =E20/G20-1 -> 0.046736772 | J20: 7957510 | K20: 8364450 | L20: =J20/K20 -> 0.95134886 | M20: 4 | N20: 5 | O20: 2 | P20: 4 | Q20: =(M20*$M$6+N20*$N$6+O20*$O$6+P20*$P$6)*20 -> 77 | R20: 同組，衛星直連手機 | S20: 強 | T20: 中 | U20: 同上，且未有盈利
... A28: ⑦ | B28: 防守（已降級） | C28: RNR | D28: RenaissanceRe | E28: 328.71 | F28: 328.43 | G28: 326.53 | H28: =E28/F28-1 -> 0.00085254088 | I28: =E28/G28-1 -> 0.0066762625 | J28: 183448 | K28: 234950 | L28: =J28/K28 -> 0.78079591 | M28: 3 | N28: 2 | O28: 4 | P28: 4 | Q28: =(M28*$M$6+N28*$N$6+O28*$O$6+P28*$P$6)*20 -> 62 | R28: 海事／戰爭再保仍是最直接的 Hormuz 受惠方式（戰爭險保費由船體價值 0.25% 升至 7.5–10%），但 9/17 未有反應 | S28: 弱 | T28: 強 | U28: 颶風季 + 實際戰爭損失
B29: 組合平均 | H29: =AVERAGE(H9:H28) -> 0.020369016 | I29: =AVERAGE(I9:I28) -> 0.038810845 | L29: =AVERAGE(L9:L28) -> 0.91751192 | Q29: =AVERAGE(Q9:Q28) -> 77.65
A31: 組別說明：① 煉油＝最高信心（兩態皆贏） ② 醫療服務／工具＝資金流最確認 ③ 電網＝AI 用電中有收入的一邊 ④ 產險再保＝唯一「想要」5% 孳息的金融 ⑤ AI 半導體＝戰術小注 ⑥ 鋼鐵＝觀察不建倉

Sheet 迴避清單 Avoid
A1: 3 日迴避／中性清單 Avoid & Stand-down List R2.00
A2: 基準 2026-09-17 美東收市 · G/H/K 欄為公式 · 代號可點擊開 TradingView 圖表 · 列出「有具體理由」的迴避標的，非泛泛看淡
A8: 類別 | B8: 代號 | C8: 公司 | D8: 收市 09-17 | E8: 前收 09-16 | F8: 5日前收 09-10 | G8: 09-17 漲跌% | H8: 5日 漲跌% | I8: 09-17 成交量 | J8: 20日 中位量 | K8: 相對量 | L8: 迴避理由 | M8: 何時反手做多
A9: A 結構性迴避｜油田服務 | B9: SLB | C9: SLB (Schlumberger) | D9: 52.085 | E9: 52.3 | F9: 56.01 | G9: =D9/E9-1 -> -0.0041108987 | H9: =D9/F9-1 -> -0.070076772 | I9: 6869904 | J9: 13457850 | K9: =I9/J9 -> 0.5104756 | L9: 5 日綜合第 103（111 組中），ret5 −6.54%、廣度 0.25。9/17 全巿反彈日仍然 −0.42% —— 反彈日跌，是機制仍然成立的最強證據 | M9: 油價確立在 $110 以上且上游資本開支上調
A10: A 結構性迴避｜油田服務 | B10: HAL | C10: Halliburton | D10: 34.03 | E10: 34.51 | F10: 36.07 | G10: =D10/E10-1 -> -0.013909012 | H10: =D10/F10-1 -> -0.056556695 | I10: 11076403 | J10: 10010150 | K10: =I10/J10 -> 1.1065172 | L10: 同上 | M10: 同上
A11: A 結構性迴避｜區域銀行 | B11: USB | C11: U.S. Bancorp | D11: 60.25 | E11: 59.73 | F11: 62.41 | G11: =D11/E11-1 -> 0.008705843 | H11: =D11/F11-1 -> -0.034609838 | I11: 5244310 | J11: 6336150 | K11: =I11/J11 -> 0.82768085 | L11: 5 日綜合由第 89 再跌至第 104，ret5 −4.15%。9/17 僅 +0.33%，遠遜大市 —— 即使息率回落亦未能吸引資金，存款成本與 CRE 曝險未解 | M11: 孳息曲線明確轉陡
A12: A 結構性迴避｜區域銀行 | B12: PNC | C12: PNC Financial | D12: 232 | E12: 231.49 | F12: 242.98 | G12: =D12/E12-1 -> 0.0022031189 | H12: =D12/F12-1 -> -0.045188904 | I12: 1165721 | J12: 1537550 | K12: =I12/J12 -> 0.75816786 | L12: 同上 | M12: 同上
A13: A 結構性迴避｜區域銀行 | B13: ZION | C13: Zions Bancorporation | D13: 65.72 | E13: 65.47 | F13: 68.29 | G13: =D13/E13-1 -> 0.0038185428 | H13: =D13/F13-1 -> -0.037633621 | I13: 1368599 | J13: 1385800 | K13: =I13/J13 -> 0.98758767 | L13: 同上 | M13: 同上
A14: A 結構性迴避｜投行 | B14: GS | C14: Goldman Sachs | D14: 951.15 | E14: 937.98 | F14: 1019.77 | G14: =D14/E14-1 -> 0.014040811 | H14: =D14/F14-1 -> -0.067289683 | I14: 2592863 | J14: 1800900 | K14: =I14/J14 -> 1.4397596 | L14: 5 日 ret5 −8.68%。9/17 僅 +0.43%。孳息 5% 下 IPO/M&A 窗口未開 | M14: 孳息回落至 4.5% 以下且併購公告回升
A15: A 結構性迴避｜投行 | B15: MS | C15: Morgan Stanley | D15: 203.48 | E15: 202.42 | F15: 212.66 | G15: =D15/E15-1 -> 0.0052366367 | H15: =D15/F15-1 -> -0.043167497 | I15: 3656022 | J15: 3975750 | K15: =I15/J15 -> 0.91958046 | L15: 同上 | M15: 同上
A16: A 結構性迴避｜貨運物流 | B16: FDX | C16: FedEx | D16: 305.94 | E16: 301.72 | F16: 311.8 | G16: =D16/E16-1 -> 0.013986478 | H16: =D16/F16-1 -> -0.018794099 | I16: 674165 | J16: 1323200 | K16: =I16/J16 -> 0.50949592 | L16: 指引下調屬多日重估；5 日綜合第 88，ret5 −3.93%，9/17 只 +0.76% | M16: 指引重設後首次上修
A17: A 結構性迴避｜貨運物流 | B17: UPS | C17: United Parcel Service | D17: 100.18 | E17: 98.77 | F17: 99.97 | G17: =D17/E17-1 -> 0.01427559 | H17: =D17/F17-1 -> 0.0021006302 | I17: 2525673 | J17: 3735150 | K17: =I17/J17 -> 0.67619051 | L17: 同上 | M17: 同上
A18: A 結構性迴避｜電信 | B18: T | C18: AT&T | D18: 25.38 | E18: 25.86 | F18: 25.55 | G18: =D18/E18-1 -> -0.018561485 | H18: =D18/F18-1 -> -0.0066536204 | I18: 27356100 | J18: 32823800 | K18: =I18/J18 -> 0.8334227 | L18: ★ R1.01 的判斷已驗證：9/17 電信 −3.43%、廣度 0.00，為當日 111 組最差，名次由第 33 直插至第 100。5% 無風險利率下股息吸引力被壓縮 | M18: 孳息明確見頂回落
A19: A 結構性迴避｜電信 | B19: VZ | C19: Verizon | D19: 48.33 | E19: 49.76 | F19: 49.97 | G19: =D19/E19-1 -> -0.028737942 | H19: =D19/F19-1 -> -0.032819692 | I19: 18656140 | J19: 18296250 | K19: =I19/J19 -> 1.0196702 | L19: 同上 | M19: 同上
A20: A 結構性迴避｜綜合油氣 | B20: XOM | C20: Exxon Mobil | D20: 163.26 | E20: 163.32 | F20: 165.23 | G20: =D20/E20-1 -> -0.00036737693 | H20: =D20/F20-1 -> -0.011922774 | I20: 7719504 | J20: 13702000 | K20: =I20/J20 -> 0.5633852 | L20: 9/17 −0.01%，反彈日零反應；上游佔比高，下游對沖不足 | M20: 下游佔比提升
... A33: B 由迴避改為中性｜量子運算 | B33: IONQ | C33: IonQ | D33: 40.365 | E33: 36.84 | F33: 36.84 | G33: =D33/E33-1 -> 0.095684039 | H33: =D33/F33-1 -> 0.095684039 | I33: 19994776 | J33: 15609650 | K33: =I33/J33 -> 1.280924 | L33: 9/17 +9.57%，組別為當日 111 組之冠（+7.99%、廣度 1.00），名次由第 69 升至第 15 | M33: 同上；純粹的息率久期交易，無基本面變化
C34: 組合平均 | G34: =AVERAGE(G9:G33) -> 0.021485284 | H34: =AVERAGE(H9:H33) -> -0.024876135 | K34: =AVERAGE(K9:K33) -> 1.0077513
A36: A 類＝機制仍然成立，9/17 全巿反彈日依然落後，未來 3 日不新增多倉（非建議沽空）。B 類＝R1.01 列為迴避但 9/17 大幅反彈，迴避理由已被「息率暫停上升」削弱，本版改列中性：既不建議新倉，亦不再視為迴避。10 年期由 5.04% 的 19 年高位回落、8 連升中斷，是 B 類全部反彈的單一共同原因；若孳息重上 5.1%，B 類的迴避理由即時恢復。

Sheet 板塊資金流證據 Evidence
A1: 111 個子板塊資金流證據（可追溯全表）
A2: 來源：SubSector 資金流向 R12 引擎（本次重跑） · 視窗 2026-09-11 → 2026-09-17 · 按 5 日綜合分排序 · 成分股可點擊 · ※ 淨額含 9/17 未結算成交量，屬臨時值
A8: 5日 排名 | B8: 子板塊 | C8: English | D8: 大板塊 | E8: 5日 分數 | F8: 09-17 分數 | G8: 09-17 漲跌% | H8: 5日 漲跌% | I8: 09-17 廣度 | J8: 5日 廣度 | K8: 09-17 相對量 | L8: 斜率 | M8: 09-17 淨額※ (US$ 百萬) | N8: 5日 淨額※ (US$ 百萬) | O8: 成分股 1 | P8: 成分股 2 | Q8: 成分股 3 | R8: 成分股 4 | S8: 成分股 5 | T8: 成分股 6 | U8: 成分股 7 | V8: 成分股 8 | W8: 備註
A9: =ROW()-8 -> 1 | B9: 診斷與生命科學工具 | C9: Diagnostics & Life-Science Tools | D9: 醫療保健 Health Care | E9: 100 | F9: 90 | G9: 0.030787182 | H9: 0.11458338 | I9: 1 | J9: 0.9 | K9: 1 | L9: 0.2429148 | M9: 1251.9188 | N9: 6024.3933 | O9: TMO | P9: DHR | Q9: A | R9: ILMN | W9: ★ 第②組：連續兩版 5 日綜合第 1；9/16、9/17 兩種息率環境下都上升
A10: =ROW()-8 -> 2 | B10: 煉油與成品油 | C10: Refining & Marketing | D10: 能源 Energy | E10: 99.090909 | F10: 96.363636 | G10: 0.02526658 | H10: 0.072120687 | I10: 1 | J10: 0.75 | K10: 1 | L10: 0.62267442 | M10: 2197.5203 | N10: 3295.6219 | O10: MPC | P10: PSX | Q10: VLO | R10: DINO | W10: ★ 第①組：9/17 +2.53%、廣度 1.00，名次 4→2，斜率 +0.62
A11: =ROW()-8 -> 3 | B11: 電子硬件與EMS/連接器 | C11: Electronic Hardware, EMS & Connectors | D11: 資訊科技 Information Technology | E11: 98.181818 | F11: 89.090909 | G11: 0.016853483 | H11: 0.027026845 | I11: 0.83333333 | J11: 0.7 | K11: 1 | L11: 0.043345703 | M11: 10072.417 | N11: 17291.813 | O11: AAPL | P11: DELL | Q11: FLEX | R11: JBL | S11: APH | T11: TEL
A12: =ROW()-8 -> 4 | B12: 資料/分析平台 | C12: Data & Analytics Platforms | D12: 資訊科技 Information Technology | E12: 97.272727 | F12: 88.181818 | G12: 0.025336564 | H12: 0.051788534 | I12: 1 | J12: 0.75 | K12: 1 | L12: 0.28977824 | M12: 2735.5443 | N12: 10802.791 | O12: PLTR | P12: SNOW | Q12: MDB | R12: DDOG
A13: =ROW()-8 -> 5 | B13: 網絡安全 | C13: Cybersecurity | D13: 資訊科技 Information Technology | E13: 96.363636 | F13: 62.727273 | G13: 0.010258622 | H13: 0.14918317 | I13: 0.6 | J13: 0.68 | K13: 1 | L13: 0.18275276 | M13: 1652.3394 | N13: 14932.771 | O13: PANW | P13: CRWD | Q13: ZS | R13: FTNT | S13: S
A14: =ROW()-8 -> 6 | B14: 鋼鐵 | C14: Steel | D14: 原材料 Materials | E14: 95.454545 | F14: 82.727273 | G14: 0.028115285 | H14: 0.042884547 | I14: 1 | J14: 0.75 | K14: 1 | L14: 0.23421157 | M14: -84.961517 | N14: 11.421812 | O14: NUE | P14: STLD | Q14: CLF | R14: RS | W14: ★ 第⑤組：9/17 +2.81%、廣度 1.00，名次 11→6 —— 升勢有廣度且未伸展
A15: =ROW()-8 -> 7 | B15: 大型網絡平台與數位廣告 | C15: Mega-cap Internet & Digital Ads | D15: 通訊服務 Communication Services | E15: 94.545455 | F15: 85.454545 | G15: 0.01354986 | H15: 0.052013856 | I15: 1 | J15: 0.8 | K15: 1 | L15: 0.019744455 | M15: 10561.002 | N15: 10553.283 | O15: GOOGL | P15: META
A16: =ROW()-8 -> 8 | B16: 太空與衛星 | C16: Space & Satellites | D16: 工業 Industrials | E16: 93.636364 | F16: 98.181818 | G16: 0.063567483 | H16: 0.046164568 | I16: 1 | J16: 0.6 | K16: 1 | L16: 0.62274483 | M16: 1016.4759 | N16: 1073.3685 | O16: RKLB | P16: ASTS | Q16: LUNR | R16: PL | S16: RDW | W16: ★ 第④組：9/17 +6.36%、廣度 1.00，名次 40→8，斜率 +0.62
A17: =ROW()-8 -> 9 | B17: 晶圓代工/IDM | C17: Foundry & IDM | D17: 資訊科技 Information Technology | E17: 92.727273 | F17: 97.272727 | G17: 0.064280367 | H17: 0.047550046 | I17: 1 | J17: 0.65 | K17: 1 | L17: 0.43727628 | M17: 5141.1558 | N17: -6139.4298 | O17: TSM | P17: INTC | Q17: GFS | R17: UMC | W17: ★ 第③組：9/17 +6.43%、廣度 1.00，名次 38→9
A18: =ROW()-8 -> 10 | B18: AI資料中心建設 | C18: AI Data Center Buildout | D18: 資訊科技 Information Technology | E18: 91.818182 | F18: 70 | G18: 0.028976889 | H18: 0.034369588 | I18: 1 | J18: 0.68 | K18: 1 | L18: 0.0030041884 | M18: -1049.808 | N18: -171.62558 | O18: VRT | P18: SMCI | Q18: ANET | R18: MOD | S18: CIEN
A19: =ROW()-8 -> 11 | B19: 工業與物流REIT | C19: Industrial & Logistics REITs | D19: 房地產 Real Estate | E19: 90.909091 | F19: 87.272727 | G19: 0.014164922 | H19: 0.018489443 | I19: 1 | J19: 0.8 | K19: 1 | L19: 0.097998189 | M19: 341.71285 | N19: 1077.1196 | O19: PLD | P19: EGP | Q19: FR | R19: STAG
A20: =ROW()-8 -> 12 | B20: 資料中心REIT | C20: Data Center REITs | D20: 房地產 Real Estate | E20: 90 | F20: 77.272727 | G20: 0.014067145 | H20: -0.0014848013 | I20: 1 | J20: 0.8 | K20: 1 | L20: 0.22736287 | M20: 32.015895 | N20: 5.621184 | O20: EQIX | P20: DLR
A21: =ROW()-8 -> 13 | B21: 國防科技與無人機 | C21: Defense Tech & Drones | D21: 工業 Industrials | E21: 89.090909 | F21: 67.272727 | G21: 0.018111917 | H21: 0.0039285554 | I21: 0.5 | J21: 0.55 | K21: 1 | L21: 0.11487432 | M21: -293.66247 | N21: 1078.3837 | O21: AVAV | P21: KTOS | Q21: RCAT | R21: ONDS
A22: =ROW()-8 -> 14 | B22: AI加速晶片/GPU | C22: AI Accelerators & GPU | D22: 資訊科技 Information Technology | E22: 88.181818 | F22: 91.818182 | G22: 0.039884538 | H22: 0.026901792 | I22: 1 | J22: 0.65 | K22: 1 | L22: 0.49351929 | M22: 10818.386 | N22: -35950.227 | O22: NVDA | P22: AMD | Q22: AVGO | R22: MRVL | W22: ○ 9/17 +3.99%、廣度 1.00，名次 57→14
A23: =ROW()-8 -> 15 | B23: 量子運算 | C23: Quantum Computing | D23: 資訊科技 Information Technology | E23: 87.272727 | F23: 100 | G23: 0.079933128 | H23: 0.073247902 | I23: 1 | J23: 0.55 | K23: 1 | L23: 0.38263213 | M23: 840.82708 | N23: 565.7897 | O23: IONQ | P23: RGTI | Q23: QBTS | R23: QUBT | W23: △ B 類改中性：9/17 +7.99%，當日 111 組之冠，名次 69→15
A24: =ROW()-8 -> 16 | B24: 產險與再保 | C24: P&C Insurance & Reinsurance | D24: 金融 Financials | E24: 86.363636 | F24: 41.818182 | G24: -0.00097026441 | H24: 0.012456458 | I24: 0 | J24: 0.64 | K24: 1 | L24: -0.2024519 | M24: 561.75592 | N24: 2313.3784 | O24: CB | P24: TRV | Q24: PGR | R24: AIG | S24: RNR | W24: ⚠ 第⑦組（已降級）：9/17 −0.10%、廣度 0.00，名次 6→16
A25: =ROW()-8 -> 17 | B25: 住宅建築商 | C25: Homebuilders | D25: 非必需消費 Consumer Discretionary | E25: 85.454545 | F25: 71.818182 | G25: 0.012914324 | H25: 0.024203977 | I25: 1 | J25: 0.76 | K25: 1 | L25: -0.35146724 | M25: 12.231295 | N25: 475.97609 | O25: DHI | P25: LEN | Q25: PHM | R25: NVR | S25: TOL | W25: △ B 類改中性：9/17 +1.29%、廣度 1.00，名次 44→17
A26: =ROW()-8 -> 18 | B26: 大型藥廠 | C26: Large-cap Pharma | D26: 醫療保健 Health Care | E26: 84.545455 | F26: 72.727273 | G26: 0.0065511422 | H26: 0.01296336 | I26: 0.83333333 | J26: 0.76666667 | K26: 1 | L26: 0.31410012 | M26: 2892.3027 | N26: -2753.7362 | O26: LLY | P26: JNJ | Q26: PFE | R26: MRK | S26: ABBV | T26: BMY
A27: =ROW()-8 -> 19 | B27: 大型生物科技 | C27: Large-cap Biotech | D27: 醫療保健 Health Care | E27: 83.636364 | F27: 81.818182 | G27: 0.01388561 | H27: 0.0099130979 | I27: 1 | J27: 0.72 | K27: 1 | L27: 0.44095589 | M27: 1609.9122 | N27: -105.7045 | O27: AMGN | P27: GILD | Q27: REGN | R27: VRTX | S27: BIIB
A28: =ROW()-8 -> 20 | B28: 醫院與醫療服務 | C28: Hospitals & Providers | D28: 醫療保健 Health Care | E28: 82.727273 | F28: 13.636364 | G28: -0.0062990703 | H28: 0.019915705 | I28: 0 | J28: 0.6 | K28: 1 | L28: -0.074508655 | M28: -299.28829 | N28: 715.64238 | O28: HCA | P28: THC | Q28: UHS | R28: EHC | W28: ⚠ 第⑦組（已降級）：R1.01 列為高信心，9/17 −0.63%、廣度 0.00，名次 3→20
A29: =ROW()-8 -> 21 | B29: 電氣設備與電網 | C29: Electrical Equipment & Grid | D29: 工業 Industrials | E29: 81.818182 | F29: 34.545455 | G29: 0.0090420111 | H29: -0.0050529565 | I29: 0.6 | J29: 0.56 | K29: 1.0414094 | L29: -0.13424848 | M29: -2740.7316 | N29: -2274.2394 | O29: ETN | P29: EMR | Q29: PWR | R29: HUBB | S29: GEV | W29: ★ 第⑥組（已降級）：9/17 只 +0.90%、廣度 0.60，名次 14→21，斜率轉負
A30: =ROW()-8 -> 22 | B30: 光通訊/CPO | C30: Optical Networking & CPO | D30: 資訊科技 Information Technology | E30: 80.909091 | F30: 37.272727 | G30: 0.012618404 | H30: -0.0091312907 | I30: 0.8 | J30: 0.68 | K30: 1 | L30: 0.29637876 | M30: -3286.0804 | N30: -10592.508 | O30: COHR | P30: LITE | Q30: AAOI | R30: CRDO | S30: POET | W30: ○ 9/17 +1.26%，名次 34→22
A31: =ROW()-8 -> 23 | B31: EDA與半導體IP | C31: EDA & Semiconductor IP | D31: 資訊科技 Information Technology | E31: 80 | F31: 74.545455 | G31: 0.032002718 | H31: -0.0033577678 | I31: 1 | J31: 0.6 | K31: 1 | L31: 0.2785185 | M31: 251.19099 | N31: -2638.669 | O31: SNPS | P31: CDNS | Q31: ARM | W31: ★ 第③組：9/17 +3.20%、廣度 1.00，名次 37→23
A32: =ROW()-8 -> 24 | B32: 工業自動化與機器人 | C32: Industrial Automation & Robotics | D32: 工業 Industrials | E32: 79.090909 | F32: 48.181818 | G32: 0.016602161 | H32: 0.0069907637 | I32: 0.75 | J32: 0.75 | K32: 1 | L32: -0.019415593 | M32: -603.1055 | N32: -2386.7352 | O32: ROK | P32: SYM | Q32: NDSN | R32: TER
A33: =ROW()-8 -> 25 | B33: 銅與基本金屬 | C33: Copper & Base Metals | D33: 原材料 Materials | E33: 78.181818 | F33: 83.636364 | G33: 0.029249502 | H33: -0.0032967494 | I33: 1 | J33: 0.5 | K33: 1 | L33: 0.4367994 | M33: -246.04519 | N33: 61.493985 | O33: FCX | P33: SCCO | Q33: TECK | R33: HBM
A34: =ROW()-8 -> 26 | B34: 家庭與個人護理 | C34: Household & Personal Care | D34: 必需消費 Consumer Staples | E34: 77.272727 | F34: 44.545455 | G34: -0.0021853934 | H34: 0.0022236293 | I34: 0.4 | J34: 0.6 | K34: 1 | L34: -0.016904432 | M34: 698.46586 | N34: 624.52921 | O34: PG | P34: CL | Q34: KMB | R34: CHD | S34: EL
A35: =ROW()-8 -> 27 | B35: 醫療器械 | C35: Medical Devices | D35: 醫療保健 Health Care | E35: 76.363636 | F35: 28.181818 | G35: -0.0038725365 | H35: 0.022959395 | I35: 0.2 | J35: 0.6 | K35: 1 | L35: -0.20159858 | M35: 519.56911 | N35: -209.694 | O35: ABT | P35: MDT | Q35: SYK | R35: BSX | S35: ISRG
A36: =ROW()-8 -> 28 | B36: 黃金與貴金屬礦 | C36: Gold & Precious Metals Miners | D36: 原材料 Materials | E36: 75.454545 | F36: 84.545455 | G36: 0.021153672 | H36: -0.001223942 | I36: 0.83333333 | J36: 0.53333333 | K36: 1 | L36: 0.24086415 | M36: -230.26666 | N36: 367.92383 | O36: NEM | P36: GOLD | Q36: AEM | R36: AU | S36: KGC | T36: RGLD
A37: =ROW()-8 -> 29 | B37: 辦公樓REIT | C37: Office REITs | D37: 房地產 Real Estate | E37: 74.545455 | F37: 36.363636 | G37: 0.0032347827 | H37: 0.010570489 | I37: 0.5 | J37: 0.6 | K37: 1 | L37: -0.17421111 | M37: -40.94091 | N37: -61.82206 | O37: BXP | P37: VNO | Q37: SLG | R37: HIW
A38: =ROW()-8 -> 30 | B38: 腫瘤與細胞治療 | C38: Oncology & Cell Therapy | D38: 醫療保健 Health Care | E38: 73.636364 | F38: 54.545455 | G38: 0.016815726 | H38: 0.010661961 | I38: 0.875 | J38: 0.55 | K38: 1 | L38: -0.06398148 | M38: -238.32803 | N38: -12.702204 | O38: LEGN | P38: IOVA | Q38: ALLO | R38: ARVN | S38: RVMD | T38: NKTX | U38: FATE | V38: CRVS
A39: =ROW()-8 -> 31 | B39: 雲端基建/IaaS/Neocloud | C39: Cloud Infrastructure & Neoclouds | D39: 資訊科技 Information Technology | E39: 72.727273 | F39: 79.090909 | G39: 0.0099335669 | H39: -0.018989109 | I39: 0.8 | J39: 0.44 | K39: 1 | L39: -0.0059874038 | M39: 4079.0467 | N39: -7209.1679 | O39: MSFT | P39: AMZN | Q39: GOOGL | R39: NBIS | S39: CRWV
A40: =ROW()-8 -> 32 | B40: 基因治療與基因編輯 | C40: Gene Editing & Gene Therapy | D40: 醫療保健 Health Care | E40: 71.818182 | F40: 92.727273 | G40: 0.078083075 | H40: 0.045610833 | I40: 1 | J40: 0.6 | K40: 1 | L40: 0.64309221 | M40: 6.9046171 | N40: -264.91914 | O40: CRSP | P40: NTLA | Q40: BEAM
A41: =ROW()-8 -> 33 | B41: 航空公司 | C41: Airlines | D41: 工業 Industrials | E41: 70.909091 | F41: 69.090909 | G41: 0.020285552 | H41: 0.018723039 | I41: 1 | J41: 0.6 | K41: 1 | L41: -0.16391261 | M41: -818.751 | N41: -1799.4148 | O41: DAL | P41: UAL | Q41: AAL | R41: LUV
A42: =ROW()-8 -> 34 | B42: 壽險與年金 | C42: Life Insurance & Annuities | D42: 金融 Financials | E42: 70 | F42: 33.636364 | G42: 0.0012445537 | H42: 0.0034986963 | I42: 0.4 | J42: 0.64 | K42: 1 | L42: -0.26243654 | M42: -233.30095 | N42: 701.79065 | O42: MET | P42: PRU | Q42: AFL | R42: LNC | S42: EQH
A43: =ROW()-8 -> 35 | B43: 電商平台 | C43: E-commerce Platforms | D43: 非必需消費 Consumer Discretionary | E43: 69.090909 | F43: 55.454545 | G43: 0.0077636321 | H43: 0.026830661 | I43: 0.4 | J43: 0.52 | K43: 1 | L43: -0.17414321 | M43: 768.47512 | N43: -3144.9282 | O43: AMZN | P43: SHOP | Q43: EBAY | R43: CHWY | S43: W
A44: =ROW()-8 -> 36 | B44: 人力與商業服務 | C44: Staffing & Business Services | D44: 工業 Industrials | E44: 68.181818 | F44: 35.454545 | G44: -0.0025260984 | H44: 0.0071040812 | I44: 0.2 | J44: 0.48 | K44: 1 | L44: -0.32692052 | M44: 466.19606 | N44: 909.38651 | O44: ADP | P44: PAYX | Q44: MAN | R44: RHI | S44: CTAS
A45: =ROW()-8 -> 37 | B45: 基礎化工與化肥 | C45: Commodity Chemicals & Fertilizers | D45: 原材料 Materials | E45: 67.272727 | F45: 56.363636 | G45: 0.0048896242 | H45: -0.0024050748 | I45: 0.6 | J45: 0.36 | K45: 1 | L45: 0.44878522 | M45: 278.08435 | N45: -27.399799 | O45: DOW | P45: LYB | Q45: CF | R45: MOS | S45: NTR
...

Sheet 代號索引 Ticker Index
A1: 代號索引 Ticker Index
A2: 基準 2026-09-17 美東收市 · 工作簿內全部 492 個代號，每個都可點擊開 TradingView 圖表 · I/J/M 欄為公式 · 表頭可篩選排序
A8: 代號 | B8: 受惠清單 | C8: 迴避清單 | D8: 所屬子板塊（可多於一個） | E8: 子板塊 最佳5日排名 | F8: 收市 09-17 | G8: 前收 09-16 | H8: 5日前收 09-10 | I8: 09-17 漲跌% | J8: 5日 漲跌% | K8: 09-17 成交量 | L8: 20日 中位量 | M8: 相對量
A9: A | B9: ② | C9: — | D9: 診斷與生命科學工具 | E9: 1 | F9: 156.35 | G9: 153.69 | H9: 143.12 | I9: =F9/G9-1 -> 0.017307567 | J9: =F9/H9-1 -> 0.092439911 | K9: 1734708 | L9: 2611600 | M9: =K9/L9 -> 0.66423189
A10: AA | B10: — | C10: — | D10: 鋁業 | E10: 66 | F10: 46.99 | G10: 46.26 | H10: 48.3 | I10: =F10/G10-1 -> 0.015780372 | J10: =F10/H10-1 -> -0.027122153 | K10: 2048059 | L10: 3613850 | M10: =K10/L10 -> 0.56672496
A11: AAL | B11: — | C11: — | D11: 航空公司 | E11: 33 | F11: 12.93 | G11: 12.7 | H11: 12.85 | I11: =F11/G11-1 -> 0.018110236 | J11: =F11/H11-1 -> 0.0062256809 | K11: 78722967 | L11: 64569550 | M11: =K11/L11 -> 1.2191965
A12: AAOI | B12: — | C12: — | D12: 光通訊/CPO | E12: 22 | F12: 98.15 | G12: 96.74 | H12: 103.29 | I12: =F12/G12-1 -> 0.01457515 | J12: =F12/H12-1 -> -0.049762804 | K12: 6492339 | L12: 6115750 | M12: =K12/L12 -> 1.0615769
A13: AAON | B13: — | C13: — | D13: 樓宇產品與HVAC | E13: 75 | F13: 76.44 | G13: 75.56 | H13: 76.52 | I13: =F13/G13-1 -> 0.011646374 | J13: =F13/H13-1 -> -0.0010454783 | K13: 851733 | L13: 1003800 | M13: =K13/L13 -> 0.84850867
A14: AAPL | B14: — | C14: — | D14: 電子硬件與EMS/連接器 | E14: 3 | F14: 337.08 | G14: 332.41 | H14: 326.57 | I14: =F14/G14-1 -> 0.014048915 | J14: =F14/H14-1 -> 0.032182993 | K14: 25891668 | L14: 38959250 | M14: =K14/L14 -> 0.66458333
A15: ABBV | B15: — | C15: — | D15: 大型藥廠 | E15: 18 | F15: 263.98 | G15: 262.51 | H15: 255 | I15: =F15/G15-1 -> 0.0055997867 | J15: =F15/H15-1 -> 0.035215686 | K15: 1816936 | L15: 4311850 | M15: =K15/L15 -> 0.42138201
A16: ABT | B16: — | C16: — | D16: 醫療器械 | E16: 27 | F16: 102.23 | G16: 102.36 | H16: 103.36 | I16: =F16/G16-1 -> -0.0012700274 | J16: =F16/H16-1 -> -0.010932663 | K16: 6209121 | L16: 7460600 | M16: =K16/L16 -> 0.83225491
A17: ACI | B17: — | C17: — | D17: 大賣場與超巿 | E17: 48 | F17: 12.565 | G17: 12.56 | H17: 11.7 | I17: =F17/G17-1 -> 0.00039808917 | J17: =F17/H17-1 -> 0.073931624 | K17: 4858225 | L17: 6141450 | M17: =K17/L17 -> 0.79105504
A18: ACM | B18: — | C18: — | D18: 工程建設/EPC | E18: 67 | F18: 63.41 | G18: 62.81 | H18: 62.89 | I18: =F18/G18-1 -> 0.009552619 | J18: =F18/H18-1 -> 0.0082684052 | K18: 764384 | L18: 1685300 | M18: =K18/L18 -> 0.4535596
A19: ACN | B19: — | C19: — | D19: IT服務與系統整合 | E19: 43 | F19: 190.275 | G19: 189.64 | H19: 177.91 | I19: =F19/G19-1 -> 0.0033484497 | J19: =F19/H19-1 -> 0.069501433 | K19: 2189903 | L19: 4610450 | M19: =K19/L19 -> 0.47498682
A20: ADBE | B20: — | C20: — | D20: 企業軟體/SaaS | E20: 50 | F20: 252.63 | G20: 250.5 | H20: 248.83 | I20: =F20/G20-1 -> 0.008502994 | J20: =F20/H20-1 -> 0.01527147 | K20: 3705952 | L20: 4459200 | M20: =K20/L20 -> 0.83108001
... A45: AON | B45: — | C45: — | D45: 保險經紀 | E45: 110 | F45: 296.04 | G45: 300.57 | H45: 307.77 | I45: =F45/G45-1 -> -0.015071364 | J45: =F45/H45-1 -> -0.038112876 | K45: 2231126 | L45: 1633450 | M45: =K45/L45 -> 1.3658979
A46: APA | B46: — | C46: — | D46: — | F46: 45.46 | G46: 44.79 | H46: 44.53 | I46: =F46/G46-1 -> 0.014958696 | J46: =F46/H46-1 -> 0.020884797 | K46: 4209639 | L46: 4866200 | M46: =K46/L46 -> 0.86507727
A47: APD | B47: — | C47: — | D47: 特種化工 | E47: 61 | F47: 286.15 | G47: 287.08 | H47: 293.65 | I47: =F47/G47-1 -> -0.0032395151 | J47: =F47/H47-1 -> -0.02554061 | K47: 663798 | L47: 980300 | M47: =K47/L47 -> 0.67713761
A48: APH | B48: — | C48: — | D48: 電子硬件與EMS/連接器 | E48: 3 | F48: 78.36 | G48: 77.26 | H48: 80.25 | I48: =F48/G48-1 -> 0.014237639 | J48: =F48/H48-1 -> -0.023551402 | K48: 6221132 | L48: 10936300 | M48: =K48/L48 -> 0.56885162
A49: APO | B49: — | C49: — | D49: 另類資產與私募信貸 | E49: 87 | F49: 126.01 | G49: 124.53 | H49: 127.91 | I49: =F49/G49-1 -> 0.011884686 | J49: =F49/H49-1 -> -0.014854194 | K49: 1781980 | L49: 2204050 | M49: =K49/L49 -> 0.80850253
A50: APTV | B50: — | C50: — | D50: 傳統汽車與零部件 | E50: 84 | F50: 43.625 | G50: 43.34 | H50: 45.69 | I50: =F50/G50-1 -> 0.0065759114 | J50: =F50/H50-1 -> -0.045195885 | K50: 3636071 | L50: 3747950 | M50: =K50/L50 -> 0.97014928
A51: ARES | B51: — | C51: — | D51: 另類資產與私募信貸 | E51: 87 | F51: 125.31 | G51: 124.21 | H51: 130.63 | I51: =F51/G51-1 -> 0.0088559697 | J51: =F51/H51-1 -> -0.040725714 | K51: 1194046 | L51: 1771700 | M51: =K51/L51 -> 0.67395496
A52: ARM | B52: — | C52: — | D52: EDA與半導體IP | E52: 23 | F52: 264.89 | G52: 243.98 | H52: 254.18 | I52: =F52/G52-1 -> 0.085703746 | J52: =F52/H52-1 -> 0.042135495 | K52: 4920338 | L52: 3744150 | M52: =K52/L52 -> 1.3141402
A53: ARVN | B53: — | C53: — | D53: 腫瘤與細胞治療 | E53: 30 | F53: 8.3 | G53: 8.16 | H53: 8.71 | I53: =F53/G53-1 -> 0.017156863 | J53: =F53/H53-1 -> -0.047072331 | K53: 414658 | L53: 585500 | M53: =K53/L53 -> 0.70821178
A54: ASML | B54: — | C54: — | D54: 半導體設備 | E54: 64 | F54: 1628.74 | G54: 1602.22 | H54: 1687.4301 | I54: =F54/G54-1 -> 0.016552034 | J54: =F54/H54-1 -> -0.034780759 | K54: 1257601 | L54: 1140050 | M54: =K54/L54 -> 1.1031104
A55: ASPI | B55: — | C55: — | D55: 小型模組化核能SMR | E55: 54 | F55: 3.245 | G55: 3.15 | H55: 3.59 | I55: =F55/G55-1 -> 0.03015873 | J55: =F55/H55-1 -> -0.096100279 | K55: 2758711 | L55: 3661700 | M55: =K55/L55 -> 0.75339624
A56: ASTS | B56: ④ | C56: — | D56: 太空與衛星、有線/寬頻/衛星 | E56: 8 | F56: 62.71 | G56: 59.27 | H56: 59.91 | I56: =F56/G56-1 -> 0.05803948 | J56: =F56/H56-1 -> 0.046736772 | K56: 7957510 | L56: 8364450 | M56: =K56/L56 -> 0.95134886
A57: ATO | B57: — | C57: — | D57: 燃氣公用 | E57: 80 | F57: 161.92 | G57: 161.96 | H57: 164.81 | I57: =F57/G57-1 -> -0.00024697456 | J57: =F57/H57-1 -> -0.017535344 | K57: 868017 | L57: 888900 | M57: =K57/L57 -> 0.97650692
A58: AU | B58: — | C58: — | D58: 黃金與貴金屬礦 | E58: 28 | F58: 102.4 | G58: 99.74 | H58: 103.88 | I58: =F58/G58-1 -> 0.02666934 | J58: =F58/H58-1 -> -0.014247208 | K58: 1561652 | L58: 2588500 | M58: =K58/L58 -> 0.60330384
... A500: ZS | B500: — | C500: — | D500: 網絡安全 | E500: 5 | F500: 197.35 | G500: 191.58 | H500: 163.48 | I500: =F500/G500-1 -> 0.030117966 | J500: =F500/H500-1 -> 0.20718131 | K500: 2686024 | L500: 2580250 | M500: =K500/L500 -> 1.0409937
A502: 綠底＝在「3日受惠清單」內（20 檔） 紅底＝在「迴避清單」內（25 檔） 其餘為 111 個子板塊籃子的成分股。子板塊排名為該代號所屬板塊中 5 日綜合分最高者的名次（1 = 最強）。

Sheet 催化劑日程 Catalysts
A1: 未來 3 個交易日催化劑日程
A2: 基準 2026-09-17 美東收市 · 時間為美東時間 · 「相關代號」欄的代號可點擊開 TradingView 圖表
A8: 日期 | B8: 星期 | C8: 事件 | D8: 時間 (ET) | E8: 為何重要 | F8: 衝擊哪些清單項目 | G8: 方向偏好 | H8: 相關代號 1 | I8: 相關代號 2 | J8: 相關代號 3 | K8: 相關代號 4 | L8: 相關代號 5 | M8: 相關代號 6 | N8: 相關代號 7
A9: 2026-09-18 | B9: 五 | C9: ★ 日本央行議息 + 植田記者會 | D9: 日本時間中午／02:30 ET | E9: 市場預期加息 25bp 至 1.25%，1993 年以來最高，2024 年結束超寬鬆以來第 6 次。美 10 年期在 5.01% 之際，若措辭偏鷹 → 日圓套息平倉 → 全球久期衝擊，直接打擊 9/17 剛反彈的長久期資產 | F9: 第③組 TSM／SNPS／CDNS、第④組 RKLB／ASTS 最敏感；B 類全部 | G9: 鷹派 → 狀態 B，本清單防守部位回升 | H9: TSM | I9: SNPS | J9: CDNS | K9: RKLB | L9: ASTS
A10: 2026-09-18 | B10: 五 | C10: ★ 四巫日（季度期權期指同時到期）+ 標普季度再平衡 | D10: 收市 | E10: 9 月第三個週五。9/17 多個組別單日升 6–8%（量子 +7.99%、SMR +8.01%、晶圓代工 +6.43%），這類倉位驅動的急升最容易在到期日被打回 | F10: 第③④組與全部 B 類；第①⑤組（煉油、鋼鐵）相對安全 | G10: 波動放大；宜避免追高 | H10: IONQ | I10: OKLO | J10: TSM | K10: RKLB
A11: 2026-09-18 | B11: 五 | C11: 8 月經濟諮商局領先指標 | D11: 10:00 | E11: 若領先指標走弱而聯儲仍鷹 → 滯脹定價；本清單的防守部位（第⑦組）只在此情境下才有相對優勢 | F11: 第⑦組 HCA／TRV／RNR | G11: 弱數據 → 第⑦組回升 | H11: HCA | I11: TRV | J11: RNR
A12: 2026-09-21 | B12: 一 | C12: 到期後倉位重置 | D12: 開市 | E12: 四巫日後第一個交易日，被 gamma 壓抑的走勢通常於此釋放。9/17 的反彈究竟是趨勢反轉還是空頭回補，這一日最能分辨 | F12: 全表 | G12: 趨勢確認日
A13: 2026-09-21 | B13: 一 | C13: 沙特 East–West 輸油管：一半運能是否如期恢復 | D13: 不定 | E13: Aramco 稱繞過受損段後可於數日內恢復約一半運能，全面復原約需六週。同時已改以 Hormuz 外 Sohar 附近的船對船轉運補充亞洲買家 | F13: 第①組全部：原油供應恢復而煉油產能未復，正是裂解價差擴張的條件 | G13: 供應恢復 → 對煉油有利 | H13: VLO | I13: MPC | J13: DINO | K13: PSX
A14: 2026-09-22 | B14: 二 | C14: 聯儲官員發言密集期 | D14: 全日 | E14: 9/16 點陣圖顯示 18 人中 16 人預期年內再加一次。9/17 的 8 連升中斷是否只是喘息，取決於官員如何描述「下一次」 | F14: 全表；第⑦組與 B 類方向完全相反 | G14: 偏鷹 → 第⑦組；偏鴿 → B 類 | H14: HCA | I14: TRV | J14: OKLO | K14: COIN
A15: 2026-09-22 | B15: 二 | C15: Hormuz 航運事件與戰爭險費率 | D15: 不定 | E15: 美伊已進入「油輪換油輪」互擊，停火談判多次破裂；胡塞武裝亦持續襲擊沙特設施。戰爭險保費已由船體價值 0.25% 升至 7.5–10% | F15: 第⑦組 RNR（戰爭再保）／第①組煉油 | G15: 再有大規模襲擊 → 油價與裂解同升 | H15: RNR | I15: VLO | J15: MPC
A16: 2026-09-30 | B16: （參考） | C16: 俄羅斯柴油出口禁令到期日 | D16: — | E16: 禁令已延長至 9/30。俄佔全球柴油約 10%，8 月煉油量 380 萬桶/日為二十年最低。烏克蘭無人機已打掉約 280 萬桶俄煉油產能 | F16: 第①組全部：若不續期，柴油裂解可能回落 | G16: 本清單 3 日窗口外，但屬第①組主要失效條件 | H16: VLO | I16: MPC | J16: DINO | K16: PSX

Sheet 情境矩陣 Scenarios
A1: 兩態情境矩陣 Scenario Matrix
A2: 狀態機率為可調整輸入（黃底藍字）；期望值 ＝ P(A)×A 報酬 + P(B)×B 報酬，報酬分 −2 至 +2
B4: 狀態 A：息率見頂（9/17 的延續） | C4: 10 年期由 5.04% 的 19 年高位回落至 5.01%，8 連升中斷；Brent 再跌 $1.01 至 $104.82、WTI 至 $101.91；Aramco 數日內恢復一半管線運能。實質利率見頂 → 被息率殺傷最重的長久期資產續彈 | D4: P(A) | E4: 0.5
B5: 狀態 B：息率再升（回到 9/16 的形態） | C5: 日本央行鷹派加息（預期 +25bp 至 1.25%，1993 年來最高）觸發日圓套息平倉；或 Hormuz 再有大規模襲擊令油價重上；或聯儲官員確認年內再加一次。10 年期重上 5.1% | D5: P(B) | E5: =1-E4 -> 0.5
A7: 機率設為 50/50：9/17 的息率回落只是一日，而 9/18 日本央行預期鷹派加息、聯儲點陣圖仍指向年內再加一次，兩股力量方向相反。上一版把 P(A) 設為 0.55 並押注息率續升的結構，day 1 即被推翻，故本版不再對方向下重注，改為只持有兩態皆贏的部位。改動 E4 即可重算下表。
A9: 組別 | B9: 主題 | C9: 在狀態 A 下的機制 | D9: A 報酬 −2~+2 | E9: B 報酬 −2~+2 | F9: 期望值 | G9: 在狀態 B 下的機制
A10: ① | B10: 煉油與成品油 | C10: 原料成本回落而中東逾 20% 煉油產能未復 → 裂解價差維持 → 毛利擴張 | D10: 2 | E10: 2 | F10: =$E$4*D10+(1-$E$4)*E10 -> 2 | G10: 成品油價領先原油上漲，裂解再擴；俄羅斯柴油禁令疊加
A11: ② | B11: 診斷與生命科學工具 | C11: 無油品投入、本土收入、近期盈利無久期；9/16 與 9/17 兩種息率日都上升 | D11: 2 | E11: 2 | F11: =$E$4*D11+(1-$E$4)*E11 -> 2 | G11: 同一理由反向成立：息率再升時它仍然不受油價與久期傳導
A12: ③ | B12: 晶圓代工與AI半導體 | C12: AI 資本開支的利率免疫性被重新定價，9/17 單日 +6.43% | D12: 2 | E12: -1 | F12: =$E$4*D12+(1-$E$4)*E12 -> 0.5 | G12: 高 beta 長久期，日圓套息平倉或孳息重上時最先被拋
A13: ④ | B13: 太空與衛星 | C13: 地緣需求 + 息率回落對長久期成長股解壓，斜率全表第二高 | D13: 2 | E13: -1 | F13: =$E$4*D13+(1-$E$4)*E13 -> 0.5 | G13: 小型高 beta；四巫日與久期衝擊下回吐最快
A14: ⑤ | B14: 鋼鐵 | C14: 本土、關稅保護，對利率不如建商敏感；升勢有廣度 | D14: 1 | E14: 1 | F14: =$E$4*D14+(1-$E$4)*E14 -> 1 | G14: 戰爭與基建需求支撐；能源成本上升則侵蝕電爐毛利
A15: ⑥ | B15: 電氣設備與電網 | C15: AI 用電訂單不受息率左右，但 9/17 表現已落後 | D15: 1 | E15: 0 | F15: =$E$4*D15+(1-$E$4)*E15 -> 0.5 | G15: 高 beta 工業股，全面去風險時同跌
A16: ⑦ | B16: 防守：醫院與產險（已降級） | C16: 息率回落時防守性失去溢價 —— 這正是 9/17 發生的事 | D16: -1 | E16: 2 | F16: =$E$4*D16+(1-$E$4)*E16 -> 0.5 | G16: 息率再升時的避風港：浮存金以 5% 再投資、醫療需求剛性
A17: ✕ | B17: A 類：油服／區域銀行／投行／貨運／電信 | C17: 9/17 全巿反彈日依然落後，機制不因息率方向改變 | D17: -1 | E17: -1 | F17: =$E$4*D17+(1-$E$4)*E17 -> -1 | G17: 孳息再升則持債虧損與 deal flow 問題加深
A18: △ | B18: B 類：SMR／鈾／稀土／數位資產／建商／量子 | C18: 實質利率見頂 → 反彈續延（9/17 單日 +1.3% 至 +8.0%） | D18: 2 | E18: -2 | F18: =$E$4*D18+(1-$E$4)*E18 -> 0 | G18: 孳息重上 5.1% → 立即回到 9/16 的殺跌形態，這是本清單最大的單一反向風險
B19: 受惠組期望值平均 | F19: =AVERAGE(F10:F15) -> 1.0833333
B20: 迴避／中性組期望值平均 | F20: =AVERAGE(F17:F18) -> -0.5
A22: 讀法：只有第①組（煉油）與第②組（診斷工具）在兩態下都是 +2 —— 這是本清單唯一不需要猜息率方向的部分，也是 R1.01 唯一在 9/17 完全兌現的部分。第③④組在狀態 B 下轉負，第⑦組的 A/B 為 −1/+2，B 類的 A/B 為 +2/−2：後兩者是同一個賭注的兩面，方向相反，因此兩邊都只能小注。上一版的錯誤正是把第⑦組當成核心倉 —— 那其實是對息率方向下注，而不是對機制下注。

Sheet 數據來源與限制 Sources
A1: 數據來源、方法與已知限制
A2: R2.00 · 生成 2026-09-18 09:00 HKT · 模型 claude-opus-5（high effort）
A4: 一、價格與成交量
A5: 項目 | B5: 內容 | C5: 說明 | D5: 欄位
A6: 來源 | B6: Yahoo Finance 每日 OHLCV，經 GitHub Actions runner 以 yfinance 抓取後提交回倉庫 | C6: 本環境的出口代理封鎖所有財經網站，直接抓取不可行；故於 runner 上執行後將資料提交回 repo | D6: data/yahoo/broad_2026-09-19.csv.gz
A7: 基準日 | B7: 2026-09-17（美東週四）收市 | C7: 前收＝2026-09-16；5 日前收＝2026-09-10（5 個交易日） | D7: 清單頁 E/F/G 欄
A8: ⚠ 9/17 的來源 | B8: 日線鏡像把 2026-09-17 發佈為「只有成交量、完全沒有價格」的列 —— 1,499 個檔案的 Open/High/Low/Close 全部為空 | C8: 週轉率檢查看不到這種故障：成交量是完整發佈的（鏡像週轉率 1.0585，一個正常交易日），缺的是價格。這與 09-14 至 09-16 的盤中快照是兩種不同的故障。因此 9/17 的價格全部來自 Yahoo tail 抓取（tail.csv.gz 546 隻 + tail_broad.csv.gz 1,692 隻） | D8: 引擎 meta 的 mirror_priceless
A9: 9/17 價格的交叉驗證 | B9: tail 用的是小時線折疊成日線的路徑。在 Yahoo 已結算日線同時覆蓋的名字上，折疊收盤價偏差 0.0000%（成交量亦然）；兩次相隔數分鐘的獨立抓取在 257 個共同代號上偏差 0.00000% | C9: 樣本雖小（結算重疊只有 5 隻），但與過去三版「收盤價永遠準確、成交量不準」的結論一致 | D9: —
A10: ⚠ 市場面板縮小 | B10: 平衡市場面板由上一版的 1,658 隻降至 1,109 隻。面板要求一隻股票在每個計分日都有報價，而 9/17 只有 Yahoo 小時線路徑覆蓋到的名字有價 | C10: 全巿中位回報因此建基於較小的樣本：9/11 +0.46%、9/14 −0.03%、9/15 −0.69%、9/16 −0.53%、9/17 +0.24% | D10: 板塊資金流證據頁
A11: ⚠ 9/17 無成交量確認 | B11: 小時線路徑的成交量不是結算印記，引擎因此把該日所有名字的量能項 B 歸零 | C11: 即 9/17 的分數只由方向（A）與收市位置（C）構成，沒有成交量確認；淨額估算亦屬臨時值並以 ≈ 標記 | D11: 全部工作表
A12: ⚠ 個別缺漏 | B12: PBF（PBF Energy）在兩次 tail 抓取中都沒有 9/17 的報價，已從工作簿剔除並記錄於 data/ratehike_geo_missing.json | C12: R1.01 曾把 PBF 列為第①組第 2 位。本版寧可剔除，也不用 9/16 的舊價充當 —— 否則百分比變動欄會讀成一個真實的走勢 | D12: —
A13: 成交量基準 | B13: 該股自身前 20 個交易日的成交量中位數 | C13: 相對量 ＝ 9/17 成交量 ÷ 該中位數（9/17 因上述原因一律顯示 1.00） | D13: 清單頁 K/L 欄
A14: 代號連結 | B14: 工作簿內每一個代號都連結到 TradingView 圖表版面 chart/Q1c5VWwD，與本項目的 HTML 報告同一個版面 | C14: 「催化劑日程」的敘述欄仍以文字提及代號（Excel 每格只容許一個連結），該行右側的「相關代號」欄提供可點擊版本 | D14: 全部工作表
A16: 二、資金流分數方法（「板塊資金流證據」頁）
A17: • 方向 A ＝ tanh((個股回報 − 全市中位回報) / 0.02)；量能 B ＝ clip(log2(clip(成交量/20日中位量, 0.25, 4))/2, −1, 1)；收位 C ＝ ((收−低)−(高−收))/(高−低)
A18: • 單股強度 f ＝ (0.70A + 0.30C) × (1 + 0.50B)；籃子以成交金額加權，並用逐次注水法將單一成分上限壓至 40%
A19: • 每日作橫截面 z 分數後轉百分位（0–100）；5 日綜合採用權重 [1.0, 1.15, 1.35, 1.6, 1.9]（越近權重越高）
A20: • 淨額估算（mfd）＝ Σ(收位 C × 成交金額)。★ 這是價量代理，不是真實資金流：13F 與 ETF 申贖資料在本環境不可達
A21: • 全市中位採用「平衡面板」：僅計入每個計分日及其前一日均有報價的股票，2026-09-17 只有 1,109 檔（見上方限制）
A23: 三、已知限制與缺陷（必讀）
A24: 項目 | B24: 內容 | C24: 影響範圍 | D24: 狀態
A25: ⚠ LNG 組別數據缺陷 | B25: 「LNG液化天然氣」組的成分股 NFE（New Fortress Energy）做了反向拆股：收市價由 9/11 的 $0.33 跳至 9/15 的 $12.77。Yahoo 的 close 欄未還原拆股（adj_close 有），引擎使用 raw close，產生 +3771% 的單日回報 | C25: 該組 5 日回報顯示 +9111%（垃圾值），且 9/10 與 9/14 兩日分數因 tanh 飽和被高估為滿分上升日。111 組中僅此 1 組受影響（現排第 72 位），其餘 110 組不受影響。本清單所推薦與迴避的標的均不在該組 | D25: 已在「板塊資金流證據」頁標記為 n/a；修正版待用戶確認
A26: ※ 淨額估算為臨時值 | B26: 9/16 成交量尚未結算。實測未結算 vs 結算：分數 p95 差 1.82 分（滿分 100）、名次最多差 4；但淨額估算中位差 1.22%、p95 16.3%、最大 75.4% | C26: 「板塊資金流證據」頁 M、N 欄的美元金額屬臨時值；分數與排名不受影響 | D26: 已於頁首與欄標題以「※」標註
A27: 資金流為價量代理 | B27: 無真實基金流向資料（13F、ETF 申贖在本環境不可達） | C27: 所有「資金流入／流出」均為價格與成交量推算，非實際申贖 | D27: 設計限制，非缺陷
A28: 判斷分數為主觀 | B28: 清單頁 M–P 欄（機制／資金流／未伸展／廣度，各 0–5）為分析員主觀評分，非計算所得 | C28: 綜合分 Q 欄由這四項加權而成；權重列於該頁黃色格，可自行調整重算 | D28: 已以藍字標示為輸入值
A29: 油輪／航運未納入追蹤範圍 | B29: Hormuz 最直接的受惠者為油輪（戰爭險費率由船體價值 0.25% 升至 7.5–10%，VLCC 日租金曾破 $100 萬），但 111 個子板塊中的「貨運與物流」僅涵蓋 UPS/FDX/ODFL 等包裹與陸運，不含油輪 | C29: FRO、DHT、INSW、TNK、STNG 等油輪股不在本追蹤宇宙內，故未列入清單。另需注意：油輪相關 ETF 年內已漲逾 3,600%，屬極度伸展 | D29: 已知覆蓋缺口
A30: 本表性質 | B30: 研究紀錄，非投資建議。3 日為極短線窗口，個股結果由倉位與流動性主導的成分高於基本面 | C30: 全表 | D30: —
A32: 四、新聞與宏觀資料來源
A33: 主題 | B33: 出處 | C33: 連結 | D33: 取用日期
A34: 9/17 收市：加息後納指回升、孳息 8 連升中斷 | B34: TheStreet | C34: https://www.thestreet.com/stock-market-today/stock-market-today-dow-jones-sp-500-nasdaq-updates-sept-17-2026 | D34: 2026-09-18
A35: 油價下跌：沙特改經 Hormuz 出口以補管線關閉 | B35: CNBC | C35: https://www.cnbc.com/2026/09/17/oil-prices-today-wti-brent-hormuz-iran-war.html | D35: 2026-09-18
A36: 油價下挫：沙特着手修復關鍵管線 | B36: gCaptain | C36: https://gcaptain.com/oil-extends-drop-as-saudi-arabia-moves-to-restore-vital-pipeline/ | D36: 2026-09-18
A37: 8 月新屋開工 −2.6%，單戶開工 +7.6% | B37: Reuters / Yahoo Finance | C37: https://finance.yahoo.com/real-estate/articles/us-single-family-housing-starts-131652276.html | D37: 2026-09-18
A38: 按揭利率 9/17：30 年期 7.01% | B38: Mortgage Daily | C38: https://www.mortgagedaily.com/rates/mortgage-rates-today-2026-09-17/ | D38: 2026-09-18
A39: 日本央行 9/18 預期加息 25bp 至 1.25%，1993 年來最高 | B39: Investing.com | C39: https://in.investing.com/news/economy-news/boj-preview-september-25-bps-hike-expected-with-hawkish-outlook-5596110 | D39: 2026-09-18
A40: 日本央行預期鷹派加息 | B40: FXStreet | C40: https://www.fxstreet.com/news/bank-of-japan-is-expected-to-deliver-a-hawkish-hike-pressured-by-rising-inflation-202609172200 | D40: 2026-09-18
A41: 煉油股估值：MPC/VLO 已高於共識目標價，評級以 Hold 居多 | B41: 24/7 Wall St. | C41: https://247wallst.com/investing/2026/09/17/think-its-too-late-to-buy-marathon-and-valero-heres-why-analysts-say-wait-instead/ | D41: 2026-09-18
A42: 美伊「油輪換油輪」互擊，停火談判破裂 | B42: Al Jazeera | C42: https://www.aljazeera.com/news/2026/9/6/us-iran-engaged-in-tanker-war-where-is-the-months-long-conflict-headed | D42: 2026-09-18
A43: FOMC 9/16 加息 25bp 至 3.75–4.00% | B43: CNBC | C43: https://www.cnbc.com/2026/09/16/fed-rate-decision-september-2026.html | D43: 2026-09-18
A44: Warsh：通脹仍然過高（會議實錄） | B44: CNBC | C44: https://www.cnbc.com/2026/09/16/fed-meeting-today-live-updates.html | D44: 2026-09-18
...
