Workbook

Sheet 摘要 Summary
A1: 加息及地緣政治 3 日觀察清單 R1.01
A2: 基準：2026-09-16 美東收市 · 涵蓋交易日：2026-09-17（四）、09-18（五）、09-21（一） · 生成：2026-09-17 15:16 HKT · claude-opus-5 / high
A4: 一、當前 regime：三個同時發生的衝擊
A5: 面向 | B5: 事件 | C5: 關鍵數字 | G5: 對股票的傳導
A6: 貨幣政策 | B6: 9/16 FOMC 加息 25bp 至 3.75–4.00%，2023 年 7 月以來首次，票數 12-0。主席 Kevin Warsh（非 Powell） | D6: 點陣圖：18 人中 16 人預期年內再加一次，4 人預期兩次；年底中位 4.1%，2027/9 約 4.5% | G6: 折現率上升 → 無盈利長久期資產受創最深；收息型金融受惠，持久期型金融受損
A7: 利率市場 | B7: 10 年期美債孳息突破 5%，19 年新高（2007 年以來最高） | D7: 9/15 盤中 5.04% | G7: 債券代理股（電信、公用、REIT）失去相對吸引力；按揭利率跟升壓住房地產
A8: 地緣政治 | B8: 9/10 無人機（經伊拉克）襲擊沙特 East–West 輸油管。該管是 Hormuz 的替代路線，伊朗封鎖海峽後承載每日 4–5 百萬桶 | D8: 油價當周 +8% 破 $100；月內 +16%。9/16 美國能源部長稱「數日內」重啟 → Brent −2.7% 收 $105.83、WTI −3.2% 收 $102.43 | G8: 原油供應可望恢復，但中東逾 20% 煉油產能因實體損毀停擺 → 原油與成品油分道揚鑣
A10: 二、核心判斷
A11: • 未來 3 日只有兩種狀態：A＝輸油管如期重啟、油續回落、通脹預期降溫；B＝修復實際需 5–6 週（業界估計，與能源部長說法矛盾）或 Hormuz 再有船隻遇襲、油再爆上。
A12: • 本清單不賭油價方向，而是持有「在 A、B 兩態下都贏」的兩個價差：①裂解價差 vs 原油（煉油商做多裂解、做空原油）；②收保費 vs 持久期（保險 vs 銀行）。
A13: • 輸油管重啟恢復的是「原油供應」，不是「煉油產能」——後者因實體損毀無法隨管線修復而回來。這正是 9/16 能源板塊內部出現 7.4 個百分點分歧的原因。
A15: 三、清單統計（公式即時計算，隨清單頁改動更新）
A16: 指標 | B16: 數值 | D16: 指標 | E16: 數值 | G16: 說明
A17: 受惠股檔數 | B17: =COUNT('3日受惠清單 Watchlist'!Q9:Q33) -> 25 | D17: 迴避股檔數 | E17: =COUNTA('迴避清單 Avoid'!B9:B34) -> 26 | G17: 兩表合計覆蓋的美股檔數
A18: 受惠股平均綜合分 | B18: =AVERAGE('3日受惠清單 Watchlist'!Q9:Q33) -> 79.36 | D18: 受惠股 9/16 平均漲跌 | E18: =AVERAGE('3日受惠清單 Watchlist'!H9:H33) -> 0.022517396 | G18: 綜合分為 0–100，權重可於清單頁黃色格調整
A19: 綜合分 ≥ 80 檔數 | B19: =COUNTIF('3日受惠清單 Watchlist'!Q9:Q33,">=80") -> 13 | D19: 迴避股 9/16 平均漲跌 | E19: =AVERAGE('迴避清單 Avoid'!G9:G34) -> -0.0353725 | G19: 當日兩表平均表現差距即為輪動幅度
A20: 9/16 全市中位漲跌 | B20: -0.0048680527 | D20: 9/16 市場面板檔數 | E20: 1658 | G20: 來源：SubSector 資金流向 Watchlist R11.00 平衡市場面板
A22: 四、上一輪判斷的錯誤與修正（透明度）
A23: 上一輪的判斷 | C23: 結果 | E23: 錯在哪裡 | G23: 本輪如何修正
A24: 能源上游列為順勢 | C24: 9/16 頁岩 E&P −6.42%（成交量 4.57x），為 111 組最差 | E24: 交易了「油價水平」而非「油價催化劑」。已 +16% 的倉位，真正風險是供應恢復的頭條，而該頭條 6 日內就出現 | G24: 改為持有煉油（裂解價差），其多頭邏輯不需要原油上漲，且供應恢復對它有利
A25: 銀行列為順勢 | C25: 區域銀行 −3.91%（2.40x）、投行 −3.48%（1.91x） | E25: 未區分「收息的金融」與「持久期的金融」。5% 的 10Y 對存款成本、持債虧損、deal flow 是利空 | G25: 改為產險與再保：浮存金以 5% 再投資，無存款 beta、無持債虧損，另加 Hormuz 戰爭險硬市場
A26: AI 基建列為避開 | C26: 9/16 光通訊/CPO +5.61%、AI 資料中心 +2.20%、晶圓代工 +2.47% | E26: 低估了 AI 資本開支對利率的免疫性——Warsh 在聲明中親自點名該開支為通脹來源之一 | G26: 納入 AI 半導體，但僅列戰術小注並標註「5 日仍為負、屬反彈非趨勢」，不作核心倉
A28: 本表為研究紀錄，非投資建議。所有判斷分數為分析員主觀評分，方法與限制見「數據來源與限制」頁。

Sheet 3日受惠清單 Watchlist
A1: 3 日受惠股清單 Rate-Hike & Geopolitical 3-Day Watchlist R1.01
A2: 基準 2026-09-16 美東收市 · H/I/L/Q 欄為公式，黑字＝公式、藍字＝輸入值、黃底＝可調整假設 · 代號可點擊開 TradingView 圖表
M4: 綜合分權重（黃底＝可調整輸入，改動後 Q 欄即時重算）
M5: 機制強度 | N5: 資金流確認 | O5: 未伸展度 | P5: 廣度 | Q5: 合計
M6: 0.4 | N6: 0.25 | O6: 0.2 | P6: 0.15 | Q6: =SUM(M6:P6) -> 1
A8: 組別 | B8: 主題板塊 | C8: 代號 | D8: 公司 | E8: 收市 09-16 | F8: 前收 09-15 | G8: 5日前收 09-09 | H8: 09-16 漲跌% | I8: 5日 漲跌% | J8: 09-16 成交量 | K8: 20日 中位量 | L8: 相對量 | M8: 機制 0-5 | N8: 資金流 0-5 | O8: 未伸展 0-5 | P8: 廣度 0-5 | Q8: 綜合分 0-100 | R8: 受惠機制（為何這 3 日會贏） | S8: 狀態A：油續跌 | T8: 狀態B：油再爆 | U8: 失效條件 / 注意
A9: ① | B9: 煉油與成品油 | C9: VLO | D9: Valero Energy | E9: 403.28 | F9: 397.04 | G9: 388.95 | H9: =E9/F9-1 -> 0.015716301 | I9: =E9/G9-1 -> 0.036842782 | J9: 3522494 | K9: 2629700 | L9: =J9/K9 -> 1.3395041 | M9: 5 | N9: 5 | O9: 4 | P9: 5 | Q9: =(M9*$M$6+N9*$N$6+O9*$O$6+P9*$P$6)*20 -> 96 | R9: 最純粹的美國煉油商，墨西哥灣出口槓桿最高。做多裂解價差、做空原油：輸油管重啟降低原料成本，而中東逾20%煉油產能實體損毀無法隨之恢復 | S9: 強（原料成本下降、裂解維持） | T9: 強（成品油價領先原油上漲） | U9: Hormuz 停火且中東煉廠產能加速修復 → 裂解崩塌
A10: ① | B10: 煉油與成品油 | C10: PBF | D10: PBF Energy | E10: 75.93 | F10: 74.72 | G10: 76.51 | H10: =E10/F10-1 -> 0.01619379 | I10: =E10/G10-1 -> -0.0075807084 | J10: 3811063 | K10: 2415250 | L10: =J10/K10 -> 1.5779166 | M10: 5 | N10: 5 | O10: 5 | P10: 3 | Q10: =(M10*$M$6+N10*$N$6+O10*$O$6+P10*$P$6)*20 -> 94 | R10: 財務槓桿最高，對裂解價差的 beta 最大；5 日仍為 −0.76%，是組內最未伸展的一隻 | S10: 強（毛利彈性最大） | T10: 強（彈性最大，雙刃） | U10: 小型股、波動最大；裂解回落時跌幅亦最大
A11: ① | B11: 煉油與成品油 | C11: DINO | D11: HF Sinclair | E11: 113.97 | F11: 112.25 | G11: 108.14 | H11: =E11/F11-1 -> 0.01532294 | I11: =E11/G11-1 -> 0.053911596 | J11: 2091749 | K11: 2328700 | L11: =J11/K11 -> 0.89824752 | M11: 5 | N11: 5 | O11: 3 | P11: 5 | Q11: =(M11*$M$6+N11*$N$6+O11*$O$6+P11*$P$6)*20 -> 92 | R11: 中陸地區煉廠，柴油佔比高，直接對應柴油裂解創紀錄的 $108/桶與美國柴油首破 $6/加侖 | S11: 強 | T11: 強 | U11: 5 日已 +5.39%，組內最伸展；俄羅斯柴油禁令若於 9/30 到期不續 → 柴油裂解回落
A12: ① | B12: 煉油與成品油 | C12: MPC | D12: Marathon Petroleum | E12: 413.92 | F12: 410.84 | G12: 399.44 | H12: =E12/F12-1 -> 0.0074968358 | I12: =E12/G12-1 -> 0.036250751 | J12: 2868447 | K12: 2295550 | L12: =J12/K12 -> 1.2495685 | M12: 5 | N12: 4 | O12: 4 | P12: 5 | Q12: =(M12*$M$6+N12*$N$6+O12*$O$6+P12*$P$6)*20 -> 91 | R12: 美國煉油產能最大，搭配零售網絡，規模最穩健的參與方式 | S12: 強 | T12: 強 | U12: 同組風險；規模大 → 彈性小於 PBF/DINO
A13: ① | B13: 煉油與成品油 | C13: PSX | D13: Phillips 66 | E13: 264.63 | F13: 264.93 | G13: 260.78 | H13: =E13/F13-1 -> -0.0011323746 | I13: =E13/G13-1 -> 0.014763402 | J13: 2670800 | K13: 2685750 | L13: =J13/K13 -> 0.99443358 | M13: 4 | N13: 3 | O13: 4 | P13: 5 | Q13: =(M13*$M$6+N13*$N$6+O13*$O$6+P13*$P$6)*20 -> 78 | R13: 中游與化工佔比較高，純煉油度較低；9/16 是組內唯一收跌（−0.11%） | S13: 中 | T13: 中 | U13: 中游業務使其部分對沖掉裂解上行，純度最低
A14: ② | B14: 醫院與醫療服務 | C14: THC | D14: Tenet Healthcare | E14: 265.78 | F14: 260.85 | G14: 269.08 | H14: =E14/F14-1 -> 0.018899751 | I14: =E14/G14-1 -> -0.012264011 | J14: 628980 | K14: 713550 | L14: =J14/K14 -> 0.88147992 | M14: 4 | N14: 5 | O14: 5 | P14: 5 | Q14: =(M14*$M$6+N14*$N$6+O14*$O$6+P14*$P$6)*20 -> 92 | R14: 零石油投入、收入全數本土、近期盈利無久期。5 日仍為 −1.23%，是本組最未伸展的一隻 | S14: 強（防守性 + 資金回流） | T14: 強（唯一不受油價傳導的板塊） | U14: 醫保報銷政策消息；週五四巫日引發全面去風險時仍會下跌
A15: ② | B15: 醫院與醫療服務 | C15: UHS | D15: Universal Health Services | E15: 181.21 | F15: 176.85 | G15: 175.78 | H15: =E15/F15-1 -> 0.024653661 | I15: =E15/G15-1 -> 0.030890886 | J15: 881541 | K15: 621000 | L15: =J15/K15 -> 1.4195507 | M15: 4 | N15: 5 | O15: 4 | P15: 5 | Q15: =(M15*$M$6+N15*$N$6+O15*$O$6+P15*$P$6)*20 -> 88 | R15: 9/16 組內最強（+2.47%），成交 1.42x，行為醫療佔比高 | S15: 強 | T15: 強 | U15: 同上；個別州份醫保費率消息
A16: ② | B16: 醫院與醫療服務 | C16: HCA | D16: HCA Healthcare | E16: 430.43 | F16: 423.82 | G16: 421.83 | H16: =E16/F16-1 -> 0.015596244 | I16: =E16/G16-1 -> 0.02038736 | J16: 1369642 | K16: 1319750 | L16: =J16/K16 -> 1.0378041 | M16: 4 | N16: 5 | O16: 4 | P16: 5 | Q16: =(M16*$M$6+N16*$N$6+O16*$O$6+P16*$P$6)*20 -> 88 | R16: 規模最大、現金流最穩，是防守配置的核心持股 | S16: 強 | T16: 強 | U16: 同上
A17: ② | B17: 醫院與醫療服務 | C17: EHC | D17: Encompass Health | E17: 123.91 | F17: 122 | G17: 121.52 | H17: =E17/F17-1 -> 0.015655738 | I17: =E17/G17-1 -> 0.019667544 | J17: 879222 | K17: 753800 | L17: =J17/K17 -> 1.1663863 | M17: 4 | N17: 4 | O17: 4 | P17: 5 | Q17: =(M17*$M$6+N17*$N$6+O17*$O$6+P17*$P$6)*20 -> 83 | R17: 康復照護，需求剛性，與經濟周期關聯最低 | S17: 強 | T17: 強 | U17: 同上
A18: ② | B18: 診斷與生命科學工具 | C18: A | D18: Agilent Technologies | E18: 153.69 | F18: 150.27 | G18: 144.75 | H18: =E18/F18-1 -> 0.022759034 | I18: =E18/G18-1 -> 0.061761658 | J18: 2507653 | K18: 2570400 | L18: =J18/K18 -> 0.97558862 | M18: 4 | N18: 4 | O18: 3 | P18: 4 | Q18: =(M18*$M$6+N18*$N$6+O18*$O$6+P18*$P$6)*20 -> 76 | R18: 5 日分數 100.0（111 組之首）組別的成員；9/16 +2.28% 而 5 日 +6.18%，仍屬可接受 | S18: 強 | T18: 中強 | U18: 5 日組別已 +6.65%，整組偏伸展；中國採購與 NIH 預算消息
A19: ② | B19: 診斷與生命科學工具 | C19: TMO | D19: Thermo Fisher Scientific | E19: 648.43 | F19: 641.39 | G19: 605.69 | H19: =E19/F19-1 -> 0.010976161 | I19: =E19/G19-1 -> 0.07056415 | J19: 2879941 | K19: 1669300 | L19: =J19/K19 -> 1.7252387 | M19: 4 | N19: 4 | O19: 2 | P19: 4 | Q19: =(M19*$M$6+N19*$N$6+O19*$O$6+P19*$P$6)*20 -> 72 | R19: 組內權重最大；資金流確認明確（組別 5 日淨流入 +$45.2 億） | S19: 強 | T19: 中強 | U19: 5 日 +7.06%，已伸展；追價風險
A20: ③ | B20: 電氣設備與電網 | C20: GEV | D20: GE Vernova | E20: 925.09 | F20: 882.81 | G20: 951.04 | H20: =E20/F20-1 -> 0.047892525 | I20: =E20/G20-1 -> -0.027285919 | J20: 3556586 | K20: 1958000 | L20: =J20/K20 -> 1.8164382 | M20: 4 | N20: 5 | O20: 4 | P20: 3 | Q20: =(M20*$M$6+N20*$N$6+O20*$O$6+P20*$P$6)*20 -> 82 | R20: 9/16 +4.79%、成交 1.82x，組內最強。AI 用電中「有訂單、有定價權」的一邊——與零收入的 SMR/鈾形成鏡像（後者 5 日 −17.7%/−16.3%） | S20: 強 | T20: 中（高 beta，去風險時同跌） | U20: 高 beta 工業股；9/18 日本央行鷹派 + 四巫日引發全面去槓桿時首當其衝
... A33: ⑥ | B33: 鋼鐵（觀察） | C33: CLF | D33: Cleveland-Cliffs | E33: 12.15 | F33: 11.79 | G33: 12.09 | H33: =E33/F33-1 -> 0.030534351 | I33: =E33/G33-1 -> 0.0049627792 | J33: 14277992 | K33: 12008650 | L33: =J33/K33 -> 1.1889756 | M33: 3 | N33: 4 | O33: 4 | P33: 3 | Q33: =(M33*$M$6+N33*$N$6+O33*$O$6+P33*$P$6)*20 -> 69 | R33: 9/16 +3.05%，組內最強；高槓桿小型股 | S33: 中 | T33: 中強 | U33: 同上；高負債對 5% 利率敏感
B34: 組合平均 | H34: =AVERAGE(H9:H33) -> 0.022517396 | I34: =AVERAGE(I9:I33) -> 0.0051477269 | L34: =AVERAGE(L9:L33) -> 1.2132351 | Q34: =AVERAGE(Q9:Q33) -> 79.36
A36: 組別說明：① 煉油＝最高信心（兩態皆贏） ② 醫療服務／工具＝資金流最確認 ③ 電網＝AI 用電中有收入的一邊 ④ 產險再保＝唯一「想要」5% 孳息的金融 ⑤ AI 半導體＝戰術小注 ⑥ 鋼鐵＝觀察不建倉

Sheet 迴避清單 Avoid
A1: 3 日迴避清單 Avoid List R1.01
A2: 基準 2026-09-16 美東收市 · G/H/K 欄為公式 · 代號可點擊開 TradingView 圖表 · 列出「有具體理由」的迴避標的，非泛泛看淡
A8: 類別 | B8: 代號 | C8: 公司 | D8: 收市 09-16 | E8: 前收 09-15 | F8: 5日前收 09-09 | G8: 09-16 漲跌% | H8: 5日 漲跌% | I8: 09-16 成交量 | J8: 20日 中位量 | K8: 相對量 | L8: 迴避理由 | M8: 何時反手做多
A9: 頁岩E&P／油服 | B9: FANG | C9: Diamondback Energy | D9: 194.54 | E9: 211.53 | F9: 202.63 | G9: =D9/E9-1 -> -0.080319576 | H9: =D9/F9-1 -> -0.039924986 | I9: 15400011 | J9: 1852750 | K9: =I9/J9 -> 8.3119746 | L9: 擁擠多倉在 8.31x 成交量下爆掉——全表最極端的量能。前一交易日同組 APA 才創 52 週新高 | M9: 輸油管修復證實需 5–6 週，且量能回落至 1.5x 以下
A10: 頁岩E&P／油服 | B10: OXY | C10: Occidental Petroleum | D10: 59.36 | E10: 63.52 | F10: 61.3 | G10: =D10/E10-1 -> -0.065491184 | H10: =D10/F10-1 -> -0.031647635 | I10: 11536216 | J10: 7087900 | K10: =I10/J10 -> 1.6275929 | L10: 同上；−6.55%、成交 1.63x
A11: 頁岩E&P／油服 | B11: COP | C11: ConocoPhillips | D11: 132.54 | E11: 141.22 | F11: 136.53 | G11: =D11/E11-1 -> -0.061464382 | H11: =D11/F11-1 -> -0.029224346 | I11: 9045920 | J11: 6032150 | K11: =I11/J11 -> 1.4996179 | L11: 同上；−6.15%、成交 1.50x
A12: 頁岩E&P／油服 | B12: EOG | C12: EOG Resources | D12: 144.93 | E12: 153.74 | F12: 147.01 | G12: =D12/E12-1 -> -0.05730454 | H12: =D12/F12-1 -> -0.014148697 | I12: 4385565 | J12: 2869250 | K12: =I12/J12 -> 1.5284709 | L12: 同上；−5.73%、成交 1.53x
A13: 頁岩E&P／油服 | B13: DVN | C13: Devon Energy | D13: 48.44 | E13: 51.33 | F13: 48.98 | G13: =D13/E13-1 -> -0.056302357 | H13: =D13/F13-1 -> -0.011024908 | I13: 14976497 | J13: 10321150 | K13: =I13/J13 -> 1.4510493 | L13: 同上；−5.63%、成交 1.45x
A14: 頁岩E&P／油服 | B14: SLB | C14: SLB (Schlumberger) | D14: 52.3 | E14: 54.2 | F14: 57.05 | G14: =D14/E14-1 -> -0.035055351 | H14: =D14/F14-1 -> -0.083260298 | I14: 21322320 | J14: 11813250 | K14: =I14/J14 -> 1.8049495 | L14: 油服 5 日 −8.33%；上游資本開支預期隨油價回落而下修
A15: 頁岩E&P／油服 | B15: HAL | C15: Halliburton | D15: 34.51 | E15: 35.67 | F15: 37.13 | G15: =D15/E15-1 -> -0.032520325 | H15: =D15/F15-1 -> -0.070562887 | I15: 13783174 | J15: 9902350 | K15: =I15/J15 -> 1.3919094 | L15: 同上；5 日 −7.06%
A16: 頁岩E&P／油服 | B16: RIG | C16: Transocean | D16: 5.54 | E16: 5.94 | F16: 5.71 | G16: =D16/E16-1 -> -0.067340067 | H16: =D16/F16-1 -> -0.029772329 | I16: 58121780 | J16: 39924850 | K16: =I16/J16 -> 1.4557795 | L16: 海上鑽井組 9/16 −5.47%，為 111 組第 109 位
A17: 綜合油氣巨頭 | B17: XOM | C17: Exxon Mobil | D17: 163.32 | E17: 169.32 | F17: 164.23 | G17: =D17/E17-1 -> -0.035435861 | H17: =D17/F17-1 -> -0.0055410096 | I17: 13428810 | J17: 13779050 | K17: =I17/J17 -> 0.9745817 | L17: −3.54%；上游佔比高，與煉油分部的對沖不足以抵銷 | M17: 下游佔比提升或裂解利潤入賬體現
A18: 綜合油氣巨頭 | B18: CVX | C18: Chevron | D18: 211.54 | E18: 217.77 | F18: 213.81 | G18: =D18/E18-1 -> -0.028608165 | H18: =D18/F18-1 -> -0.010616903 | I18: 8045164 | J18: 7908100 | K18: =I18/J18 -> 1.0173321 | L18: −2.86%；同上
A19: 區域銀行 | B19: USB | C19: U.S. Bancorp | D19: 59.73 | E19: 62.22 | F19: 62.11 | G19: =D19/E19-1 -> -0.040019286 | H19: =D19/F19-1 -> -0.038319111 | I19: 17454429 | J19: 6283850 | K19: =I19/J19 -> 2.7776648 | L19: 5% 的 10Y ＝ 持債未實現虧損擴大 + 存款成本上升 + CRE 曝險。−4.00%、成交 2.78x 屬明顯分派 | M19: 孳息曲線轉陡（長端回落而短端不動）
A20: 區域銀行 | B20: PNC | C20: PNC Financial | D20: 231.49 | E20: 240.78 | F20: 240.69 | G20: =D20/E20-1 -> -0.038582939 | H20: =D20/F20-1 -> -0.038223441 | I20: 2752968 | J20: 1456000 | K20: =I20/J20 -> 1.8907747 | L20: 同上；−3.86%、成交 1.89x
A21: 區域銀行 | B21: ZION | C21: Zions Bancorporation | D21: 65.47 | E21: 67.99 | F21: 68.11 | G21: =D21/E21-1 -> -0.037064274 | H21: =D21/F21-1 -> -0.038760828 | I21: 2312683 | J21: 1298600 | K21: =I21/J21 -> 1.7809048 | L21: 同上；−3.71%、成交 1.78x
A22: 投行與資本巿場 | B22: GS | C22: Goldman Sachs | D22: 937.98 | E22: 976.67 | F22: 1028.78 | G22: =D22/E22-1 -> -0.039614199 | H22: =D22/F22-1 -> -0.088259881 | I22: 3546168 | J22: 1800900 | K22: =I22/J22 -> 1.9691088 | L22: 5 日 −8.83%；孳息 5% 下 IPO/M&A 窗口關閉，deal flow 凍結 | M22: 孳息回落至 4.5% 以下且併購公告回升
A23: 投行與資本巿場 | B23: MS | C23: Morgan Stanley | D23: 202.42 | E23: 206.28 | F23: 215.35 | G23: =D23/E23-1 -> -0.01871243 | H23: =D23/F23-1 -> -0.060041792 | I23: 6999366 | J23: 3925900 | K23: =I23/J23 -> 1.7828692 | L23: 同上；5 日 −6.00%
A24: 鈾與核燃料／SMR | B24: OKLO | C24: Oklo | D24: 35.62 | E24: 35.98 | F24: 42.57 | G24: =D24/E24-1 -> -0.010005559 | H24: =D24/F24-1 -> -0.16326051 | I24: 7791736 | J24: 7796150 | K24: =I24/J24 -> 0.99943382 | L24: 零收入、長久期，加息周期中最先被殺。5 日 −16.33%（組別 −17.74%，111 組最差之一） | M24: 孳息見頂回落，或簽訂有實質現金流的 offtake
A25: 鈾與核燃料／SMR | B25: CCJ | C25: Cameco | D25: 90.9 | E25: 91.21 | F25: 100.41 | G25: =D25/E25-1 -> -0.0033987501 | H25: =D25/F25-1 -> -0.094711682 | I25: 2114588 | J25: 2289300 | K25: =I25/J25 -> 0.92368322 | L25: 鈾組 5 日 −16.32%，廣度 0.04（幾乎全組下跌）
A26: 稀土與關鍵礦產 | B26: MP | C26: MP Materials | D26: 48.99 | E26: 49.17 | F26: 54.3 | G26: =D26/E26-1 -> -0.0036607688 | H26: =D26/F26-1 -> -0.097790055 | I26: 3766247 | J26: 4808850 | K26: =I26/J26 -> 0.78319078 | L26: 5 日 −9.78%（組別 −13.96%）；同屬長久期主題股
A27: 住宅建築商 | B27: DHI | C27: D.R. Horton | D27: 138.32 | E27: 140.2 | F27: 138.93 | G27: =D27/E27-1 -> -0.013409415 | H27: =D27/F27-1 -> -0.0043907004 | I27: 3932995 | J27: 1928200 | K27: =I27/J27 -> 2.0397236 | L27: 10Y 5% → 按揭利率跟升。已在 2.04x 成交量下下跌，而 9/17（週四）8 月新屋開工就是直接的向下催化劑 | M27: 10Y 明確跌穿 4.5%
A28: 住宅建築商 | B28: LEN | C28: Lennar | D28: 78.36 | E28: 80.07 | F28: 80.76 | G28: =D28/E28-1 -> -0.021356313 | H28: =D28/F28-1 -> -0.029717682 | I28: 6117645 | J28: 2451200 | K28: =I28/J28 -> 2.4957755 | L28: 同上；成交 2.50x
A29: 數位資產 | B29: COIN | C29: Coinbase | D29: 164.51 | E29: 172.11 | F29: 174.72 | G29: =D29/E29-1 -> -0.044157806 | H29: =D29/F29-1 -> -0.058436355 | I29: 13685409 | J29: 9628700 | K29: =I29/J29 -> 1.4213143 | L29: 實質利率 beta 最高的一類；−4.42%（組別 5 日 −8.10%、淨流出 −$81.2 億） | M29: 實質利率見頂
A30: 貨運與物流 | B30: FDX | C30: FedEx | D30: 301.72 | E30: 308.26 | F30: 309.19 | G30: =D30/E30-1 -> -0.021215857 | H30: =D30/F30-1 -> -0.024159902 | I30: 1578698 | J30: 1287650 | K30: =I30/J30 -> 1.2260304 | L30: 指引下調屬多日重估而非一日事件；組別 9/16 −4.94%、成交 3.15x | M30: 指引重設後的首次上修
A31: 貨運與物流 | B31: UPS | C31: United Parcel Service | D31: 98.77 | E31: 102.35 | F31: 99.22 | G31: =D31/E31-1 -> -0.034978017 | H31: =D31/F31-1 -> -0.0045353759 | I31: 4943050 | J31: 3717400 | K31: =I31/J31 -> 1.3297062 | L31: 同上；−3.50%
A32: 電信／債券代理 | B32: T | C32: AT&T | D32: 25.86 | E32: 26.72 | F32: 25.15 | G32: =D32/E32-1 -> -0.032185629 | H32: =D32/F32-1 -> 0.028230616 | I32: 37788742 | J32: 32823800 | K32: =I32/J32 -> 1.1512604 | L32: 5% 無風險利率下股息吸引力被壓縮；−3.22% | M32: 孳息回落
A33: 電信／債券代理 | B33: VZ | C33: Verizon | D33: 49.76 | E33: 51.45 | F33: 49.74 | G33: =D33/E33-1 -> -0.032847425 | H33: =D33/F33-1 -> 0.00040209087 | I33: 24326001 | J33: 18057600 | K33: =I33/J33 -> 1.3471337 | L33: 同上；−3.28%
A34: 再生能源 | B34: NEE | C34: NextEra Energy | D34: 80.37 | E34: 81.07 | F34: 82.65 | G34: =D34/E34-1 -> -0.0086345134 | H34: =D34/F34-1 -> -0.027586207 | I34: 9620130 | J34: 11151200 | K34: =I34/J34 -> 0.86269908 | L34: 公用事業 + 再生能源雙重久期曝險；組別 9/16 −2.67% | M34: 孳息回落 + 稅務抵免政策明朗
C35: 組合平均 | G35: =AVERAGE(G9:G34) -> -0.0353725 | H35: =AVERAGE(H9:H34) -> -0.040972493 | K35: =AVERAGE(K9:K34) -> 1.7632512
A37: 註：迴避＝未來 3 日不新增多倉，非建議沽空。FANG 的 8.31x 成交量屬投降式放量，此類日子有時反而是階段底；但在 +16% 月線漲幅後遇上供應恢復頭條，3 日內的基準情境是震盪而非 V 型反彈。

Sheet 板塊資金流證據 Evidence
A1: 111 個子板塊資金流證據（可追溯全表）
A2: 來源：SubSector 資金流向 Watchlist R11.00 · 視窗 2026-09-10 → 2026-09-16 · 按 5 日綜合分排序 · 成分股可點擊 · ※ 淨額含 9/16 未結算成交量，屬臨時值
A8: 5日 排名 | B8: 子板塊 | C8: English | D8: 大板塊 | E8: 5日 分數 | F8: 09-16 分數 | G8: 09-16 漲跌% | H8: 5日 漲跌% | I8: 09-16 廣度 | J8: 5日 廣度 | K8: 09-16 相對量 | L8: 斜率 | M8: 09-16 淨額※ (US$ 百萬) | N8: 5日 淨額※ (US$ 百萬) | O8: 成分股 1 | P8: 成分股 2 | Q8: 成分股 3 | R8: 成分股 4 | S8: 成分股 5 | T8: 成分股 6 | U8: 成分股 7 | V8: 成分股 8 | W8: 備註
A9: =ROW()-8 -> 1 | B9: 診斷與生命科學工具 | C9: Diagnostics & Life-Science Tools | D9: 醫療保健 Health Care | E9: 100 | F9: 93.636364 | G9: 0.0147074 | H9: 0.066509813 | I9: 1 | J9: 0.75 | K9: 1.6252503 | L9: 0.55498252 | M9: 397.4116 | N9: 4514.7595 | O9: TMO | P9: DHR | Q9: A | R9: ILMN | W9: ★ 第②組：5 日分數 111 組之首，但 5 日已 +6.65%
A10: =ROW()-8 -> 2 | B10: 網絡安全 | C10: Cybersecurity | D10: 資訊科技 Information Technology | E10: 99.090909 | F10: 70 | G10: -0.0063529154 | H10: 0.14407601 | I10: 0.6 | J10: 0.72 | K10: 1.2056076 | L10: 0.19967646 | M10: 756.12812 | N10: 13175.115 | O10: PANW | P10: CRWD | Q10: ZS | R10: FTNT | S10: S
A11: =ROW()-8 -> 3 | B11: 醫院與醫療服務 | C11: Hospitals & Providers | D11: 醫療保健 Health Care | E11: 98.181818 | F11: 99.090909 | G11: 0.018701329 | H11: 0.014697885 | I11: 1 | J11: 0.7 | K11: 1.1257927 | L11: 0.50696032 | M11: 551.34085 | N11: 775.50221 | O11: HCA | P11: THC | Q11: UHS | R11: EHC | W11: ★ 第②組：9/16 廣度 1.00，5 日僅 +1.47% ＝ 未伸展
A12: =ROW()-8 -> 4 | B12: 煉油與成品油 | C12: Refining & Marketing | D12: 能源 Energy | E12: 97.272727 | F12: 97.272727 | G12: 0.0093509291 | H12: 0.035448149 | I12: 1 | J12: 0.6 | K12: 1.3313237 | L12: 0.70385235 | M12: 1645.1907 | N12: -1170.092 | O12: MPC | P12: PSX | Q12: VLO | R12: DINO | W12: ★ 本清單第①組：9/16 能源板塊中唯一上升，與頁岩 E&P 同日相差 7.4 個百分點
A13: =ROW()-8 -> 5 | B13: 電子硬件與EMS/連接器 | C13: Electronic Hardware, EMS & Connectors | D13: 資訊科技 Information Technology | E13: 96.363636 | F13: 91.818182 | G13: 0.0069276738 | H13: -0.0069110916 | I13: 0.83333333 | J13: 0.56666667 | K13: 1.5023634 | L13: 0.041897028 | M13: -4145.374 | N13: 26421.869 | O13: AAPL | P13: DELL | Q13: FLEX | R13: JBL | S13: APH | T13: TEL
A14: =ROW()-8 -> 6 | B14: 產險與再保 | C14: P&C Insurance & Reinsurance | D14: 金融 Financials | E14: 95.454545 | F14: 69.090909 | G14: -0.0035217874 | H14: 0.018319473 | I14: 0.8 | J14: 0.84 | K14: 1.0475353 | L14: -0.06348112 | M14: -108.30407 | N14: 1456.1848 | O14: CB | P14: TRV | Q14: PGR | R14: AIG | S14: RNR | W14: ★ 第④組：5 日廣度 0.84 為全表最高
A15: =ROW()-8 -> 7 | B15: 國防科技與無人機 | C15: Defense Tech & Drones | D15: 工業 Industrials | E15: 94.545455 | F15: 67.272727 | G15: -0.029705611 | H15: -0.0045562373 | I15: 0.5 | J15: 0.6 | K15: 1.3860294 | L15: 0.018171324 | M15: 429.31057 | N15: 490.63825 | O15: AVAV | P15: KTOS | Q15: RCAT | R15: ONDS
A16: =ROW()-8 -> 8 | B16: 資料/分析平台 | C16: Data & Analytics Platforms | D16: 資訊科技 Information Technology | E16: 93.636364 | F16: 92.727273 | G16: 0.0084862641 | H16: 0.025928054 | I16: 1 | J16: 0.65 | K16: 0.80205816 | L16: 0.31713559 | M16: 2973.7962 | N16: 6137.6228 | O16: PLTR | P16: SNOW | Q16: MDB | R16: DDOG
A17: =ROW()-8 -> 9 | B17: 大型網絡平台與數位廣告 | C17: Mega-cap Internet & Digital Ads | D17: 通訊服務 Communication Services | E17: 92.727273 | F17: 61.818182 | G17: -0.00076793241 | H17: 0.033619096 | I17: 0.5 | J17: 0.7 | K17: 0.95358247 | L17: -0.017624025 | M17: -11879.125 | N17: -4885.0755 | O17: GOOGL | P17: META
A18: =ROW()-8 -> 10 | B18: 社交與線上社群 | C18: Social & Community Platforms | D18: 通訊服務 Communication Services | E18: 91.818182 | F18: 29.090909 | G18: -0.013979229 | H18: 0.056762346 | I18: 0 | J18: 0.7 | K18: 0.99741073 | L18: -0.77718631 | M18: -539.5472 | N18: 724.90172 | O18: PINS | P18: SNAP | Q18: RDDT | R18: MTCH
A19: =ROW()-8 -> 11 | B19: 鋼鐵 | C19: Steel | D19: 原材料 Materials | E19: 90.909091 | F19: 87.272727 | G19: 0.0098624199 | H19: 0.0010365175 | I19: 1 | J19: 0.65 | K19: 1.0389518 | L19: 0.29121759 | M19: -84.038426 | N19: 113.69091 | O19: NUE | P19: STLD | Q19: CLF | R19: RS | W19: ★ 第⑥組：觀察，方向未確立
A20: =ROW()-8 -> 12 | B20: 壽險與年金 | C20: Life Insurance & Annuities | D20: 金融 Financials | E20: 90 | F20: 49.090909 | G20: -0.011971666 | H20: 0.007634741 | I20: 0.2 | J20: 0.76 | K20: 1.4013709 | L20: -0.24955639 | M20: -97.222205 | N20: 1154.6748 | O20: MET | P20: PRU | Q20: AFL | R20: LNC | S20: EQH
A21: =ROW()-8 -> 13 | B21: 醫療器械 | C21: Medical Devices | D21: 醫療保健 Health Care | E21: 89.090909 | F21: 77.272727 | G21: 0.0034123918 | H21: 0.014371549 | I21: 0.8 | J21: 0.64 | K21: 1.3505636 | L21: 0.16652916 | M21: -1508.2748 | N21: -1883.9967 | O21: ABT | P21: MDT | Q21: SYK | R21: BSX | S21: ISRG
A22: =ROW()-8 -> 14 | B22: 電氣設備與電網 | C22: Electrical Equipment & Grid | D22: 工業 Industrials | E22: 88.181818 | F22: 94.545455 | G22: 0.012918895 | H22: -0.02876588 | I22: 0.8 | J22: 0.48 | K22: 1.3364999 | L22: 0.31748212 | M22: 1202.1132 | N22: -734.52299 | O22: ETN | P22: EMR | Q22: PWR | R22: HUBB | S22: GEV | W22: ★ 第③組：9/16 單日 94.5 分而 5 日 −2.88% ＝ 動能已重置
A23: =ROW()-8 -> 15 | B23: 家庭與個人護理 | C23: Household & Personal Care | D23: 必需消費 Consumer Staples | E23: 87.272727 | F23: 73.636364 | G23: 0.00011324884 | H23: -0.0031767633 | I23: 0.6 | J23: 0.64 | K23: 1.0567009 | L23: 0.08640644 | M23: -571.20343 | N23: -730.65181 | O23: PG | P23: CL | Q23: KMB | R23: CHD | S23: EL
A24: =ROW()-8 -> 16 | B24: 辦公樓REIT | C24: Office REITs | D24: 房地產 Real Estate | E24: 86.363636 | F24: 90 | G24: 0.0021056657 | H24: 0.00031641566 | I24: 1 | J24: 0.55 | K24: 1.435241 | L24: 0.086423015 | M24: 70.510059 | N24: -70.606021 | O24: BXP | P24: VNO | Q24: SLG | R24: HIW
A25: =ROW()-8 -> 17 | B25: AI資料中心建設 | C25: AI Data Center Buildout | D25: 資訊科技 Information Technology | E25: 85.454545 | F25: 96.363636 | G25: 0.022030389 | H25: -0.027457775 | I25: 1 | J25: 0.48 | K25: 1.3449647 | L25: 0.47425188 | M25: -523.55904 | N25: -2392.5659 | O25: VRT | P25: SMCI | Q25: ANET | R25: MOD | S25: CIEN
A26: =ROW()-8 -> 18 | B26: 人力與商業服務 | C26: Staffing & Business Services | D26: 工業 Industrials | E26: 84.545455 | F26: 47.272727 | G26: -0.012671972 | H26: 0.0055515432 | I26: 0.2 | J26: 0.56 | K26: 1.2238691 | L26: -0.20279103 | M26: -581.5303 | N26: 264.97143 | O26: ADP | P26: PAYX | Q26: MAN | R26: RHI | S26: CTAS
A27: =ROW()-8 -> 19 | B27: 工業與物流REIT | C27: Industrial & Logistics REITs | D27: 房地產 Real Estate | E27: 83.636364 | F27: 51.818182 | G27: -0.005066806 | H27: -0.0024600226 | I27: 0.75 | J27: 0.65 | K27: 1.2389644 | L27: 0.085819501 | M27: -261.53301 | N27: 322.33965 | O27: PLD | P27: EGP | Q27: FR | R27: STAG
A28: =ROW()-8 -> 20 | B28: 串流影音 | C28: Streaming Video | D28: 通訊服務 Communication Services | E28: 82.727273 | F28: 56.363636 | G28: -0.005480306 | H28: 0.013260943 | I28: 0.5 | J28: 0.75 | K28: 1.1661145 | L28: -0.47461984 | M28: -2117.1319 | N28: 956.19325 | O28: NFLX | P28: DIS | Q28: WBD | R28: ROKU
A29: =ROW()-8 -> 21 | B29: 數位醫療與遠距醫療 | C29: Digital Health & Telehealth | D29: 醫療保健 Health Care | E29: 81.818182 | F29: 80 | G29: -0.0038640389 | H29: 0.03728191 | I29: 0.75 | J29: 0.7 | K29: 0.95574021 | L29: -0.19158103 | M29: 1.7893333 | N29: -136.35289 | O29: HIMS | P29: TDOC | Q29: DOCS | R29: OSCR
A30: =ROW()-8 -> 22 | B30: 資料中心REIT | C30: Data Center REITs | D30: 房地產 Real Estate | E30: 80.909091 | F30: 89.090909 | G30: 0.009578554 | H30: -0.034082569 | I30: 1 | J30: 0.6 | K30: 1.1870484 | L30: 0.51887311 | M30: -300.09309 | N30: -748.46036 | O30: EQIX | P30: DLR
A31: =ROW()-8 -> 23 | B31: 大型藥廠 | C31: Large-cap Pharma | D31: 醫療保健 Health Care | E31: 80 | F31: 79.090909 | G31: 0.00037866827 | H31: 0.0027559085 | I31: 1 | J31: 0.7 | K31: 0.78571592 | L31: 0.20287672 | M31: -469.21019 | N31: -7867.7426 | O31: LLY | P31: JNJ | Q31: PFE | R31: MRK | S31: ABBV | T31: BMY
A32: =ROW()-8 -> 24 | B32: 支付與收單 | C32: Payments & Merchant Acquiring | D32: 金融 Financials | E32: 79.090909 | F32: 33.636364 | G32: -0.018630852 | H32: -0.0046298601 | I32: 0 | J32: 0.64 | K32: 0.99837951 | L32: -0.28681636 | M32: -1822.7456 | N32: 2501.6557 | O32: V | P32: MA | Q32: PYPL | R32: GPN | S32: TOST
A33: =ROW()-8 -> 25 | B33: 工業自動化與機器人 | C33: Industrial Automation & Robotics | D33: 工業 Industrials | E33: 78.181818 | F33: 85.454545 | G33: 0.0067884729 | H33: -0.034127555 | I33: 0.75 | J33: 0.55 | K33: 1.1504855 | L33: 0.28985128 | M33: -215.12886 | N33: -1792.071 | O33: ROK | P33: SYM | Q33: NDSN | R33: TER
A34: =ROW()-8 -> 26 | B34: 航太與國防 | C34: Aerospace & Defense | D34: 工業 Industrials | E34: 77.272727 | F34: 55.454545 | G34: -0.0026018577 | H34: 0.0085833948 | I34: 0.83333333 | J34: 0.7 | K34: 1.6400877 | L34: -0.051713056 | M34: -197.36342 | N34: -550.46321 | O34: LMT | P34: RTX | Q34: NOC | R34: GD | S34: LHX | T34: BA
A35: =ROW()-8 -> 27 | B35: 教育與消費服務 | C35: Education & Consumer Services | D35: 非必需消費 Consumer Discretionary | E35: 76.363636 | F35: 23.636364 | G35: -0.013465401 | H35: 0.0069314175 | I35: 0 | J35: 0.73333333 | K35: 1.2948094 | L35: -0.21062848 | M35: -119.28222 | N35: -85.30137 | O35: LRN | P35: HRB | Q35: SCI
A36: =ROW()-8 -> 28 | B36: 酒精飲品 | C36: Alcoholic Beverages | D36: 必需消費 Consumer Staples | E36: 75.454545 | F36: 57.272727 | G36: -0.0059814262 | H36: 0.0058049949 | I36: 0.75 | J36: 0.7 | K36: 1.1570117 | L36: -0.20338015 | M36: -251.66834 | N36: -310.45257 | O36: STZ | P36: BF.B | Q36: TAP | R36: DEO
A37: =ROW()-8 -> 29 | B37: 傳媒與娛樂內容 | C37: Media & Entertainment Content | D37: 通訊服務 Communication Services | E37: 74.545455 | F37: 78.181818 | G37: -0.0080488851 | H37: -0.019250198 | I37: 0.5 | J37: 0.45 | K37: 1.1112427 | L37: 0.23645761 | M37: -180.88846 | N37: -426.96165 | O37: LYV | P37: FWONK | Q37: NWSA | R37: PARA
A38: =ROW()-8 -> 30 | B38: 食品加工 | C38: Packaged Food | D38: 必需消費 Consumer Staples | E38: 73.636364 | F38: 80.909091 | G38: 0.0047777721 | H38: -0.0012075652 | I38: 1 | J38: 0.6 | K38: 1.0009921 | L38: 0.37358445 | M38: -332.39582 | N38: -411.26753 | O38: GIS | P38: KHC | Q38: HSY | R38: CAG
A39: =ROW()-8 -> 31 | B39: 煙草與尼古丁 | C39: Tobacco & Nicotine | D39: 必需消費 Consumer Staples | E39: 72.727273 | F39: 59.090909 | G39: -0.0022606102 | H39: 0.007188328 | I39: 0.66666667 | J39: 0.6 | K39: 0.82504035 | L39: -0.11181312 | M39: -485.47836 | N39: -676.79087 | O39: PM | P39: MO | Q39: TPB
A40: =ROW()-8 -> 32 | B40: IT服務與系統整合 | C40: IT Services & Consulting | D40: 資訊科技 Information Technology | E40: 71.818182 | F40: 9.0909091 | G40: -0.03167568 | H40: 0.033167301 | I40: 0 | J40: 0.64 | K40: 1.0013318 | L40: -0.50347607 | M40: -1209.217 | N40: 1351.5966 | O40: ACN | P40: IBM | Q40: INFY | R40: CTSH | S40: EPAM
A41: =ROW()-8 -> 33 | B41: 電信營運商 | C41: Telecom Carriers | D41: 通訊服務 Communication Services | E41: 70.909091 | F41: 4.5454545 | G41: -0.029453675 | H41: 0.0075205635 | I41: 0 | J41: 0.73333333 | K41: 1.3416078 | L41: -0.61732101 | M41: -1559.9009 | N41: -460.45288 | O41: T | P41: VZ | Q41: TMUS | W41: ✕ 迴避：債券代理股
A42: =ROW()-8 -> 34 | B42: 光通訊/CPO | C42: Optical Networking & CPO | D42: 資訊科技 Information Technology | E42: 70 | F42: 100 | G42: 0.056087864 | H42: -0.065738413 | I42: 1 | J42: 0.52 | K42: 1.5011155 | L42: 0.88489067 | M42: 4935.4514 | N42: -13290.148 | O42: COHR | P42: LITE | Q42: AAOI | R42: CRDO | S42: POET | W42: ★ 第⑤組（戰術）：9/16 全表最強，但 5 日 −6.57%、淨流出 −$132.9 億
A43: =ROW()-8 -> 35 | B43: 電商平台 | C43: E-commerce Platforms | D43: 非必需消費 Consumer Discretionary | E43: 69.090909 | F43: 64.545455 | G43: -0.0032267091 | H43: 0.019001863 | I43: 0.6 | J43: 0.6 | K43: 1.0931858 | L43: -0.31153545 | M43: -2850.3022 | N43: -1660.183 | O43: AMZN | P43: SHOP | Q43: EBAY | R43: CHWY | S43: W
A44: =ROW()-8 -> 36 | B44: 大賣場與超巿 | C44: Hypermarkets & Grocery | D44: 必需消費 Consumer Staples | E44: 68.181818 | F44: 31.818182 | G44: -0.015084066 | H44: 0.039735972 | I44: 0 | J44: 0.64 | K44: 0.99463614 | L44: -0.34713025 | M44: -3533.55 | N44: -3937.4948 | O44: WMT | P44: COST | Q44: KR | R44: BJ | S44: ACI
A45: =ROW()-8 -> 37 | B45: EDA與半導體IP | C45: EDA & Semiconductor IP | D45: 資訊科技 Information Technology | E45: 67.272727 | F45: 98.181818 | G45: 0.01995424 | H45: -0.042878283 | I45: 1 | J45: 0.53333333 | K45: 1.0200347 | L45: 0.1447496 | M45: 545.47072 | N45: -2978.4948 | O45: SNPS | P45: CDNS | Q45: ARM | W45: ★ 第⑤組（戰術）
...

Sheet 代號索引 Ticker Index
A1: 代號索引 Ticker Index
A2: 基準 2026-09-16 美東收市 · 工作簿內全部 493 個代號，每個都可點擊開 TradingView 圖表 · I/J/M 欄為公式 · 表頭可篩選排序
A8: 代號 | B8: 受惠清單 | C8: 迴避清單 | D8: 所屬子板塊（可多於一個） | E8: 子板塊 最佳5日排名 | F8: 收市 09-16 | G8: 前收 09-15 | H8: 5日前收 09-09 | I8: 09-16 漲跌% | J8: 5日 漲跌% | K8: 09-16 成交量 | L8: 20日 中位量 | M8: 相對量
A9: A | B9: ② | C9: — | D9: 診斷與生命科學工具 | E9: 1 | F9: 153.69 | G9: 150.27 | H9: 144.75 | I9: =F9/G9-1 -> 0.022759034 | J9: =F9/H9-1 -> 0.061761658 | K9: 2507653 | L9: 2570400 | M9: =K9/L9 -> 0.97558862
A10: AA | B10: — | C10: — | D10: 鋁業 | E10: 102 | F10: 46.26 | G10: 46.52 | H10: 50.73 | I10: =F10/G10-1 -> -0.005588994 | J10: =F10/H10-1 -> -0.088113542 | K10: 3582218 | L10: 3571800 | M10: =K10/L10 -> 1.0029167
A11: AAL | B11: — | C11: — | D11: 航空公司 | E11: 49 | F11: 12.7 | G11: 12.77 | H11: 12.94 | I11: =F11/G11-1 -> -0.0054815975 | J11: =F11/H11-1 -> -0.018547141 | K11: 137508157 | L11: 63556800 | M11: =K11/L11 -> 2.1635475
A12: AAOI | B12: — | C12: — | D12: 光通訊/CPO | E12: 34 | F12: 96.74 | G12: 95.29 | H12: 107.93 | I12: =F12/G12-1 -> 0.015216707 | J12: =F12/H12-1 -> -0.10367831 | K12: 6995300 | L12: 6115750 | M12: =K12/L12 -> 1.1438172
A13: AAON | B13: — | C13: — | D13: 樓宇產品與HVAC | E13: 64 | F13: 75.56 | G13: 74.32 | H13: 77.02 | I13: =F13/G13-1 -> 0.016684607 | J13: =F13/H13-1 -> -0.018956115 | K13: 1011085 | L13: 1039650 | M13: =K13/L13 -> 0.97252441
A14: AAPL | B14: — | C14: — | D14: 電子硬件與EMS/連接器 | E14: 5 | F14: 332.41 | G14: 331.34 | H14: 315.34 | I14: =F14/G14-1 -> 0.0032293113 | J14: =F14/H14-1 -> 0.054132048 | K14: 35870203 | L14: 39438000 | M14: =K14/L14 -> 0.90953403
A15: ABBV | B15: — | C15: — | D15: 大型藥廠 | E15: 23 | F15: 262.51 | G15: 263.04 | H15: 250.91 | I15: =F15/G15-1 -> -0.0020149027 | J15: =F15/H15-1 -> 0.046231717 | K15: 3117811 | L15: 4355550 | M15: =K15/L15 -> 0.71582487
A16: ABT | B16: — | C16: — | D16: 醫療器械 | E16: 13 | F16: 102.36 | G16: 102.03 | H16: 105.23 | I16: =F16/G16-1 -> 0.0032343428 | J16: =F16/H16-1 -> -0.027273591 | K16: 5229532 | L16: 7524150 | M16: =K16/L16 -> 0.69503293
A17: ACI | B17: — | C17: — | D17: 大賣場與超巿 | E17: 36 | F17: 12.56 | G17: 12.84 | H17: 11.85 | I17: =F17/G17-1 -> -0.021806854 | J17: =F17/H17-1 -> 0.059915612 | K17: 6550657 | L17: 6019100 | M17: =K17/L17 -> 1.0883117
A18: ACM | B18: — | C18: — | D18: 工程建設/EPC | E18: 51 | F18: 62.81 | G18: 64.16 | H18: 64.02 | I18: =F18/G18-1 -> -0.021041147 | J18: =F18/H18-1 -> -0.018900344 | K18: 1626220 | L18: 1821200 | M18: =K18/L18 -> 0.89293872
A19: ACN | B19: — | C19: — | D19: IT服務與系統整合 | E19: 32 | F19: 189.64 | G19: 193.4 | H19: 175.8 | I19: =F19/G19-1 -> -0.019441572 | J19: =F19/H19-1 -> 0.078725825 | K19: 3317201 | L19: 4839150 | M19: =K19/L19 -> 0.68549249
A20: ADBE | B20: — | C20: — | D20: 企業軟體/SaaS | E20: 43 | F20: 250.5 | G20: 257.76 | H20: 254.86 | I20: =F20/G20-1 -> -0.028165736 | J20: =F20/H20-1 -> -0.017107432 | K20: 4405737 | L20: 4611700 | M20: =K20/L20 -> 0.95533903
... A45: AON | B45: — | C45: — | D45: 保險經紀 | E45: 84 | F45: 300.57 | G45: 304.67 | H45: 304.69 | I45: =F45/G45-1 -> -0.013457183 | J45: =F45/H45-1 -> -0.01352194 | K45: 3194450 | L45: 1466500 | M45: =K45/L45 -> 2.1782816
A46: APA | B46: — | C46: — | D46: — | F46: 44.79 | G46: 47.41 | H46: 44.84 | I46: =F46/G46-1 -> -0.055262603 | J46: =F46/H46-1 -> -0.0011150758 | K46: 9160080 | L46: 4866200 | M46: =K46/L46 -> 1.8823887
A47: APD | B47: — | C47: — | D47: 特種化工 | E47: 46 | F47: 287.08 | G47: 290.56 | H47: 295.24 | I47: =F47/G47-1 -> -0.011976872 | J47: =F47/H47-1 -> -0.027638531 | K47: 1465770 | L47: 957300 | M47: =K47/L47 -> 1.5311501
A48: APH | B48: — | C48: — | D48: 電子硬件與EMS/連接器 | E48: 5 | F48: 77.26 | G48: 77.65 | H48: 81.34 | I48: =F48/G48-1 -> -0.005022537 | J48: =F48/H48-1 -> -0.050159823 | K48: 8898792 | L48: 11044800 | M48: =K48/L48 -> 0.8056997
A49: APO | B49: — | C49: — | D49: 另類資產與私募信貸 | E49: 100 | F49: 124.53 | G49: 127 | H49: 130.98 | I49: =F49/G49-1 -> -0.019448819 | J49: =F49/H49-1 -> -0.049244159 | K49: 3062118 | L49: 2204050 | M49: =K49/L49 -> 1.3893142
A50: APTV | B50: — | C50: — | D50: 傳統汽車與零部件 | E50: 65 | F50: 43.34 | G50: 43.75 | H50: 44.51 | I50: =F50/G50-1 -> -0.0093714286 | J50: =F50/H50-1 -> -0.026286228 | K50: 3101679 | L50: 3747950 | M50: =K50/L50 -> 0.8275668
A51: ARES | B51: — | C51: — | D51: 另類資產與私募信貸 | E51: 100 | F51: 124.21 | G51: 129.1 | H51: 134.37 | I51: =F51/G51-1 -> -0.037877614 | J51: =F51/H51-1 -> -0.075612116 | K51: 1803125 | L51: 1713350 | M51: =K51/L51 -> 1.0523974
A52: ARM | B52: — | C52: — | D52: EDA與半導體IP | E52: 37 | F52: 243.98 | G52: 241.83 | H52: 264.23 | I52: =F52/G52-1 -> 0.0088905429 | J52: =F52/H52-1 -> -0.076637778 | K52: 2647545 | L52: 3819600 | M52: =K52/L52 -> 0.69314719
A53: ARVN | B53: — | C53: — | D53: 腫瘤與細胞治療 | E53: 50 | F53: 8.16 | G53: 8.26 | H53: 8.76 | I53: =F53/G53-1 -> -0.012106538 | J53: =F53/H53-1 -> -0.068493151 | K53: 742605 | L53: 562700 | M53: =K53/L53 -> 1.3197174
A54: ASML | B54: — | C54: — | D54: 半導體設備 | E54: 88 | F54: 1602.22 | G54: 1591.48 | H54: 1729.52 | I54: =F54/G54-1 -> 0.0067484354 | J54: =F54/H54-1 -> -0.073604237 | K54: 1333155 | L54: 1140050 | M54: =K54/L54 -> 1.1693829
A55: ASPI | B55: — | C55: — | D55: 小型模組化核能SMR | E55: 108 | F55: 3.15 | G55: 3.16 | H55: 3.82 | I55: =F55/G55-1 -> -0.003164557 | J55: =F55/H55-1 -> -0.17539267 | K55: 3490226 | L55: 3629800 | M55: =K55/L55 -> 0.96154774
A56: ASTS | B56: — | C56: — | D56: 太空與衛星、有線/寬頻/衛星 | E56: 40 | F56: 59.27 | G56: 58.77 | H56: 62.42 | I56: =F56/G56-1 -> 0.008507742 | J56: =F56/H56-1 -> -0.050464595 | K56: 7180000 | L56: 8418700 | M56: =K56/L56 -> 0.85286327
A57: ATO | B57: — | C57: — | D57: 燃氣公用 | E57: 77 | F57: 161.96 | G57: 162.04 | H57: 166.59 | I57: =F57/G57-1 -> -0.00049370526 | J57: =F57/H57-1 -> -0.027792785 | K57: 1180765 | L57: 850300 | M57: =K57/L57 -> 1.3886452
A58: AU | B58: — | C58: — | D58: 黃金與貴金屬礦 | E58: 66 | F58: 99.74 | G58: 100.71 | H58: 108.53 | I58: =F58/G58-1 -> -0.0096316155 | J58: =F58/H58-1 -> -0.080991431 | K58: 1819531 | L58: 2588500 | M58: =K58/L58 -> 0.70292872
... A351: PAYX | B351: — | C351: — | D351: 人力與商業服務 | E351: 18 | F351: 116.72 | G351: 118.3 | H351: 114.75 | I351: =F351/G351-1 -> -0.013355875 | J351: =F351/H351-1 -> 0.017167756 | K351: 2424368 | L351: 2290400 | M351: =K351/L351 -> 1.0584911
A352: PBF | B352: ① | C352: — | D352: — | F352: 75.93 | G352: 74.72 | H352: 76.51 | I352: =F352/G352-1 -> 0.01619379 | J352: =F352/H352-1 -> -0.0075807084 | K352: 3811063 | L352: 2415250 | M352: =K352/L352 -> 1.5779166
A353: PCAR | B353: — | C353: — | D353: 機械與重工 | E353: 39 | F353: 118.22 | G353: 122.46 | H353: 121.88 | I353: =F353/G353-1 -> -0.034623551 | J353: =F353/H353-1 -> -0.030029537 | K353: 2697578 | L353: 2337100 | M353: =K353/L353 -> 1.1542416
A354: PEP | B354: — | C354: — | D354: 非酒精飲品 | E354: 47 | F354: 134.34 | G354: 135.5 | H354: 136.69 | I354: =F354/G354-1 -> -0.0085608856 | J354: =F354/H354-1 -> -0.017192187 | K354: 6762364 | L354: 7004350 | M354: =K354/L354 -> 0.96545204
A355: PFE | B355: — | C355: — | D355: 大型藥廠 | E355: 23 | F355: 27.46 | G355: 27.55 | H355: 27.78 | I355: =F355/G355-1 -> -0.0032667877 | J355: =F355/H355-1 -> -0.011519078 | K355: 26039670 | L355: 31473650 | M355: =K355/L355 -> 0.82734827
A356: PFGC | B356: — | C356: — | D356: 必需品分銷 | E356: 92 | F356: 91.06 | G356: 88.97 | H356: 95.63 | I356: =F356/G356-1 -> 0.023491064 | J356: =F356/H356-1 -> -0.047788351 | K356: 1818303 | L356: 1367050 | M356: =K356/L356 -> 1.3300925
A357: PG | B357: — | C357: — | D357: 家庭與個人護理 | E357: 15 | F357: 147.02 | G357: 146.67 | H357: 142.64 | I357: =F357/G357-1 -> 0.0023863094 | J357: =F357/H357-1 -> 0.030706674 | K357: 6949663 | L357: 8753700 | M357: =K357/L357 -> 0.79391149
A358: PGR | B358: — | C358: — | D358: 產險與再保 | E358: 6 | F358: 216.99 | G358: 221.31 | H358: 215.5 | I358: =F358/G358-1 -> -0.01952013 | J358: =F358/H358-1 -> 0.0069141531 | K358: 1645711 | L358: 1795450 | M358: =K358/L358 -> 0.91660085
A359: PHM | B359: — | C359: — | D359: 住宅建築商 | E359: 44 | F359: 117.55 | G359: 119.47 | H359: 118.93 | I359: =F359/G359-1 -> -0.01607098 | J359: =F359/H359-1 -> -0.011603464 | K359: 1454349 | L359: 1215550 | M359: =K359/L359 -> 1.1964535
A360: PINS | B360: — | C360: — | D360: 社交與線上社群 | E360: 10 | F360: 18.65 | G360: 18.76 | H360: 18.28 | I360: =F360/G360-1 -> -0.0058635394 | J360: =F360/H360-1 -> 0.0202407 | K360: 12810545 | L360: 10737100 | M360: =K360/L360 -> 1.1931103
A361: PKG | B361: — | C361: — | D361: 包裝與建材 | E361: 59 | F361: 231.45 | G361: 231.21 | H361: 227.28 | I361: =F361/G361-1 -> 0.0010380174 | J361: =F361/H361-1 -> 0.018347413 | K361: 517329 | L361: 544850 | M361: =K361/L361 -> 0.94948885
...

Sheet 催化劑日程 Catalysts
A1: 未來 3 個交易日催化劑日程
A2: 基準 2026-09-16 美東收市 · 時間為美東時間 · 「相關代號」欄的代號可點擊開 TradingView 圖表
A8: 日期 | B8: 星期 | C8: 事件 | D8: 時間 (ET) | E8: 為何重要 | F8: 衝擊哪些清單項目 | G8: 方向偏好 | H8: 相關代號 1 | I8: 相關代號 2 | J8: 相關代號 3 | K8: 相關代號 4 | L8: 相關代號 5 | M8: 相關代號 6 | N8: 相關代號 7
A9: 2026-09-17 | B9: 四 | C9: 8 月新屋開工 + 營建許可 | D9: 08:30 | E9: 10Y 在 5% ＝ 30 年按揭跟升。這是本週唯一直接針對利率敏感板塊的數據 | F9: 迴避：DHI、LEN（已在 2.0–2.5x 量能下跌） | G9: 利空建商 | H9: DHI | I9: LEN
A10: 2026-09-17 | B10: 四 | C10: 初領失業救濟金 | D10: 08:30 | E10: Warsh 稱經濟「正在走強」並以就業數據佐證。強數據 ＝ 再加息機率上升 ＝ 孳息再上 | F10: 受惠：TRV、RNR、AIG、CB（息差）／迴避：OKLO、CCJ、MP | G10: 強數據利好保險、利空長久期 | H10: TRV | I10: RNR | J10: AIG | K10: CB | L10: OKLO | M10: CCJ | N10: MP
A11: 2026-09-17 | B11: 四 | C11: FOMC 靜默期結束，官員開始發言 | D11: 全日 | E11: 點陣圖顯示 16/18 預期年內再加一次——官員措辭將決定市場如何定價「下一次」 | F11: 全表；尤其第④組保險與所有迴避項目 | G11: 偏鷹 → 強化本清單配置
A12: 2026-09-17 | B12: 四 | C12: 沙特 East–West 輸油管修復進展／衛星影像 | D12: 不定 | E12: ★ 本清單最大單一變數。能源部長稱「數日」vs 業界估計 5–6 週，兩者矛盾 | F12: 全表：決定狀態 A 或狀態 B | G12: 見「情境矩陣」頁
A13: 2026-09-18 | B13: 五 | C13: 日本央行議息 | D13: 日本時間上午，美股盤前 | E13: 美 10Y 在 5% 之際若 BOJ 轉鷹 → 日圓套息平倉 → 全球久期衝擊 | F13: 第③組 GEV／ETN、第⑤組 AI 半導體（高 beta 最先被拋） | G13: 風險事件，非方向事件 | H13: GEV | I13: ETN
A14: 2026-09-18 | B14: 五 | C14: 四巫日（季度期權期指同時到期）+ 標普季度再平衡 | D14: 收市 | E14: 9 月第三個週五。巨額 gamma 到期 → 當日走勢多由倉位而非基本面決定 | F14: 第⑤組 AI 半導體（單日彈 5–9% 最易被打回）；低 beta 高廣度項目相對安全 | G14: 波動放大；宜避免追高 | H14: COHR | I14: LITE | J14: CRDO | K14: SNPS | L14: CDNS
A15: 2026-09-18 | B15: 五 | C15: 8 月工業生產、經濟諮商局領先指標 | D15: 09:15 / 10:00 | E15: 若領先指標走弱而 Fed 仍鷹 → 滯脹定價，利好防守性醫療 | F15: 第②組 THC、UHS、HCA、EHC | G15: 弱數據利好醫療服務 | H15: THC | I15: UHS | J15: HCA | K15: EHC
A16: 2026-09-21 | B16: 一 | C16: 到期後倉位重置 | D16: 開市 | E16: 四巫日後的第一個交易日，被 gamma 壓抑的走勢通常於此釋放 | F16: 全表 | G16: 趨勢確認日
A17: 2026-09-21 | B17: 一 | C17: Hormuz 航運事件／戰爭險費率更新 | D17: 不定 | E17: 自上週六起已有至少兩艘船隻在 Hormuz 遇襲。費率已由船體價值 0.25% 升至 7.5–10% | F17: 第④組 RNR（戰爭再保）／第①組煉油 | G17: 再有襲擊 → 狀態 B | H17: RNR | I17: VLO | J17: MPC | K17: PBF | L17: DINO | M17: PSX
A18: 2026-09-30 | B18: （參考） | C18: 俄羅斯柴油出口禁令到期日 | D18: — | E18: 禁令已延長至 9/30。俄佔全球柴油約 10%，8 月煉油量 380 萬桶/日為二十年最低 | F18: 第①組全部：若不續期，柴油裂解可能回落 | G18: 本清單 3 日窗口外，但屬第①組主要失效條件 | H18: VLO | I18: MPC | J18: PBF | K18: DINO | L18: PSX

Sheet 情境矩陣 Scenarios
A1: 兩態情境矩陣 Scenario Matrix
A2: 狀態機率為可調整輸入（黃底藍字）；期望值 ＝ P(A)×A 報酬 + P(B)×B 報酬，報酬分 −2 至 +2
B4: 狀態 A：輸油管如期重啟、油續回落 | C4: 美國能源部長 Chris Wright 稱沙特 East–West 管「數日內」恢復；油價自 $105.83 / $102.43 進一步回落，通脹預期降溫，長端孳息喘定 | D4: P(A) | E4: 0.55
B5: 狀態 B：修復需 5–6 週或再有襲擊、油再爆 | C5: 業界估計修復需 5–6 週，與官方說法矛盾；或 Hormuz 再有船隻遇襲（上週六以來已至少兩艘）。油再破頂，孳息續升 | D5: P(B) | E5: =1-E4 -> 0.45
A7: 機率為分析員主觀設定：能源部長的公開表態具體且可證偽，但業界修復估計與之矛盾，故未給予壓倒性權重。改動 E4 即可重算下表。
A9: 組別 | B9: 主題 | C9: 在狀態 A 下的機制 | D9: A 報酬 −2~+2 | E9: B 報酬 −2~+2 | F9: 期望值 | G9: 在狀態 B 下的機制
A10: ① | B10: 煉油與成品油 | C10: 原料成本下降而中東逾 20% 煉油產能實體損毀未復 → 裂解價差維持 → 毛利擴張 | D10: 2 | E10: 2 | F10: =$E$4*D10+(1-$E$4)*E10 -> 2 | G10: 成品油價領先原油上漲，裂解再擴；俄羅斯柴油禁令疊加 → 毛利同樣擴張
A11: ② | B11: 醫療服務／工具 | C11: 無油品投入、本土收入；資金自能源與銀行流入的主要去處 | D11: 2 | E11: 2 | F11: =$E$4*D11+(1-$E$4)*E11 -> 2 | G11: 唯一完全不受油價傳導的板塊；滯脹環境下的防守核心
A12: ③ | B12: 電氣設備與電網 | C12: AI 資本開支不受利率影響（Warsh 親自點名為通脹來源），訂單與定價權俱在 | D12: 2 | E12: 0 | F12: =$E$4*D12+(1-$E$4)*E12 -> 1.1 | G12: 高 beta 工業股，全面去風險時同跌；但訂單不受油價直接影響
A13: ④ | B13: 產險與再保 | C13: 浮存金以 5% 再投資，無存款 beta、無持債虧損 | D13: 1 | E13: 2 | F13: =$E$4*D13+(1-$E$4)*E13 -> 1.45 | G13: 戰爭險保費由船體價值 0.25% 升至 7.5–10%，硬市場加碼；息差收益不變
A14: ⑤ | B14: AI 半導體（戰術） | C14: 利率免疫敘事延續，但 5 日仍為負 → 屬反彈非趨勢 | D14: 1 | E14: 0 | F14: =$E$4*D14+(1-$E$4)*E14 -> 0.55 | G14: 四巫日 + BOJ 疊加時最先被拋；單日 5–9% 漲幅最易回吐
A15: ⑥ | B15: 鋼鐵（觀察） | C15: 本土、關稅保護，對利率不如建商敏感；但 5 日僅 +0.10%，方向未確立 | D15: 0 | E15: 1 | F15: =$E$4*D15+(1-$E$4)*E15 -> 0.45 | G15: 戰爭與基建需求支撐；能源成本上升則侵蝕電爐煉鋼毛利
A16: ✕ | B16: 頁岩 E&P／油服 | C16: 供應恢復直擊多頭核心，擁擠倉位續解 | D16: -2 | E16: 2 | F16: =$E$4*D16+(1-$E$4)*E16 -> -0.2 | G16: 油再爆則大幅反彈——這是本清單最大的反向風險
A17: ✕ | B17: 區域銀行／投行 | C17: 長端孳息喘定可帶來技術反彈，但存款成本與 CRE 問題不變 | D17: -1 | E17: -2 | F17: =$E$4*D17+(1-$E$4)*E17 -> -1.45 | G17: 孳息再升 → 持債虧損擴大、deal flow 續凍
A18: ✕ | B18: 鈾／SMR／稀土 | C18: 孳息喘定可帶來超跌反彈，但無現金流的估值問題不變 | D18: -1 | E18: -2 | F18: =$E$4*D18+(1-$E$4)*E18 -> -1.45 | G18: 實質利率再升 → 長久期無盈利資產續殺
A19: ✕ | B19: 住宅建商／債券代理 | C19: 孳息回落是唯一救贖，但 9/17 新屋開工先行 | D19: -1 | E19: -2 | F19: =$E$4*D19+(1-$E$4)*E19 -> -1.45 | G19: 按揭利率續升 → 需求與估值雙殺
B20: 受惠組期望值平均 | F20: =AVERAGE(F10:F15) -> 1.2583333
B21: 迴避組期望值平均 | F21: =AVERAGE(F16:F19) -> -1.1375
A23: 讀法：只有第①組與第②組在兩態下都是 +2 ——這就是「不賭油價方向」的具體意思。第③、⑤組在狀態 B 下歸零，故列為次級與戰術倉。頁岩 E&P 的 A/B 報酬為 −2/+2，是本清單最大的單一反向風險：若輸油管修復證實需 5–6 週，該組會強勢反彈。

Sheet 數據來源與限制 Sources
A1: 數據來源、方法與已知限制
A2: R1.01 · 生成 2026-09-17 15:16 HKT · 模型 claude-opus-5（high effort）
A4: 一、價格與成交量
A5: 項目 | B5: 內容 | C5: 說明 | D5: 欄位
A6: 來源 | B6: Yahoo Finance 每日 OHLCV，經 GitHub Actions runner 以 yfinance 抓取後提交回倉庫 | C6: 本環境的出口代理封鎖所有財經網站，直接抓取不可行；故於 runner 上執行後將資料提交回 repo | D6: data/yahoo/broad_2026-09-18.csv.gz
A7: 基準日 | B7: 2026-09-16（美東週三，FOMC 決議日）收市 | C7: 前收＝2026-09-15；5 日前收＝2026-09-09（5 個交易日） | D7: 清單頁 E/F/G 欄
A8: 成交量基準 | B8: 該股自身前 20 個交易日的成交量中位數 | C8: 相對量 ＝ 9/16 成交量 ÷ 該中位數。1.0 ＝ 正常 | D8: 清單頁 K/L 欄
A9: 代號連結 | B9: 工作簿內每一個代號都連結到 TradingView 圖表版面 chart/Q1c5VWwD，與本項目的 HTML 報告同一個版面 | C9: 共 1,073 個可點擊儲存格：受惠清單 25、迴避清單 26、板塊成分股 498、代號索引 493、催化劑日程 31。「催化劑日程」的敘述欄仍以文字提及代號（Excel 每格只容許一個連結），該行右側的「相關代號」欄提供可點擊版本 | D9: 全部工作表
A10: 9/16 結算狀態 | B10: 9/16 由 Yahoo 收市後日線提供；日線鏡像當日 14:15 ET（收市前）提交，經跨來源裁決剔除 | C10: 9/16 成交量尚未結算（結算印記佔比 1.8%）。實測：收盤價誤差中位/p95 皆為 0.0000%；成交量 p95 約 15% | D10: 影響淨額，不影響收盤價
A12: 二、資金流分數方法（「板塊資金流證據」頁）
A13: • 方向 A ＝ tanh((個股回報 − 全市中位回報) / 0.02)；量能 B ＝ clip(log2(clip(成交量/20日中位量, 0.25, 4))/2, −1, 1)；收位 C ＝ ((收−低)−(高−收))/(高−低)
A14: • 單股強度 f ＝ (0.70A + 0.30C) × (1 + 0.50B)；籃子以成交金額加權，並用逐次注水法將單一成分上限壓至 40%
A15: • 每日作橫截面 z 分數後轉百分位（0–100）；5 日綜合採用權重 [1.0, 1.15, 1.35, 1.6, 1.9]（越近權重越高）
A16: • 淨額估算（mfd）＝ Σ(收位 C × 成交金額)。★ 這是價量代理，不是真實資金流：13F 與 ETF 申贖資料在本環境不可達
A17: • 全市中位採用「平衡面板」：僅計入每個計分日及其前一日均有報價的股票，2026-09-16 為 1,658 檔
A19: 三、已知限制與缺陷（必讀）
A20: 項目 | B20: 內容 | C20: 影響範圍 | D20: 狀態
A21: ⚠ LNG 組別數據缺陷 | B21: 「LNG液化天然氣」組的成分股 NFE（New Fortress Energy）做了反向拆股：收市價由 9/11 的 $0.33 跳至 9/15 的 $12.77。Yahoo 的 close 欄未還原拆股（adj_close 有），引擎使用 raw close，產生 +3771% 的單日回報 | C21: 該組 5 日回報顯示 +9111%（垃圾值），且 9/10 與 9/14 兩日分數因 tanh 飽和被高估為滿分上升日。111 組中僅此 1 組受影響（現排第 72 位），其餘 110 組不受影響。本清單所推薦與迴避的標的均不在該組 | D21: 已在「板塊資金流證據」頁標記為 n/a；修正版待用戶確認
A22: ※ 淨額估算為臨時值 | B22: 9/16 成交量尚未結算。實測未結算 vs 結算：分數 p95 差 1.82 分（滿分 100）、名次最多差 4；但淨額估算中位差 1.22%、p95 16.3%、最大 75.4% | C22: 「板塊資金流證據」頁 M、N 欄的美元金額屬臨時值；分數與排名不受影響 | D22: 已於頁首與欄標題以「※」標註
A23: 資金流為價量代理 | B23: 無真實基金流向資料（13F、ETF 申贖在本環境不可達） | C23: 所有「資金流入／流出」均為價格與成交量推算，非實際申贖 | D23: 設計限制，非缺陷
A24: 判斷分數為主觀 | B24: 清單頁 M–P 欄（機制／資金流／未伸展／廣度，各 0–5）為分析員主觀評分，非計算所得 | C24: 綜合分 Q 欄由這四項加權而成；權重列於該頁黃色格，可自行調整重算 | D24: 已以藍字標示為輸入值
A25: 油輪／航運未納入追蹤範圍 | B25: Hormuz 最直接的受惠者為油輪（戰爭險費率由船體價值 0.25% 升至 7.5–10%，VLCC 日租金曾破 $100 萬），但 111 個子板塊中的「貨運與物流」僅涵蓋 UPS/FDX/ODFL 等包裹與陸運，不含油輪 | C25: FRO、DHT、INSW、TNK、STNG 等油輪股不在本追蹤宇宙內，故未列入清單。另需注意：油輪相關 ETF 年內已漲逾 3,600%，屬極度伸展 | D25: 已知覆蓋缺口
A26: 本表性質 | B26: 研究紀錄，非投資建議。3 日為極短線窗口，個股結果由倉位與流動性主導的成分高於基本面 | C26: 全表 | D26: —
A28: 四、新聞與宏觀資料來源
A29: 主題 | B29: 出處 | C29: 連結 | D29: 取用日期
A30: FOMC 9/16 加息 25bp 至 3.75–4.00% | B30: CNBC | C30: https://www.cnbc.com/2026/09/16/fed-rate-decision-september-2026.html | D30: 2026-09-17
A31: Warsh：通脹仍然過高（會議實錄） | B31: CNBC | C31: https://www.cnbc.com/2026/09/16/fed-meeting-today-live-updates.html | D31: 2026-09-17
A32: 2023 年以來首次加息 | B32: Fox Business | C32: https://www.foxbusiness.com/economy/federal-reserve-interest-rate-decision-september-16-2026 | D32: 2026-09-17
A33: 9/16 收市：加息後道指標普急跌 | B33: TheStreet | C33: https://www.thestreet.com/stock-market-today/stock-market-today-dow-jones-sp-500-nasdaq-updates-sept-16-2026 | D33: 2026-09-17
A34: 9/15：孳息創 19 年新高 | B34: TheStreet | C34: https://www.thestreet.com/stock-market-today/stock-market-today-sept-15-2026-dow-futures-slide-as-oil-prices-surge-and-treasury-yields-hit-2007-highs | D34: 2026-09-17
A35: 油價下跌：沙特輸油管將於數日內重啟 | B35: CNBC | C35: https://www.cnbc.com/2026/09/16/oil-prices-today-brent-wti-hormuz-iran-war.html | D35: 2026-09-17
A36: 沙特關閉繞道 Hormuz 的關鍵輸油管 | B36: CNBC | C36: https://www.cnbc.com/2026/09/13/oil-price-iran-war-strait-hormuz-saudi-pipeline.html | D36: 2026-09-17
A37: East–West 輸油管為何攸關全球石油 | B37: Al Jazeera | C37: https://www.aljazeera.com/news/2026/9/14/why-saudi-arabias-east-west-pipeline-matters-for-global-oil | D37: 2026-09-17
A38: 2026 年 East–West 輸油管襲擊事件 | B38: Wikipedia | C38: https://en.wikipedia.org/wiki/2026_East%E2%80%93West_Crude_Oil_Pipeline_attack | D38: 2026-09-17
A39: $100/桶柴油裂解價差：2026 年全球煉油的脆弱性 | B39: RBN Energy | C39: https://rbnenergy.com/daily-posts/blog/100bbl-diesel-crack-or-how-2026-exposed-fragility-global-refining | D39: 2026-09-17
A40: 美國柴油價創紀錄、煉油毛利飆升 | B40: Discovery Alert | C40: https://discoveryalert.com/analysis/us-diesel-prices-record-september-2026/ | D40: 2026-09-17
... A46: 9 月加息機率與利率期貨定價 | B46: Yahoo Finance | C46: https://finance.yahoo.com/economy/policy/articles/fomc-september-2026-odds-rate-201618784.html | D46: 2026-09-17
