Workbook

Sheet 說明
A1: 美股觀察名單 — 全體成分股「營收 / 營利」對照表 R1.00
A2: 編製時間 2026-09-07 10:18 HKT ｜ 532 隻 ｜ 涵蓋 Sub-Sector Watchlist R4.00（491 隻）與 AI Sector Watchlist R5.00（111 隻），70 隻兩表重疊
A4: 【本表用途】
A5: • 兩份資金流向報告只看價量，唔睇基本面。本表補上每隻成分股嘅「賺唔賺到錢」——最近五個季度營收、四個季度營業利益、
A6: 以及最新一季嘅毛利率／營業利益率／淨利率，令「資金流入邊個板塊」可以同「邊個板塊真係有盈利」對照睇。
A8: 【版面沿用 AI_Growth_Breakeven_Watchlist_R7.xlsx】
A9: • 同樣係「說明 / 主表 / 分級彙總 / 圖表連結 / 資料來源」結構；主表凍結窗格、開篩選、營收欄淺藍底、營利欄淺紅底、級別欄按等級上色。
A10: • 同樣將營收寫成純數字（單位「百萬」寫喺表頭），可直接排序、計算按季變動、畫圖；幣別與季度對照獨立成欄。
A11: • 不同之處（因為資料來源唔同，必須講清楚）：
A12: R7 嘅「淨利｜經常｜一次」三行拆解、「一次性項目清單」、「經常性軌跡」係逐間公司人手查財報寫出嚟嘅。
A13: 本表 532 隻全部由 Yahoo Finance 財報 API 自動抓取，冇人手核實每間公司嘅一次性項目，所以唔會憑空寫呢三欄。
A14: 取而代之，本表用「營業利益」(Operating Income) 作為經常性盈利嘅代理 —— 佢本身已剔除大部分投資收益、
... A49: • 本表為公開資料整理與研究參考，非投資建議。

Sheet 觀察名單
A1: # | B1: 美股 Ticker (按=開圖) | C1: 子板塊 SubSector (R4.00) | D1: 公司 | E1: AI 小群組 (R5.00) ／行業 | F1: 幣別 | G1: 季度對照 (Q-4 → Q0) | H1: 營收 Q-4 (百萬) | I1: 營收 Q-3 (百萬) | J1: 營收 Q-2 (百萬) | K1: 營收 Q-1 (百萬) | L1: 營收 Q0 最新 (百萬) | M1: 營收按年 % (Q0/Q-4) | N1: 營業利益 Q-3 (百萬) | O1: 營業利益 Q-2 (百萬) | P1: 營業利益 Q-1 (百萬) | Q1: 營業利益 Q0 (百萬) | R1: 營業利益率 Q0 % | S1: 毛利 Q0 (百萬) | T1: 毛利率 Q0 % | U1: 淨利 Q0 (百萬) | V1: 淨利率 Q0 % | W1: 年度營收 (最近財年, 百萬) | X1: 年度營業利益 (最近財年, 百萬) | Y1: 年度營業 利益率 % | Z1: 盈利狀態 | AA1: 級 | AB1: 資料截至
A2: 1 | B2: A | C2: 診斷與生命科學工具 | D2: Agilent Technologies, Inc. | E2: Diagnostics & Research | F2: USD | G2: 25Q3 / 25Q4 / 26Q1 / 26Q2 / 26Q3 | H2: 1738 | I2: 1861 | J2: 1798 | K2: 1835 | L2: 1878 | M2: =IF(OR(N(H2)=0,L2=""),"",L2/H2-1) -> 0.080552359 | N2: 443 | O2: 353 | P2: 399 | Q2: 444 | R2: =IF(OR(N(L2)=0,Q2=""),"",Q2/L2) -> 0.23642173 | S2: 1042 | T2: =IF(OR(N(L2)=0,S2=""),"",S2/L2) -> 0.55484558 | U2: 362 | V2: =IF(OR(N(L2)=0,U2=""),"",U2/L2) -> 0.19275825 | W2: 6948 | X2: 1479 | Y2: =IF(OR(N(W2)=0,X2=""),"",X2/W2) -> 0.21286701 | Z2: =IF(AA2="A","四季持續盈利",IF(AA2="B","最新季為正/波動",IF(AA2="C","虧損收窄",IF(AA2="D","虧損擴大或轉虧","數據不足")))) -> 四季持續盈利 | AA2: =IF(COUNT(N2:Q2)<4,"—",IF(MIN(N2:Q2)>0,"A",IF(Q2>0,"B",IF(Q2>N2,"C","D")))) -> A | AB2: 2026-07-31
A3: 2 | B3: AA | C3: 鋁業 | D3: Alcoa Corporation | E3: Aluminum | F3: USD | G3: 25Q2 / 25Q3 / 25Q4 / 26Q1 / 26Q2 | H3: 3018 | I3: 2995 | J3: 3449 | K3: 3193 | L3: 3966 | M3: =IF(OR(N(H3)=0,L3=""),"",L3/H3-1) -> 0.31411531 | N3: 51 | O3: -112 | P3: 426 | Q3: 714 | R3: =IF(OR(N(L3)=0,Q3=""),"",Q3/L3) -> 0.18003026 | S3: 999 | T3: =IF(OR(N(L3)=0,S3=""),"",S3/L3) -> 0.25189107 | U3: 407 | V3: =IF(OR(N(L3)=0,U3=""),"",U3/L3) -> 0.10262229 | W3: 12831 | X3: 758 | Y3: =IF(OR(N(W3)=0,X3=""),"",X3/W3) -> 0.059075676 | Z3: =IF(AA3="A","四季持續盈利",IF(AA3="B","最新季為正/波動",IF(AA3="C","虧損收窄",IF(AA3="D","虧損擴大或轉虧","數據不足")))) -> 最新季為正/波動 | AA3: =IF(COUNT(N3:Q3)<4,"—",IF(MIN(N3:Q3)>0,"A",IF(Q3>0,"B",IF(Q3>N3,"C","D")))) -> B | AB3: 2026-06-30
A4: 3 | B4: AAL | C4: 航空公司 | D4: American Airlines Group Inc. | E4: Airlines | F4: USD | G4: 25Q2 / 25Q3 / 25Q4 / 26Q1 / 26Q2 | H4: 14392 | I4: 13691 | J4: 13999 | K4: 13912 | L4: 16735 | M4: =IF(OR(N(H4)=0,L4=""),"",L4/H4-1) -> 0.16279878 | N4: 158 | O4: 486 | P4: -27 | Q4: 453 | R4: =IF(OR(N(L4)=0,Q4=""),"",Q4/L4) -> 0.027069017 | S4: 2991 | T4: =IF(OR(N(L4)=0,S4=""),"",S4/L4) -> 0.17872722 | U4: 71 | V4: =IF(OR(N(L4)=0,U4=""),"",U4/L4) -> 0.0042426053 | W4: 54633 | X4: 1626 | Y4: =IF(OR(N(W4)=0,X4=""),"",X4/W4) -> 0.029762232 | Z4: =IF(AA4="A","四季持續盈利",IF(AA4="B","最新季為正/波動",IF(AA4="C","虧損收窄",IF(AA4="D","虧損擴大或轉虧","數據不足")))) -> 最新季為正/波動 | AA4: =IF(COUNT(N4:Q4)<4,"—",IF(MIN(N4:Q4)>0,"A",IF(Q4>0,"B",IF(Q4>N4,"C","D")))) -> B | AB4: 2026-06-30
A5: 4 | B5: AAOI | C5: 光通訊/CPO | D5: Applied Optoelectronics, Inc. | E5: Communication Equipment | F5: USD | G5: 25Q2 / 25Q3 / 25Q4 / 26Q1 / 26Q2 | H5: 102.952 | I5: 118.63 | J5: 134.274 | K5: 151.144 | L5: 191.922 | M5: =IF(OR(N(H5)=0,L5=""),"",L5/H5-1) -> 0.86418914 | N5: -14.968 | O5: -11.352 | P5: -12.877 | Q5: -23.847 | R5: =IF(OR(N(L5)=0,Q5=""),"",Q5/L5) -> -0.1242536 | S5: 53.207 | T5: =IF(OR(N(L5)=0,S5=""),"",S5/L5) -> 0.27723242 | U5: -22.781 | V5: =IF(OR(N(L5)=0,U5=""),"",U5/L5) -> -0.11869926 | W5: 455.715 | X5: -49.736 | Y5: =IF(OR(N(W5)=0,X5=""),"",X5/W5) -> -0.10913839 | Z5: =IF(AA5="A","四季持續盈利",IF(AA5="B","最新季為正/波動",IF(AA5="C","虧損收窄",IF(AA5="D","虧損擴大或轉虧","數據不足")))) -> 虧損擴大或轉虧 | AA5: =IF(COUNT(N5:Q5)<4,"—",IF(MIN(N5:Q5)>0,"A",IF(Q5>0,"B",IF(Q5>N5,"C","D")))) -> D | AB5: 2026-06-30
A6: 5 | B6: AAON | C6: 樓宇產品與HVAC | D6: AAON, Inc. | E6: Building Products & Equipment | F6: USD | G6: 25Q2 / 25Q3 / 25Q4 / 26Q1 / 26Q2 | H6: 311.567 | I6: 384.238 | J6: 424.217 | K6: 496.936 | L6: 626.976 | M6: =IF(OR(N(H6)=0,L6=""),"",L6/H6-1) -> 1.0123312 | N6: 43.631 | O6: 43.96 | P6: 57.059 | Q6: 70.332 | R6: =IF(OR(N(L6)=0,Q6=""),"",Q6/L6) -> 0.11217654 | S6: 152.491 | T6: =IF(OR(N(L6)=0,S6=""),"",S6/L6) -> 0.24321665 | U6: 56.659 | V6: =IF(OR(N(L6)=0,U6=""),"",U6/L6) -> 0.09036869 | W6: 1442.076 | X6: 152.349 | Y6: =IF(OR(N(W6)=0,X6=""),"",X6/W6) -> 0.10564561 | Z6: =IF(AA6="A","四季持續盈利",IF(AA6="B","最新季為正/波動",IF(AA6="C","虧損收窄",IF(AA6="D","虧損擴大或轉虧","數據不足")))) -> 四季持續盈利 | AA6: =IF(COUNT(N6:Q6)<4,"—",IF(MIN(N6:Q6)>0,"A",IF(Q6>0,"B",IF(Q6>N6,"C","D")))) -> A | AB6: 2026-06-30
A7: 6 | B7: AAPL | C7: 電子硬件與EMS/連接器 | D7: Apple Inc. | E7: A4 運算 | F7: USD | G7: 25Q2 / 25Q3 / 25Q4 / 26Q1 / 26Q2 | H7: 94036 | I7: 102466 | J7: 143756 | K7: 111184 | L7: 109417 | M7: =IF(OR(N(H7)=0,L7=""),"",L7/H7-1) -> 0.16356502 | N7: 32427 | O7: 50852 | P7: 35885 | Q7: 35695 | R7: =IF(OR(N(L7)=0,Q7=""),"",Q7/L7) -> 0.32622901 | S7: 54770 | T7: =IF(OR(N(L7)=0,S7=""),"",S7/L7) -> 0.50056207 | U7: 29789 | V7: =IF(OR(N(L7)=0,U7=""),"",U7/L7) -> 0.27225203 | W7: 416161 | X7: 133050 | Y7: =IF(OR(N(W7)=0,X7=""),"",X7/W7) -> 0.319708 | Z7: =IF(AA7="A","四季持續盈利",IF(AA7="B","最新季為正/波動",IF(AA7="C","虧損收窄",IF(AA7="D","虧損擴大或轉虧","數據不足")))) -> 四季持續盈利 | AA7: =IF(COUNT(N7:Q7)<4,"—",IF(MIN(N7:Q7)>0,"A",IF(Q7>0,"B",IF(Q7>N7,"C","D")))) -> A | AB7: 2026-06-30
A8: 7 | B8: ABBV | C8: 大型藥廠 | D8: AbbVie Inc. | E8: Drug Manufacturers - General | F8: USD | G8: 25Q2 / 25Q3 / 25Q4 / 26Q1 / 26Q2 | H8: 15423 | I8: 15776 | J8: 16618 | K8: 15002 | L8: 16990 | M8: =IF(OR(N(H8)=0,L8=""),"",L8/H8-1) -> 0.1016015 | N8: 4584 | O8: 5809 | P8: 4734 | Q8: 6723 | R8: =IF(OR(N(L8)=0,Q8=""),"",Q8/L8) -> 0.39570335 | S8: 12699 | T8: =IF(OR(N(L8)=0,S8=""),"",S8/L8) -> 0.74743967 | U8: 3613 | V8: =IF(OR(N(L8)=0,U8=""),"",U8/L8) -> 0.2126545 | W8: 61160 | X8: 20091 | Y8: =IF(OR(N(W8)=0,X8=""),"",X8/W8) -> 0.32849902 | Z8: =IF(AA8="A","四季持續盈利",IF(AA8="B","最新季為正/波動",IF(AA8="C","虧損收窄",IF(AA8="D","虧損擴大或轉虧","數據不足")))) -> 四季持續盈利 | AA8: =IF(COUNT(N8:Q8)<4,"—",IF(MIN(N8:Q8)>0,"A",IF(Q8>0,"B",IF(Q8>N8,"C","D")))) -> A | AB8: 2026-06-30
A9: 8 | B9: ABT | C9: 醫療器械 | D9: Abbott Laboratories | E9: Medical Devices | F9: USD | G9: 25Q2 / 25Q3 / 25Q4 / 26Q1 / 26Q2 | H9: 11142 | I9: 11369 | J9: 11459 | K9: 11164 | M9: =IF(OR(N(H9)=0,L9=""),"",L9/H9-1) | N9: 2057 | O9: 2251 | P9: 1345 | R9: =IF(OR(N(L9)=0,Q9=""),"",Q9/L9) | T9: =IF(OR(N(L9)=0,S9=""),"",S9/L9) | V9: =IF(OR(N(L9)=0,U9=""),"",U9/L9) | W9: 44328 | X9: 8053 | Y9: =IF(OR(N(W9)=0,X9=""),"",X9/W9) -> 0.18166847 | Z9: =IF(AA9="A","四季持續盈利",IF(AA9="B","最新季為正/波動",IF(AA9="C","虧損收窄",IF(AA9="D","虧損擴大或轉虧","數據不足")))) -> 數據不足 | AA9: =IF(COUNT(N9:Q9)<4,"—",IF(MIN(N9:Q9)>0,"A",IF(Q9>0,"B",IF(Q9>N9,"C","D")))) -> — | AB9: 2026-06-30
A10: 9 | B10: ACI | C10: 大賣場與超巿 | D10: Albertsons Companies, Inc. | E10: Grocery Stores | F10: USD | G10: 25Q2 / 25Q3 / 25Q4 / 26Q1 / 26Q2 | H10: 24880.8 | I10: 18915.8 | J10: 19123.7 | K10: 20252.2 | L10: 24941.6 | M10: =IF(OR(N(H10)=0,L10=""),"",L10/H10-1) -> 0.0024436513 | N10: 299.7 | O10: 488.5 | P10: -490.2 | Q10: 258.9 | R10: =IF(OR(N(L10)=0,Q10=""),"",Q10/L10) -> 0.010380248 | S10: 6638.1 | T10: =IF(OR(N(L10)=0,S10=""),"",S10/L10) -> 0.26614572 | U10: 84.7 | V10: =IF(OR(N(L10)=0,U10=""),"",U10/L10) -> 0.0033959329 | W10: 83172.5 | X10: 715.4 | Y10: =IF(OR(N(W10)=0,X10=""),"",X10/W10) -> 0.0086014007 | Z10: =IF(AA10="A","四季持續盈利",IF(AA10="B","最新季為正/波動",IF(AA10="C","虧損收窄",IF(AA10="D","虧損擴大或轉虧","數據不足")))) -> 最新季為正/波動 | AA10: =IF(COUNT(N10:Q10)<4,"—",IF(MIN(N10:Q10)>0,"A",IF(Q10>0,"B",IF(Q10>N10,"C","D")))) -> B | AB10: 2026-05-31
A11: 10 | B11: ACM | C11: 工程建設/EPC | D11: AECOM | E11: Engineering & Construction | F11: USD | G11: 25Q2 / 25Q3 / 25Q4 / 26Q1 / 26Q2 | H11: 4178.44 | I11: 4175.417 | J11: 3830.834 | K11: 3801.143 | L11: 3586.067 | M11: =IF(OR(N(H11)=0,L11=""),"",L11/H11-1) -> -0.14176894 | N11: 291.425 | O11: 240.151 | P11: 252.199 | Q11: -68.41 | R11: =IF(OR(N(L11)=0,Q11=""),"",Q11/L11) -> -0.01907661 | S11: -34.042 | T11: =IF(OR(N(L11)=0,S11=""),"",S11/L11) -> -0.0094928511 | U11: -86.712 | V11: =IF(OR(N(L11)=0,U11=""),"",U11/L11) -> -0.024180251 | W11: 16139.622 | X11: 1058.864 | Y11: =IF(OR(N(W11)=0,X11=""),"",X11/W11) -> 0.065606493 | Z11: =IF(AA11="A","四季持續盈利",IF(AA11="B","最新季為正/波動",IF(AA11="C","虧損收窄",IF(AA11="D","虧損擴大或轉虧","數據不足")))) -> 虧損擴大或轉虧 | AA11: =IF(COUNT(N11:Q11)<4,"—",IF(MIN(N11:Q11)>0,"A",IF(Q11>0,"B",IF(Q11>N11,"C","D")))) -> D | AB11: 2026-06-30
A12: 11 | B12: ACN | C12: IT服務與系統整合 | D12: Accenture plc | E12: G5 IT | F12: USD | G12: 25Q2 / 25Q3 / 25Q4 / 26Q1 / 26Q2 | H12: 17727.871 | I12: 17596.26 | J12: 18742.125 | K12: 18044.066 | L12: 18718.144 | M12: =IF(OR(N(H12)=0,L12=""),"",L12/H12-1) -> 0.055859669 | N12: 2665.015 | O12: 3181.239 | P12: 2493.547 | Q12: 3175.298 | R12: =IF(OR(N(L12)=0,Q12=""),"",Q12/L12) -> 0.16963744 | S12: 6134.335 | T12: =IF(OR(N(L12)=0,S12=""),"",S12/L12) -> 0.32772133 | U12: 2338.989 | V12: =IF(OR(N(L12)=0,U12=""),"",U12/L12) -> 0.12495838 | W12: 69672.977 | X12: 10840.988 | Y12: =IF(OR(N(W12)=0,X12=""),"",X12/W12) -> 0.15559817 | Z12: =IF(AA12="A","四季持續盈利",IF(AA12="B","最新季為正/波動",IF(AA12="C","虧損收窄",IF(AA12="D","虧損擴大或轉虧","數據不足")))) -> 四季持續盈利 | AA12: =IF(COUNT(N12:Q12)<4,"—",IF(MIN(N12:Q12)>0,"A",IF(Q12>0,"B",IF(Q12>N12,"C","D")))) -> A | AB12: 2026-05-31
A13: 12 | B13: ADBE | C13: 企業軟體/SaaS | D13: Adobe Inc. | E13: G3 AI | F13: USD | G13: 25Q2 / 25Q3 / 25Q4 / 26Q1 / 26Q2 | H13: 5873 | I13: 5988 | J13: 6194 | K13: 6398 | L13: 6618 | M13: =IF(OR(N(H13)=0,L13=""),"",L13/H13-1) -> 0.12685169 | N13: 2173 | O13: 2261 | P13: 2418 | Q13: 2238 | R13: =IF(OR(N(L13)=0,Q13=""),"",Q13/L13) -> 0.33816863 | S13: 5903 | T13: =IF(OR(N(L13)=0,S13=""),"",S13/L13) -> 0.89196132 | U13: 1712 | V13: =IF(OR(N(L13)=0,U13=""),"",U13/L13) -> 0.25868843 | W13: 23769 | X13: 8706 | Y13: =IF(OR(N(W13)=0,X13=""),"",X13/W13) -> 0.3662754 | Z13: =IF(AA13="A","四季持續盈利",IF(AA13="B","最新季為正/波動",IF(AA13="C","虧損收窄",IF(AA13="D","虧損擴大或轉虧","數據不足")))) -> 四季持續盈利 | AA13: =IF(COUNT(N13:Q13)<4,"—",IF(MIN(N13:Q13)>0,"A",IF(Q13>0,"B",IF(Q13>N13,"C","D")))) -> A | AB13: 2026-05-31
A14: 13 | B14: ADI | C14: 類比/功率半導體 | D14: Analog Devices, Inc. | E14: Semiconductors | F14: USD | G14: 25Q3 / 25Q4 / 26Q1 / 26Q2 / 26Q3 | H14: 2880.348 | I14: 3076.117 | J14: 3160.263 | K14: 3623.465 | L14: 4021.899 | M14: =IF(OR(N(H14)=0,L14=""),"",L14/H14-1) -> 0.39632399 | N14: 945.211 | O14: 1045.008 | P14: 1379.68 | Q14: 1588.753 | R14: =IF(OR(N(L14)=0,Q14=""),"",Q14/L14) -> 0.39502558 | S14: 2707.544 | T14: =IF(OR(N(L14)=0,S14=""),"",S14/L14) -> 0.6732004 | U14: 1340.09 | V14: =IF(OR(N(L14)=0,U14=""),"",U14/L14) -> 0.33319832 | W14: 11019.707 | X14: 3002.476 | Y14: =IF(OR(N(W14)=0,X14=""),"",X14/W14) -> 0.27246423 | Z14: =IF(AA14="A","四季持續盈利",IF(AA14="B","最新季為正/波動",IF(AA14="C","虧損收窄",IF(AA14="D","虧損擴大或轉虧","數據不足")))) -> 四季持續盈利 | AA14: =IF(COUNT(N14:Q14)<4,"—",IF(MIN(N14:Q14)>0,"A",IF(Q14>0,"B",IF(Q14>N14,"C","D")))) -> A | AB14: 2026-07-31
A15: 14 | B15: ADM | C15: 農產品與農業投入 | D15: Archer-Daniels-Midland Company | E15: Farm Products | F15: USD | G15: 25Q2 / 25Q3 / 25Q4 / 26Q1 / 26Q2 | H15: 21166 | I15: 20372 | J15: 18556 | K15: 20490 | L15: 22681 | M15: =IF(OR(N(H15)=0,L15=""),"",L15/H15-1) -> 0.071577058 | N15: 397 | O15: 320 | P15: 261 | Q15: 909 | R15: =IF(OR(N(L15)=0,Q15=""),"",Q15/L15) -> 0.040077598 | S15: 1935 | T15: =IF(OR(N(L15)=0,S15=""),"",S15/L15) -> 0.085313699 | U15: 908 | V15: =IF(OR(N(L15)=0,U15=""),"",U15/L15) -> 0.040033508 | W15: 80269 | X15: 1424 | Y15: =IF(OR(N(W15)=0,X15=""),"",X15/W15) -> 0.017740348 | Z15: =IF(AA15="A","四季持續盈利",IF(AA15="B","最新季為正/波動",IF(AA15="C","虧損收窄",IF(AA15="D","虧損擴大或轉虧","數據不足")))) -> 四季持續盈利 | AA15: =IF(COUNT(N15:Q15)<4,"—",IF(MIN(N15:Q15)>0,"A",IF(Q15>0,"B",IF(Q15>N15,"C","D")))) -> A | AB15: 2026-06-30
A16: 15 | B16: ADP | C16: 人力與商業服務 | D16: Automatic Data Processing, Inc. | E16: Software - Application | F16: USD | G16: 25Q2 / 25Q3 / 25Q4 / 26Q1 / 26Q2 | H16: 5126.8 | I16: 5175.2 | J16: 5359.3 | K16: 5939.2 | L16: 5473.8 | M16: =IF(OR(N(H16)=0,L16=""),"",L16/H16-1) -> 0.067683545 | N16: 1332.8 | O16: 1401.5 | P16: 1785.5 | Q16: 1259.1 | R16: =IF(OR(N(L16)=0,Q16=""),"",Q16/L16) -> 0.23002302 | S16: 2511.3 | T16: =IF(OR(N(L16)=0,S16=""),"",S16/L16) -> 0.45878549 | U16: 978.6 | V16: =IF(OR(N(L16)=0,U16=""),"",U16/L16) -> 0.17877891 | W16: 21947.4 | X16: 5779 | Y16: =IF(OR(N(W16)=0,X16=""),"",X16/W16) -> 0.26331137 | Z16: =IF(AA16="A","四季持續盈利",IF(AA16="B","最新季為正/波動",IF(AA16="C","虧損收窄",IF(AA16="D","虧損擴大或轉虧","數據不足")))) -> 四季持續盈利 | AA16: =IF(COUNT(N16:Q16)<4,"—",IF(MIN(N16:Q16)>0,"A",IF(Q16>0,"B",IF(Q16>N16,"C","D")))) -> A | AB16: 2026-06-30
A17: 16 | B17: AEHR | C17: — | D17: Aehr Test Systems, Inc. | E17: B3 先進封裝 | F17: USD | G17: 25Q2 / 25Q3 / 25Q4 / 26Q1 / 26Q2 | H17: 14.089 | I17: 10.969 | J17: 9.884 | K17: 10.313 | L17: 18.835 | M17: =IF(OR(N(H17)=0,L17=""),"",L17/H17-1) -> 0.33685854 | N17: -3.847 | O17: -4.861 | P17: -4.229 | Q17: -1.206 | R17: =IF(OR(N(L17)=0,Q17=""),"",Q17/L17) -> -0.064029732 | S17: 8.019 | T17: =IF(OR(N(L17)=0,S17=""),"",S17/L17) -> 0.42574993 | U17: 1.391 | V17: =IF(OR(N(L17)=0,U17=""),"",U17/L17) -> 0.073851872 | W17: 50.001 | X17: -14.143 | Y17: =IF(OR(N(W17)=0,X17=""),"",X17/W17) -> -0.28285434 | Z17: =IF(AA17="A","四季持續盈利",IF(AA17="B","最新季為正/波動",IF(AA17="C","虧損收窄",IF(AA17="D","虧損擴大或轉虧","數據不足")))) -> 虧損收窄 | AA17: =IF(COUNT(N17:Q17)<4,"—",IF(MIN(N17:Q17)>0,"A",IF(Q17>0,"B",IF(Q17>N17,"C","D")))) -> C | AB17: 2026-05-31
A18: 17 | B18: AEM | C18: 黃金與貴金屬礦 | D18: Agnico Eagle Mines Limited | E18: Gold | F18: USD | G18: 25Q2 / 25Q3 / 25Q4 / 26Q1 / 26Q2 | H18: 2816.101 | I18: 3059.529 | J18: 3563.973 | K18: 4099.589 | L18: 3802.818 | M18: =IF(OR(N(H18)=0,L18=""),"",L18/H18-1) -> 0.35038409 | N18: 1645.004 | O18: 1991.371 | P18: 2556.764 | Q18: 2281.946 | R18: =IF(OR(N(L18)=0,Q18=""),"",Q18/L18) -> 0.60006711 | S18: 2425.804 | T18: =IF(OR(N(L18)=0,S18=""),"",S18/L18) -> 0.63789642 | U18: 1600.453 | V18: =IF(OR(N(L18)=0,U18=""),"",U18/L18) -> 0.42085974 | W18: 11907.851 | X18: 6327.961 | Y18: =IF(OR(N(W18)=0,X18=""),"",X18/W18) -> 0.53141083 | Z18: =IF(AA18="A","四季持續盈利",IF(AA18="B","最新季為正/波動",IF(AA18="C","虧損收窄",IF(AA18="D","虧損擴大或轉虧","數據不足")))) -> 四季持續盈利 | AA18: =IF(COUNT(N18:Q18)<4,"—",IF(MIN(N18:Q18)>0,"A",IF(Q18>0,"B",IF(Q18>N18,"C","D")))) -> A | AB18: 2026-06-30
A19: 18 | B19: AEP | C19: 受監管電力公用 | D19: American Electric Power Company, Inc. | E19: Utilities - Regulated Electric | F19: USD | G19: 25Q2 / 25Q3 / 25Q4 / 26Q1 / 26Q2 | H19: 5087 | I19: 6010.4 | J19: 5315.3 | K19: 6020 | L19: 5445 | M19: =IF(OR(N(H19)=0,L19=""),"",L19/H19-1) -> 0.070375467 | N19: 1521.4 | O19: 1180.3 | P19: 1391 | Q19: 1247 | R19: =IF(OR(N(L19)=0,Q19=""),"",Q19/L19) -> 0.22901745 | S19: 3398 | T19: =IF(OR(N(L19)=0,S19=""),"",S19/L19) -> 0.62405877 | U19: 713 | V19: =IF(OR(N(L19)=0,U19=""),"",U19/L19) -> 0.13094582 | W19: 21876 | X19: 5385 | Y19: =IF(OR(N(W19)=0,X19=""),"",X19/W19) -> 0.24616018 | Z19: =IF(AA19="A","四季持續盈利",IF(AA19="B","最新季為正/波動",IF(AA19="C","虧損收窄",IF(AA19="D","虧損擴大或轉虧","數據不足")))) -> 四季持續盈利 | AA19: =IF(COUNT(N19:Q19)<4,"—",IF(MIN(N19:Q19)>0,"A",IF(Q19>0,"B",IF(Q19>N19,"C","D")))) -> A | AB19: 2026-06-30
A20: 19 | B20: AFL | C20: 壽險與年金 | D20: Aflac Incorporated | E20: Insurance - Life | F20: USD | G20: 25Q2 / 25Q3 / 25Q4 / 26Q1 / 26Q2 | H20: 4218 | I20: 4793 | J20: 4891 | K20: 4408 | L20: 4194 | M20: =IF(OR(N(H20)=0,L20=""),"",L20/H20-1) -> -0.0056899004 | N20: 2051 | O20: 1633 | P20: 1285 | Q20: 1059 | R20: =IF(OR(N(L20)=0,Q20=""),"",Q20/L20) -> 0.25250358 | T20: =IF(OR(N(L20)=0,S20=""),"",S20/L20) | U20: 825 | V20: =IF(OR(N(L20)=0,U20=""),"",U20/L20) -> 0.19670959 | W20: 17355 | X20: 4753 | Y20: =IF(OR(N(W20)=0,X20=""),"",X20/W20) -> 0.2738692 | Z20: =IF(AA20="A","四季持續盈利",IF(AA20="B","最新季為正/波動",IF(AA20="C","虧損收窄",IF(AA20="D","虧損擴大或轉虧","數據不足")))) -> 四季持續盈利 | AA20: =IF(COUNT(N20:Q20)<4,"—",IF(MIN(N20:Q20)>0,"A",IF(Q20>0,"B",IF(Q20>N20,"C","D")))) -> A | AB20: 2026-06-30
A21: 20 | B21: AFRM | C21: 消費金融與BNPL | D21: Affirm Holdings, Inc. | E21: Credit Services | F21: USD | G21: 25Q2 / 25Q3 / 25Q4 / 26Q1 / 26Q2 | H21: 876.417 | I21: 933.337 | J21: 1123.02 | K21: 1038.765 | L21: 1165.961 | M21: =IF(OR(N(H21)=0,L21=""),"",L21/H21-1) -> 0.33037241 | N21: 173.688 | O21: 229.344 | P21: 202.19 | Q21: 265.772 | R21: =IF(OR(N(L21)=0,Q21=""),"",Q21/L21) -> 0.22794244 | S21: 804.504 | T21: =IF(OR(N(L21)=0,S21=""),"",S21/L21) -> 0.6899922 | U21: 1616.613 | V21: =IF(OR(N(L21)=0,U21=""),"",U21/L21) -> 1.3865069 | W21: 4261.083 | X21: 870.994 | Y21: =IF(OR(N(W21)=0,X21=""),"",X21/W21) -> 0.20440672 | Z21: =IF(AA21="A","四季持續盈利",IF(AA21="B","最新季為正/波動",IF(AA21="C","虧損收窄",IF(AA21="D","虧損擴大或轉虧","數據不足")))) -> 四季持續盈利 | AA21: =IF(COUNT(N21:Q21)<4,"—",IF(MIN(N21:Q21)>0,"A",IF(Q21>0,"B",IF(Q21>N21,"C","D")))) -> A | AB21: 2026-06-30
A22: 21 | B22: AG | C22: 白銀礦 | D22: First Majestic Silver Corp. | E22: Silver | F22: USD | G22: 25Q2 / 25Q3 / 25Q4 / 26Q1 / 26Q2 | H22: 264.726 | I22: 286.723 | J22: 467.716 | K22: 480.938 | L22: 414.239 | M22: =IF(OR(N(H22)=0,L22=""),"",L22/H22-1) -> 0.56478397 | N22: 76.871 | O22: 210.26 | P22: 235.978 | Q22: 198.576 | R22: =IF(OR(N(L22)=0,Q22=""),"",Q22/L22) -> 0.47937543 | S22: 223.616 | T22: =IF(OR(N(L22)=0,S22=""),"",S22/L22) -> 0.53982363 | U22: 125.893 | V22: =IF(OR(N(L22)=0,U22=""),"",U22/L22) -> 0.30391392 | W22: 1265.157 | X22: 349.931 | Y22: =IF(OR(N(W22)=0,X22=""),"",X22/W22) -> 0.27659097 | Z22: =IF(AA22="A","四季持續盈利",IF(AA22="B","最新季為正/波動",IF(AA22="C","虧損收窄",IF(AA22="D","虧損擴大或轉虧","數據不足")))) -> 四季持續盈利 | AA22: =IF(COUNT(N22:Q22)<4,"—",IF(MIN(N22:Q22)>0,"A",IF(Q22>0,"B",IF(Q22>N22,"C","D")))) -> A | AB22: 2026-06-30
A23: 22 | B23: AI | C23: — | D23: C3.ai, Inc. | E23: G3 AI | F23: USD | G23: 25Q3 / 25Q4 / 26Q1 / 26Q2 / 26Q3 | H23: 70.261 | I23: 75.147 | J23: 53.26 | K23: 51.6 | M23: =IF(OR(N(H23)=0,L23=""),"",L23/H23-1) | N23: -112.113 | O23: -140.408 | P23: -110.33 | R23: =IF(OR(N(L23)=0,Q23=""),"",Q23/L23) | T23: =IF(OR(N(L23)=0,S23=""),"",S23/L23) | V23: =IF(OR(N(L23)=0,U23=""),"",U23/L23) | W23: 250.268 | X23: -487.67 | Y23: =IF(OR(N(W23)=0,X23=""),"",X23/W23) -> -1.9485911 | Z23: =IF(AA23="A","四季持續盈利",IF(AA23="B","最新季為正/波動",IF(AA23="C","虧損收窄",IF(AA23="D","虧損擴大或轉虧","數據不足")))) -> 數據不足 | AA23: =IF(COUNT(N23:Q23)<4,"—",IF(MIN(N23:Q23)>0,"A",IF(Q23>0,"B",IF(Q23>N23,"C","D")))) -> — | AB23: 2026-07-31
A24: 23 | B24: AIG | C24: 產險與再保 | D24: American International Group, Inc. | E24: Insurance - Diversified | F24: USD | G24: 25Q2 / 25Q3 / 25Q4 / 26Q1 / 26Q2 | H24: 7041 | I24: 6402 | J24: 6557 | K24: 6616 | L24: 7086 | M24: =IF(OR(N(H24)=0,L24=""),"",L24/H24-1) -> 0.0063911376 | N24: 813 | O24: 766 | P24: 1087 | Q24: 1364 | R24: =IF(OR(N(L24)=0,Q24=""),"",Q24/L24) -> 0.19249224 | T24: =IF(OR(N(L24)=0,S24=""),"",S24/L24) | U24: 948 | V24: =IF(OR(N(L24)=0,U24=""),"",U24/L24) -> 0.13378493 | W24: 26774 | X24: 4275 | Y24: =IF(OR(N(W24)=0,X24=""),"",X24/W24) -> 0.15966983 | Z24: =IF(AA24="A","四季持續盈利",IF(AA24="B","最新季為正/波動",IF(AA24="C","虧損收窄",IF(AA24="D","虧損擴大或轉虧","數據不足")))) -> 四季持續盈利 | AA24: =IF(COUNT(N24:Q24)<4,"—",IF(MIN(N24:Q24)>0,"A",IF(Q24>0,"B",IF(Q24>N24,"C","D")))) -> A | AB24: 2026-06-30
A25: 24 | B25: AJG | C25: 保險經紀 | D25: Arthur J. Gallagher & Co. | E25: Insurance Brokers | F25: USD | G25: 25Q2 / 25Q3 / 25Q4 / 26Q1 / 26Q2 | H25: 3222 | I25: 3365.6 | J25: 3628.2 | K25: 4758 | L25: 4003 | M25: =IF(OR(N(H25)=0,L25=""),"",L25/H25-1) -> 0.24239603 | N25: 536.6 | O25: 348.1 | P25: 1218 | Q25: 588 | R25: =IF(OR(N(L25)=0,Q25=""),"",Q25/L25) -> 0.14688983 | S25: 1625 | T25: =IF(OR(N(L25)=0,S25=""),"",S25/L25) -> 0.40594554 | U25: 324 | V25: =IF(OR(N(L25)=0,U25=""),"",U25/L25) -> 0.080939296 | W25: 13942 | X25: 2556 | Y25: =IF(OR(N(W25)=0,X25=""),"",X25/W25) -> 0.18333094 | Z25: =IF(AA25="A","四季持續盈利",IF(AA25="B","最新季為正/波動",IF(AA25="C","虧損收窄",IF(AA25="D","虧損擴大或轉虧","數據不足")))) -> 四季持續盈利 | AA25: =IF(COUNT(N25:Q25)<4,"—",IF(MIN(N25:Q25)>0,"A",IF(Q25>0,"B",IF(Q25>N25,"C","D")))) -> A | AB25: 2026-06-30
A26: 25 | B26: ALAB | C26: — | D26: Astera Labs, Inc. | E26: D3 高速互連 | F26: USD | G26: 25Q2 / 25Q3 / 25Q4 / 26Q1 / 26Q2 | H26: 191.925 | I26: 230.575 | J26: 270.583 | K26: 308.361 | L26: 392.4 | M26: =IF(OR(N(H26)=0,L26=""),"",L26/H26-1) -> 1.0445487 | N26: 55.406 | O26: 66.958 | P26: 61.833 | Q26: 89.248 | R26: =IF(OR(N(L26)=0,Q26=""),"",Q26/L26) -> 0.22744139 | S26: 287.567 | T26: =IF(OR(N(L26)=0,S26=""),"",S26/L26) -> 0.73284149 | U26: 153.088 | V26: =IF(OR(N(L26)=0,U26=""),"",U26/L26) -> 0.39013252 | W26: 852.525 | X26: 173.423 | Y26: =IF(OR(N(W26)=0,X26=""),"",X26/W26) -> 0.20342277 | Z26: =IF(AA26="A","四季持續盈利",IF(AA26="B","最新季為正/波動",IF(AA26="C","虧損收窄",IF(AA26="D","虧損擴大或轉虧","數據不足")))) -> 四季持續盈利 | AA26: =IF(COUNT(N26:Q26)<4,"—",IF(MIN(N26:Q26)>0,"A",IF(Q26>0,"B",IF(Q26>N26,"C","D")))) -> A | AB26: 2026-06-30
A27: 26 | B27: ALB | C27: 特種化工 | D27: Albemarle Corporation | E27: Specialty Chemicals | F27: USD | G27: 25Q2 / 25Q3 / 25Q4 / 26Q1 / 26Q2 | H27: 1329.992 | I27: 1307.829 | J27: 1428.031 | K27: 1428.731 | L27: 1743.313 | M27: =IF(OR(N(H27)=0,L27=""),"",L27/H27-1) -> 0.31076954 | N27: -33.641 | O27: 30.253 | P27: 354.39 | Q27: 460.281 | R27: =IF(OR(N(L27)=0,Q27=""),"",Q27/L27) -> 0.2640266 | S27: 590.301 | T27: =IF(OR(N(L27)=0,S27=""),"",S27/L27) -> 0.33860873 | U27: 479.959 | V27: =IF(OR(N(L27)=0,U27=""),"",U27/L27) -> 0.2753143 | W27: 5142.733 | X27: 67.285 | Y27: =IF(OR(N(W27)=0,X27=""),"",X27/W27) -> 0.01308351 | Z27: =IF(AA27="A","四季持續盈利",IF(AA27="B","最新季為正/波動",IF(AA27="C","虧損收窄",IF(AA27="D","虧損擴大或轉虧","數據不足")))) -> 最新季為正/波動 | AA27: =IF(COUNT(N27:Q27)<4,"—",IF(MIN(N27:Q27)>0,"A",IF(Q27>0,"B",IF(Q27>N27,"C","D")))) -> B | AB27: 2026-06-30
A28: 27 | B28: ALEC | C28: 臨床期中小型生技 | D28: Alector, Inc. | E28: Biotechnology | F28: USD | G28: 25Q2 / 25Q3 / 25Q4 / 26Q1 / 26Q2 | H28: 7.874 | I28: 3.26 | J28: 6.237 | K28: 1.046 | L28: 3.32 | M28: =IF(OR(N(H28)=0,L28=""),"",L28/H28-1) -> -0.57835916 | N28: -37.608 | O28: -39.566 | P28: -24.919 | Q28: -24.393 | R28: =IF(OR(N(L28)=0,Q28=""),"",Q28/L28) -> -7.3472892 | T28: =IF(OR(N(L28)=0,S28=""),"",S28/L28) | U28: -22.99 | V28: =IF(OR(N(L28)=0,U28=""),"",U28/L28) -> -6.9246988 | W28: 21.045 | X28: -156.007 | Y28: =IF(OR(N(W28)=0,X28=""),"",X28/W28) -> -7.4130197 | Z28: =IF(AA28="A","四季持續盈利",IF(AA28="B","最新季為正/波動",IF(AA28="C","虧損收窄",IF(AA28="D","虧損擴大或轉虧","數據不足")))) -> 虧損收窄 | AA28: =IF(COUNT(N28:Q28)<4,"—",IF(MIN(N28:Q28)>0,"A",IF(Q28>0,"B",IF(Q28>N28,"C","D")))) -> C | AB28: 2026-06-30
A29: 28 | B29: ALLO | C29: 腫瘤與細胞治療 | D29: Allogene Therapeutics, Inc. | E29: Biotechnology | F29: USD | G29: 25Q2 / 25Q3 / 25Q4 / 26Q1 / 26Q2 | H29: 0 | I29: 0 | J29: 0 | K29: 0 | L29: 4.64 | M29: =IF(OR(N(H29)=0,L29=""),"",L29/H29-1) | N29: -44.901 | O29: -42.404 | P29: -46.092 | Q29: -46.92 | R29: =IF(OR(N(L29)=0,Q29=""),"",Q29/L29) -> -10.112069 | T29: =IF(OR(N(L29)=0,S29=""),"",S29/L29) | U29: -42.677 | V29: =IF(OR(N(L29)=0,U29=""),"",U29/L29) -> -9.1976293 | W29: 0 | X29: -206.933 | Y29: =IF(OR(N(W29)=0,X29=""),"",X29/W29) | Z29: =IF(AA29="A","四季持續盈利",IF(AA29="B","最新季為正/波動",IF(AA29="C","虧損收窄",IF(AA29="D","虧損擴大或轉虧","數據不足")))) -> 虧損擴大或轉虧 | AA29: =IF(COUNT(N29:Q29)<4,"—",IF(MIN(N29:Q29)>0,"A",IF(Q29>0,"B",IF(Q29>N29,"C","D")))) -> D | AB29: 2026-06-30
A30: 29 | B30: ALOY | C30: 稀土與關鍵礦產 | D30: REalloys Inc. | E30: Other Industrial Metals & Mining | F30: USD | G30: 25Q1 / 25Q2 / 26Q1 / 26Q2 | H30: 0 | I30: 0.44 | J30: 0.706 | K30: 0.804 | M30: =IF(OR(N(H30)=0,L30=""),"",L30/H30-1) | N30: -0.867 | O30: -0.902 | P30: -87.657 | Q30: -36.804 | R30: =IF(OR(N(L30)=0,Q30=""),"",Q30/L30) -> -45.776119 | S30: 0.475 | T30: =IF(OR(N(L30)=0,S30=""),"",S30/L30) -> 0.59079602 | U30: -36.818 | V30: =IF(OR(N(L30)=0,U30=""),"",U30/L30) -> -45.793532 | Y30: =IF(OR(N(W30)=0,X30=""),"",X30/W30) | Z30: =IF(AA30="A","四季持續盈利",IF(AA30="B","最新季為正/波動",IF(AA30="C","虧損收窄",IF(AA30="D","虧損擴大或轉虧","數據不足")))) -> 虧損擴大或轉虧 | AA30: =IF(COUNT(N30:Q30)<4,"—",IF(MIN(N30:Q30)>0,"A",IF(Q30>0,"B",IF(Q30>N30,"C","D")))) -> D | AB30: 2026-06-30
A31: 30 | B31: ALT | C31: GLP-1減重與代謝 | D31: Altimmune, Inc. | E31: Biotechnology | F31: USD | G31: 25Q2 / 25Q3 / 25Q4 / 26Q1 / 26Q2 | H31: 0.005 | I31: 0.005 | J31: 0.026 | K31: 0 | L31: 0 | M31: =IF(OR(N(H31)=0,L31=""),"",L31/H31-1) -> -1 | N31: -20.859 | O31: -28.893 | P31: -24.244 | Q31: -26.229 | R31: =IF(OR(N(L31)=0,Q31=""),"",Q31/L31) | T31: =IF(OR(N(L31)=0,S31=""),"",S31/L31) | U31: -22.825 | V31: =IF(OR(N(L31)=0,U31=""),"",U31/L31) | W31: 0.041 | X31: -94.489 | Y31: =IF(OR(N(W31)=0,X31=""),"",X31/W31) -> -2304.6098 | Z31: =IF(AA31="A","四季持續盈利",IF(AA31="B","最新季為正/波動",IF(AA31="C","虧損收窄",IF(AA31="D","虧損擴大或轉虧","數據不足")))) -> 虧損擴大或轉虧 | AA31: =IF(COUNT(N31:Q31)<4,"—",IF(MIN(N31:Q31)>0,"A",IF(Q31>0,"B",IF(Q31>N31,"C","D")))) -> D | AB31: 2026-06-30
A32: 31 | B32: AMAT | C32: 半導體設備 | D32: Applied Materials, Inc. | E32: B2 半導體前段設備 | F32: USD | G32: 25Q3 / 25Q4 / 26Q1 / 26Q2 / 26Q3 | H32: 7302 | I32: 6800 | J32: 7012 | K32: 7910 | L32: 9115 | M32: =IF(OR(N(H32)=0,L32=""),"",L32/H32-1) -> 0.24828814 | N32: 1893 | O32: 2096 | P32: 2523 | Q32: 3075 | R32: =IF(OR(N(L32)=0,Q32=""),"",Q32/L32) -> 0.33735601 | S32: 4586 | T32: =IF(OR(N(L32)=0,S32=""),"",S32/L32) -> 0.50312671 | U32: 2538 | V32: =IF(OR(N(L32)=0,U32=""),"",U32/L32) -> 0.27844213 | W32: 28368 | X32: 8470 | Y32: =IF(OR(N(W32)=0,X32=""),"",X32/W32) -> 0.29857586 | Z32: =IF(AA32="A","四季持續盈利",IF(AA32="B","最新季為正/波動",IF(AA32="C","虧損收窄",IF(AA32="D","虧損擴大或轉虧","數據不足")))) -> 四季持續盈利 | AA32: =IF(COUNT(N32:Q32)<4,"—",IF(MIN(N32:Q32)>0,"A",IF(Q32>0,"B",IF(Q32>N32,"C","D")))) -> A | AB32: 2026-07-31
A33: 32 | B33: AMD | C33: AI加速晶片/GPU | D33: Advanced Micro Devices, Inc. | E33: A1 GPU | F33: USD | G33: 25Q2 / 25Q3 / 25Q4 / 26Q1 / 26Q2 | H33: 7685 | I33: 9246 | J33: 10270 | K33: 10253 | L33: 11536 | M33: =IF(OR(N(H33)=0,L33=""),"",L33/H33-1) -> 0.50110605 | N33: 1270 | O33: 1752 | P33: 1476 | Q33: 1990 | R33: =IF(OR(N(L33)=0,Q33=""),"",Q33/L33) -> 0.17250347 | S33: 6203 | T33: =IF(OR(N(L33)=0,S33=""),"",S33/L33) -> 0.53770804 | U33: 2297 | V33: =IF(OR(N(L33)=0,U33=""),"",U33/L33) -> 0.19911581 | W33: 34639 | X33: 3694 | Y33: =IF(OR(N(W33)=0,X33=""),"",X33/W33) -> 0.1066428 | Z33: =IF(AA33="A","四季持續盈利",IF(AA33="B","最新季為正/波動",IF(AA33="C","虧損收窄",IF(AA33="D","虧損擴大或轉虧","數據不足")))) -> 四季持續盈利 | AA33: =IF(COUNT(N33:Q33)<4,"—",IF(MIN(N33:Q33)>0,"A",IF(Q33>0,"B",IF(Q33>N33,"C","D")))) -> A | AB33: 2026-06-30
A34: 33 | B34: AMG | C34: 資產管理 | D34: Affiliated Managers Group, Inc. | E34: Asset Management | F34: USD | G34: 25Q2 / 25Q3 / 25Q4 / 26Q1 / 26Q2 | H34: 493.2 | I34: 528 | J34: 556.6 | K34: 544.9 | L34: 640.7 | M34: =IF(OR(N(H34)=0,L34=""),"",L34/H34-1) -> 0.29906732 | N34: 165.1 | O34: 99.8 | P34: 98.7 | Q34: 207.8 | R34: =IF(OR(N(L34)=0,Q34=""),"",Q34/L34) -> 0.32433276 | S34: 324.6 | T34: =IF(OR(N(L34)=0,S34=""),"",S34/L34) -> 0.50663337 | U34: 185.9 | V34: =IF(OR(N(L34)=0,U34=""),"",U34/L34) -> 0.2901514 | W34: 2074.4 | X34: 475.3 | Y34: =IF(OR(N(W34)=0,X34=""),"",X34/W34) -> 0.22912649 | Z34: =IF(AA34="A","四季持續盈利",IF(AA34="B","最新季為正/波動",IF(AA34="C","虧損收窄",IF(AA34="D","虧損擴大或轉虧","數據不足")))) -> 四季持續盈利 | AA34: =IF(COUNT(N34:Q34)<4,"—",IF(MIN(N34:Q34)>0,"A",IF(Q34>0,"B",IF(Q34>N34,"C","D")))) -> A | AB34: 2026-06-30
A35: 34 | B35: AMGN | C35: 大型生物科技 | D35: Amgen Inc. | E35: Drug Manufacturers - General | F35: USD | G35: 25Q2 / 25Q3 / 25Q4 / 26Q1 / 26Q2 | H35: 9179 | I35: 9557 | J35: 9866 | K35: 8618 | L35: 10054 | M35: =IF(OR(N(H35)=0,L35=""),"",L35/H35-1) -> 0.095326288 | N35: 2526 | O35: 2720 | P35: 2666 | Q35: 3514 | R35: =IF(OR(N(L35)=0,Q35=""),"",Q35/L35) -> 0.34951263 | S35: 7243 | T35: =IF(OR(N(L35)=0,S35=""),"",S35/L35) -> 0.72040979 | U35: 2375 | V35: =IF(OR(N(L35)=0,U35=""),"",U35/L35) -> 0.23622439 | W35: 36751 | X35: 9080 | Y35: =IF(OR(N(W35)=0,X35=""),"",X35/W35) -> 0.24706811 | Z35: =IF(AA35="A","四季持續盈利",IF(AA35="B","最新季為正/波動",IF(AA35="C","虧損收窄",IF(AA35="D","虧損擴大或轉虧","數據不足")))) -> 四季持續盈利 | AA35: =IF(COUNT(N35:Q35)<4,"—",IF(MIN(N35:Q35)>0,"A",IF(Q35>0,"B",IF(Q35>N35,"C","D")))) -> A | AB35: 2026-06-30
A36: 35 | B36: AMH | C36: 住宅公寓REIT | D36: American Homes 4 Rent | E36: REIT - Residential | F36: USD | G36: 25Q2 / 25Q3 / 25Q4 / 26Q1 / 26Q2 | H36: 457.503 | I36: 478.464 | J36: 454.991 | K36: 472.024 | L36: 470.104 | M36: =IF(OR(N(H36)=0,L36=""),"",L36/H36-1) -> 0.027542989 | N36: 116.317 | O36: 118.787 | P36: 121.355 | Q36: 125.052 | R36: =IF(OR(N(L36)=0,Q36=""),"",Q36/L36) -> 0.26600922 | S36: 274.317 | T36: =IF(OR(N(L36)=0,S36=""),"",S36/L36) -> 0.58352407 | U36: 117.112 | V36: =IF(OR(N(L36)=0,U36=""),"",U36/L36) -> 0.24911934 | W36: 1850.234 | X36: 464.125 | Y36: =IF(OR(N(W36)=0,X36=""),"",X36/W36) -> 0.25084665 | Z36: =IF(AA36="A","四季持續盈利",IF(AA36="B","最新季為正/波動",IF(AA36="C","虧損收窄",IF(AA36="D","虧損擴大或轉虧","數據不足")))) -> 四季持續盈利 | AA36: =IF(COUNT(N36:Q36)<4,"—",IF(MIN(N36:Q36)>0,"A",IF(Q36>0,"B",IF(Q36>N36,"C","D")))) -> A | AB36: 2026-06-30
A37: 36 | B37: AMKR | C37: — | D37: Amkor Technology, Inc. | E37: B3 先進封裝 | F37: USD | G37: 25Q2 / 25Q3 / 25Q4 / 26Q1 / 26Q2 | H37: 1511.392 | I37: 1986.968 | J37: 1888.046 | K37: 1684.701 | L37: 1897.965 | M37: =IF(OR(N(H37)=0,L37=""),"",L37/H37-1) -> 0.25577282 | N37: 158.927 | O37: 184.968 | P37: 100.287 | Q37: 199.854 | R37: =IF(OR(N(L37)=0,Q37=""),"",Q37/L37) -> 0.1052991 | S37: 318.59 | T37: =IF(OR(N(L37)=0,S37=""),"",S37/L37) -> 0.16785873 | U37: 173.753 | V37: =IF(OR(N(L37)=0,U37=""),"",U37/L37) -> 0.091546999 | W37: 6707.981 | X37: 467.385 | Y37: =IF(OR(N(W37)=0,X37=""),"",X37/W37) -> 0.069675958 | Z37: =IF(AA37="A","四季持續盈利",IF(AA37="B","最新季為正/波動",IF(AA37="C","虧損收窄",IF(AA37="D","虧損擴大或轉虧","數據不足")))) -> 四季持續盈利 | AA37: =IF(COUNT(N37:Q37)<4,"—",IF(MIN(N37:Q37)>0,"A",IF(Q37>0,"B",IF(Q37>N37,"C","D")))) -> A | AB37: 2026-06-30
A38: 37 | B38: AMR | C38: 煤炭 | D38: Alpha Metallurgical Resources, Inc. | E38: Coking Coal | F38: USD | G38: 25Q2 / 25Q3 / 25Q4 / 26Q1 / 26Q2 | H38: 550.274 | I38: 526.778 | J38: 520.472 | K38: 524.987 | L38: 492.856 | M38: =IF(OR(N(H38)=0,L38=""),"",L38/H38-1) -> -0.10434438 | N38: -2.522 | O38: -21.324 | P38: -10.432 | Q38: -10.5 | R38: =IF(OR(N(L38)=0,Q38=""),"",Q38/L38) -> -0.021304397 | S38: 12.273 | T38: =IF(OR(N(L38)=0,S38=""),"",S38/L38) -> 0.024901797 | U38: -12.252 | V38: =IF(OR(N(L38)=0,U38=""),"",U38/L38) -> -0.024859188 | W38: 2129.481 | X38: -61.366 | Y38: =IF(OR(N(W38)=0,X38=""),"",X38/W38) -> -0.02881735 | Z38: =IF(AA38="A","四季持續盈利",IF(AA38="B","最新季為正/波動",IF(AA38="C","虧損收窄",IF(AA38="D","虧損擴大或轉虧","數據不足")))) -> 虧損擴大或轉虧 | AA38: =IF(COUNT(N38:Q38)<4,"—",IF(MIN(N38:Q38)>0,"A",IF(Q38>0,"B",IF(Q38>N38,"C","D")))) -> D | AB38: 2026-06-30
A39: 38 | B39: AMS | C39: — | D39: American Shared Hospital Services | E39: D9 光模塊上游 | F39: USD | G39: 25Q2 / 25Q3 / 25Q4 / 26Q1 / 26Q2 | H39: 7.071 | I39: 7.171 | J39: 7.728 | K39: 7.084 | L39: 8.43 | M39: =IF(OR(N(H39)=0,L39=""),"",L39/H39-1) -> 0.19219347 | N39: 0.048 | O39: -1.08 | P39: -0.622 | Q39: -0.609 | R39: =IF(OR(N(L39)=0,Q39=""),"",Q39/L39) -> -0.072241993 | S39: 1.433 | T39: =IF(OR(N(L39)=0,S39=""),"",S39/L39) -> 0.16998814 | U39: -0.514 | V39: =IF(OR(N(L39)=0,U39=""),"",U39/L39) -> -0.060972716 | W39: 28.082 | X39: -2.014 | Y39: =IF(OR(N(W39)=0,X39=""),"",X39/W39) -> -0.071718539 | Z39: =IF(AA39="A","四季持續盈利",IF(AA39="B","最新季為正/波動",IF(AA39="C","虧損收窄",IF(AA39="D","虧損擴大或轉虧","數據不足")))) -> 虧損擴大或轉虧 | AA39: =IF(COUNT(N39:Q39)<4,"—",IF(MIN(N39:Q39)>0,"A",IF(Q39>0,"B",IF(Q39>N39,"C","D")))) -> D | AB39: 2026-06-30
A40: 39 | B40: AMT | C40: 通訊塔REIT | D40: American Tower Corporation | E40: REIT - Specialty | F40: USD | G40: 25Q2 / 25Q3 / 25Q4 / 26Q1 / 26Q2 | H40: 2626.9 | I40: 2717.4 | J40: 2737.5 | K40: 2737.5 | L40: 2749.1 | M40: =IF(OR(N(H40)=0,L40=""),"",L40/H40-1) -> 0.04651871 | N40: 1233.3 | O40: 1244.1 | P40: 1239.2 | Q40: 1268.8 | R40: =IF(OR(N(L40)=0,Q40=""),"",Q40/L40) -> 0.46153287 | S40: 2007.8 | T40: =IF(OR(N(L40)=0,S40=""),"",S40/L40) -> 0.73034811 | U40: 867.5 | V40: =IF(OR(N(L40)=0,U40=""),"",U40/L40) -> 0.31555782 | W40: 10644.6 | X40: 4929.2 | Y40: =IF(OR(N(W40)=0,X40=""),"",X40/W40) -> 0.46307048 | Z40: =IF(AA40="A","四季持續盈利",IF(AA40="B","最新季為正/波動",IF(AA40="C","虧損收窄",IF(AA40="D","虧損擴大或轉虧","數據不足")))) -> 四季持續盈利 | AA40: =IF(COUNT(N40:Q40)<4,"—",IF(MIN(N40:Q40)>0,"A",IF(Q40>0,"B",IF(Q40>N40,"C","D")))) -> A | AB40: 2026-06-30
...

Sheet 明細對照
A1: 類別 | B1: 群組 | C1: Ticker | D1: 幣別 | E1: 營收 Q0 (百萬美元, 只計美元呈報) | F1: 營業利益 Q0 (百萬美元, 只計美元呈報)
A2: 子板塊 | B2: 診斷與生命科學工具 | C2: A | D2: =IFERROR(INDEX(觀察名單!$F$2:$F$533,MATCH($C2,觀察名單!$B$2:$B$533,0)),"") -> USD | E2: =IF($D2<>"USD","",IFERROR(INDEX(觀察名單!$L$2:$L$533,MATCH($C2,觀察名單!$B$2:$B$533,0)),"")) -> 1878 | F2: =IF($D2<>"USD","",IFERROR(INDEX(觀察名單!$Q$2:$Q$533,MATCH($C2,觀察名單!$B$2:$B$533,0)),"")) -> 444
A3: 子板塊 | B3: 鋁業 | C3: AA | D3: =IFERROR(INDEX(觀察名單!$F$2:$F$533,MATCH($C3,觀察名單!$B$2:$B$533,0)),"") -> USD | E3: =IF($D3<>"USD","",IFERROR(INDEX(觀察名單!$L$2:$L$533,MATCH($C3,觀察名單!$B$2:$B$533,0)),"")) -> 3966 | F3: =IF($D3<>"USD","",IFERROR(INDEX(觀察名單!$Q$2:$Q$533,MATCH($C3,觀察名單!$B$2:$B$533,0)),"")) -> 714
A4: 子板塊 | B4: 航空公司 | C4: AAL | D4: =IFERROR(INDEX(觀察名單!$F$2:$F$533,MATCH($C4,觀察名單!$B$2:$B$533,0)),"") -> USD | E4: =IF($D4<>"USD","",IFERROR(INDEX(觀察名單!$L$2:$L$533,MATCH($C4,觀察名單!$B$2:$B$533,0)),"")) -> 16735 | F4: =IF($D4<>"USD","",IFERROR(INDEX(觀察名單!$Q$2:$Q$533,MATCH($C4,觀察名單!$B$2:$B$533,0)),"")) -> 453
A5: 子板塊 | B5: 光通訊/CPO | C5: AAOI | D5: =IFERROR(INDEX(觀察名單!$F$2:$F$533,MATCH($C5,觀察名單!$B$2:$B$533,0)),"") -> USD | E5: =IF($D5<>"USD","",IFERROR(INDEX(觀察名單!$L$2:$L$533,MATCH($C5,觀察名單!$B$2:$B$533,0)),"")) -> 191.922 | F5: =IF($D5<>"USD","",IFERROR(INDEX(觀察名單!$Q$2:$Q$533,MATCH($C5,觀察名單!$B$2:$B$533,0)),"")) -> -23.847
A6: 子板塊 | B6: 樓宇產品與HVAC | C6: AAON | D6: =IFERROR(INDEX(觀察名單!$F$2:$F$533,MATCH($C6,觀察名單!$B$2:$B$533,0)),"") -> USD | E6: =IF($D6<>"USD","",IFERROR(INDEX(觀察名單!$L$2:$L$533,MATCH($C6,觀察名單!$B$2:$B$533,0)),"")) -> 626.976 | F6: =IF($D6<>"USD","",IFERROR(INDEX(觀察名單!$Q$2:$Q$533,MATCH($C6,觀察名單!$B$2:$B$533,0)),"")) -> 70.332
A7: 子板塊 | B7: 電子硬件與EMS/連接器 | C7: AAPL | D7: =IFERROR(INDEX(觀察名單!$F$2:$F$533,MATCH($C7,觀察名單!$B$2:$B$533,0)),"") -> USD | E7: =IF($D7<>"USD","",IFERROR(INDEX(觀察名單!$L$2:$L$533,MATCH($C7,觀察名單!$B$2:$B$533,0)),"")) -> 109417 | F7: =IF($D7<>"USD","",IFERROR(INDEX(觀察名單!$Q$2:$Q$533,MATCH($C7,觀察名單!$B$2:$B$533,0)),"")) -> 35695
A8: 子板塊 | B8: 大型藥廠 | C8: ABBV | D8: =IFERROR(INDEX(觀察名單!$F$2:$F$533,MATCH($C8,觀察名單!$B$2:$B$533,0)),"") -> USD | E8: =IF($D8<>"USD","",IFERROR(INDEX(觀察名單!$L$2:$L$533,MATCH($C8,觀察名單!$B$2:$B$533,0)),"")) -> 16990 | F8: =IF($D8<>"USD","",IFERROR(INDEX(觀察名單!$Q$2:$Q$533,MATCH($C8,觀察名單!$B$2:$B$533,0)),"")) -> 6723
A9: 子板塊 | B9: 醫療器械 | C9: ABT | D9: =IFERROR(INDEX(觀察名單!$F$2:$F$533,MATCH($C9,觀察名單!$B$2:$B$533,0)),"") -> USD | E9: =IF($D9<>"USD","",IFERROR(INDEX(觀察名單!$L$2:$L$533,MATCH($C9,觀察名單!$B$2:$B$533,0)),"")) | F9: =IF($D9<>"USD","",IFERROR(INDEX(觀察名單!$Q$2:$Q$533,MATCH($C9,觀察名單!$B$2:$B$533,0)),""))
A10: 子板塊 | B10: 大賣場與超巿 | C10: ACI | D10: =IFERROR(INDEX(觀察名單!$F$2:$F$533,MATCH($C10,觀察名單!$B$2:$B$533,0)),"") -> USD | E10: =IF($D10<>"USD","",IFERROR(INDEX(觀察名單!$L$2:$L$533,MATCH($C10,觀察名單!$B$2:$B$533,0)),"")) -> 24941.6 | F10: =IF($D10<>"USD","",IFERROR(INDEX(觀察名單!$Q$2:$Q$533,MATCH($C10,觀察名單!$B$2:$B$533,0)),"")) -> 258.9
A11: 子板塊 | B11: 工程建設/EPC | C11: ACM | D11: =IFERROR(INDEX(觀察名單!$F$2:$F$533,MATCH($C11,觀察名單!$B$2:$B$533,0)),"") -> USD | E11: =IF($D11<>"USD","",IFERROR(INDEX(觀察名單!$L$2:$L$533,MATCH($C11,觀察名單!$B$2:$B$533,0)),"")) -> 3586.067 | F11: =IF($D11<>"USD","",IFERROR(INDEX(觀察名單!$Q$2:$Q$533,MATCH($C11,觀察名單!$B$2:$B$533,0)),"")) -> -68.41
A12: 子板塊 | B12: IT服務與系統整合 | C12: ACN | D12: =IFERROR(INDEX(觀察名單!$F$2:$F$533,MATCH($C12,觀察名單!$B$2:$B$533,0)),"") -> USD | E12: =IF($D12<>"USD","",IFERROR(INDEX(觀察名單!$L$2:$L$533,MATCH($C12,觀察名單!$B$2:$B$533,0)),"")) -> 18718.144 | F12: =IF($D12<>"USD","",IFERROR(INDEX(觀察名單!$Q$2:$Q$533,MATCH($C12,觀察名單!$B$2:$B$533,0)),"")) -> 3175.298
A13: 子板塊 | B13: 企業軟體/SaaS | C13: ADBE | D13: =IFERROR(INDEX(觀察名單!$F$2:$F$533,MATCH($C13,觀察名單!$B$2:$B$533,0)),"") -> USD | E13: =IF($D13<>"USD","",IFERROR(INDEX(觀察名單!$L$2:$L$533,MATCH($C13,觀察名單!$B$2:$B$533,0)),"")) -> 6618 | F13: =IF($D13<>"USD","",IFERROR(INDEX(觀察名單!$Q$2:$Q$533,MATCH($C13,觀察名單!$B$2:$B$533,0)),"")) -> 2238
... A610: AI 小群組 | B610: C2 NAND | C610: WDC | D610: =IFERROR(INDEX(觀察名單!$F$2:$F$533,MATCH($C610,觀察名單!$B$2:$B$533,0)),"") -> USD | E610: =IF($D610<>"USD","",IFERROR(INDEX(觀察名單!$L$2:$L$533,MATCH($C610,觀察名單!$B$2:$B$533,0)),"")) -> 3747 | F610: =IF($D610<>"USD","",IFERROR(INDEX(觀察名單!$Q$2:$Q$533,MATCH($C610,觀察名單!$B$2:$B$533,0)),"")) -> 1606

Sheet 子板塊彙總
A1: # | B1: 群組 | C1: 成分股數 | D1: 營收 Q0 合計 (百萬美元) | E1: 營業利益 Q0 合計 (百萬美元) | F1: 合計營業利益率 % | G1: 盈利成分股數 (營業利益 > 0) | H1: 非美元呈報 (不計入合計) | I1: R4.00 5日資金流向 z | J1: 成分股
A2: 1 | B2: IPP與電力交易商 | C2: 4 | D2: =SUMIFS(明細對照!$E$2:$E$610,明細對照!$A$2:$A$610,"子板塊",明細對照!$B$2:$B$610,$B2) -> 19961 | E2: =SUMIFS(明細對照!$F$2:$F$610,明細對照!$A$2:$A$610,"子板塊",明細對照!$B$2:$B$610,$B2) -> 1600 | F2: =IF(N(D2)=0,"",E2/D2) -> 0.080156305 | G2: =COUNTIFS(明細對照!$A$2:$A$610,"子板塊",明細對照!$B$2:$B$610,$B2,明細對照!$F$2:$F$610,">0") -> 3 | H2: =COUNTIFS(明細對照!$A$2:$A$610,"子板塊",明細對照!$B$2:$B$610,$B2)-COUNTIFS(明細對照!$A$2:$A$610,"子板塊",明細對照!$B$2:$B$610,$B2,明細對照!$D$2:$D$610,"USD") -> 0 | I2: 1.09 | J2: CEG、VST、NRG、TLN
A3: 2 | B3: 記憶體/HBM | C3: 4 | D3: =SUMIFS(明細對照!$E$2:$E$610,明細對照!$A$2:$A$610,"子板塊",明細對照!$B$2:$B$610,$B3) -> 57797 | E3: =SUMIFS(明細對照!$F$2:$F$610,明細對照!$A$2:$A$610,"子板塊",明細對照!$B$2:$B$610,$B3) -> 43524 | F3: =IF(N(D3)=0,"",E3/D3) -> 0.75304947 | G3: =COUNTIFS(明細對照!$A$2:$A$610,"子板塊",明細對照!$B$2:$B$610,$B3,明細對照!$F$2:$F$610,">0") -> 4 | H3: =COUNTIFS(明細對照!$A$2:$A$610,"子板塊",明細對照!$B$2:$B$610,$B3)-COUNTIFS(明細對照!$A$2:$A$610,"子板塊",明細對照!$B$2:$B$610,$B3,明細對照!$D$2:$D$610,"USD") -> 0 | I3: 0.98 | J3: MU、WDC、SNDK、STX
A4: 3 | B4: 數位資產金融與礦業轉HPC | C4: 6 | D4: =SUMIFS(明細對照!$E$2:$E$610,明細對照!$A$2:$A$610,"子板塊",明細對照!$B$2:$B$610,$B4) -> 3715.724 | E4: =SUMIFS(明細對照!$F$2:$F$610,明細對照!$A$2:$A$610,"子板塊",明細對照!$B$2:$B$610,$B4) -> 41.208 | F4: =IF(N(D4)=0,"",E4/D4) -> 0.011090167 | G4: =COUNTIFS(明細對照!$A$2:$A$610,"子板塊",明細對照!$B$2:$B$610,$B4,明細對照!$F$2:$F$610,">0") -> 2 | H4: =COUNTIFS(明細對照!$A$2:$A$610,"子板塊",明細對照!$B$2:$B$610,$B4)-COUNTIFS(明細對照!$A$2:$A$610,"子板塊",明細對照!$B$2:$B$610,$B4,明細對照!$D$2:$D$610,"USD") -> 0 | I4: 0.91 | J4: COIN、HOOD、CRCL、MARA、RIOT、IREN
A5: 4 | B5: 晶圓代工/IDM | C5: 4 | D5: =SUMIFS(明細對照!$E$2:$E$610,明細對照!$A$2:$A$610,"子板塊",明細對照!$B$2:$B$610,$B5) -> 17914 | E5: =SUMIFS(明細對照!$F$2:$F$610,明細對照!$A$2:$A$610,"子板塊",明細對照!$B$2:$B$610,$B5) -> 2140 | F5: =IF(N(D5)=0,"",E5/D5) -> 0.11945964 | G5: =COUNTIFS(明細對照!$A$2:$A$610,"子板塊",明細對照!$B$2:$B$610,$B5,明細對照!$F$2:$F$610,">0") -> 2 | H5: =COUNTIFS(明細對照!$A$2:$A$610,"子板塊",明細對照!$B$2:$B$610,$B5)-COUNTIFS(明細對照!$A$2:$A$610,"子板塊",明細對照!$B$2:$B$610,$B5,明細對照!$D$2:$D$610,"USD") -> 2 | I5: 0.9 | J5: TSM、INTC、GFS、UMC
A6: 5 | B6: 傳統汽車與零部件 | C6: 5 | D6: =SUMIFS(明細對照!$E$2:$E$610,明細對照!$A$2:$A$610,"子板塊",明細對照!$B$2:$B$610,$B6) -> 116785.4 | E6: =SUMIFS(明細對照!$F$2:$F$610,明細對照!$A$2:$A$610,"子板塊",明細對照!$B$2:$B$610,$B6) -> 3370.9 | F6: =IF(N(D6)=0,"",E6/D6) -> 0.028864053 | G6: =COUNTIFS(明細對照!$A$2:$A$610,"子板塊",明細對照!$B$2:$B$610,$B6,明細對照!$F$2:$F$610,">0") -> 5 | H6: =COUNTIFS(明細對照!$A$2:$A$610,"子板塊",明細對照!$B$2:$B$610,$B6)-COUNTIFS(明細對照!$A$2:$A$610,"子板塊",明細對照!$B$2:$B$610,$B6,明細對照!$D$2:$D$610,"USD") -> 0 | I6: 0.79 | J6: GM、F、APTV、LEA、MGA
A7: 6 | B7: 煉油與成品油 | C7: 4 | D7: =SUMIFS(明細對照!$E$2:$E$610,明細對照!$A$2:$A$610,"子板塊",明細對照!$B$2:$B$610,$B7) -> 147474 | E7: =SUMIFS(明細對照!$F$2:$F$610,明細對照!$A$2:$A$610,"子板塊",明細對照!$B$2:$B$610,$B7) -> 16455 | F7: =IF(N(D7)=0,"",E7/D7) -> 0.11157899 | G7: =COUNTIFS(明細對照!$A$2:$A$610,"子板塊",明細對照!$B$2:$B$610,$B7,明細對照!$F$2:$F$610,">0") -> 3 | H7: =COUNTIFS(明細對照!$A$2:$A$610,"子板塊",明細對照!$B$2:$B$610,$B7)-COUNTIFS(明細對照!$A$2:$A$610,"子板塊",明細對照!$B$2:$B$610,$B7,明細對照!$D$2:$D$610,"USD") -> 0 | I7: 0.77 | J7: MPC、PSX、VLO、DINO
A8: 7 | B8: 腫瘤與細胞治療 | C8: 8 | D8: =SUMIFS(明細對照!$E$2:$E$610,明細對照!$A$2:$A$610,"子板塊",明細對照!$B$2:$B$610,$B8) -> 743.235 | E8: =SUMIFS(明細對照!$F$2:$F$610,明細對照!$A$2:$A$610,"子板塊",明細對照!$B$2:$B$610,$B8) -> -475.716 | F8: =IF(N(D8)=0,"",E8/D8) -> -0.64006135 | G8: =COUNTIFS(明細對照!$A$2:$A$610,"子板塊",明細對照!$B$2:$B$610,$B8,明細對照!$F$2:$F$610,">0") -> 2 | H8: =COUNTIFS(明細對照!$A$2:$A$610,"子板塊",明細對照!$B$2:$B$610,$B8)-COUNTIFS(明細對照!$A$2:$A$610,"子板塊",明細對照!$B$2:$B$610,$B8,明細對照!$D$2:$D$610,"USD") -> 0 | I8: 0.69 | J8: LEGN、IOVA、ALLO、ARVN、RVMD、NKTX、FATE、CRVS
A9: 8 | B9: 小型模組化核能SMR | C9: 4 | D9: =SUMIFS(明細對照!$E$2:$E$610,明細對照!$A$2:$A$610,"子板塊",明細對照!$B$2:$B$610,$B9) -> 6.622042 | E9: =SUMIFS(明細對照!$F$2:$F$610,明細對照!$A$2:$A$610,"子板塊",明細對照!$B$2:$B$610,$B9) -> -186.80646 | F9: =IF(N(D9)=0,"",E9/D9) -> -28.209797 | G9: =COUNTIFS(明細對照!$A$2:$A$610,"子板塊",明細對照!$B$2:$B$610,$B9,明細對照!$F$2:$F$610,">0") -> 0 | H9: =COUNTIFS(明細對照!$A$2:$A$610,"子板塊",明細對照!$B$2:$B$610,$B9)-COUNTIFS(明細對照!$A$2:$A$610,"子板塊",明細對照!$B$2:$B$610,$B9,明細對照!$D$2:$D$610,"USD") -> 0 | I9: 0.69 | J9: OKLO、SMR、NNE、ASPI
A10: 9 | B10: 電氣設備與電網 | C10: 5 | D10: =SUMIFS(明細對照!$E$2:$E$610,明細對照!$A$2:$A$610,"子板塊",明細對照!$B$2:$B$610,$B10) -> 22372.797 | E10: =SUMIFS(明細對照!$F$2:$F$610,明細對照!$A$2:$A$610,"子板塊",明細對照!$B$2:$B$610,$B10) -> 1693.331 | F10: =IF(N(D10)=0,"",E10/D10) -> 0.07568705 | G10: =COUNTIFS(明細對照!$A$2:$A$610,"子板塊",明細對照!$B$2:$B$610,$B10,明細對照!$F$2:$F$610,">0") -> 3 | H10: =COUNTIFS(明細對照!$A$2:$A$610,"子板塊",明細對照!$B$2:$B$610,$B10)-COUNTIFS(明細對照!$A$2:$A$610,"子板塊",明細對照!$B$2:$B$610,$B10,明細對照!$D$2:$D$610,"USD") -> 0 | I10: 0.66 | J10: ETN、EMR、PWR、HUBB、GEV
A11: 10 | B11: 樓宇產品與HVAC | C11: 5 | D11: =SUMIFS(明細對照!$E$2:$E$610,明細對照!$A$2:$A$610,"子板塊",明細對照!$B$2:$B$610,$B11) -> 21490.776 | E11: =SUMIFS(明細對照!$F$2:$F$610,明細對照!$A$2:$A$610,"子板塊",明細對照!$B$2:$B$610,$B11) -> 3488.032 | F11: =IF(N(D11)=0,"",E11/D11) -> 0.16230368 | G11: =COUNTIFS(明細對照!$A$2:$A$610,"子板塊",明細對照!$B$2:$B$610,$B11,明細對照!$F$2:$F$610,">0") -> 5 | H11: =COUNTIFS(明細對照!$A$2:$A$610,"子板塊",明細對照!$B$2:$B$610,$B11)-COUNTIFS(明細對照!$A$2:$A$610,"子板塊",明細對照!$B$2:$B$610,$B11,明細對照!$D$2:$D$610,"USD") -> 0 | I11: 0.59 | J11: CARR、TT、JCI、LII、AAON
A12: 11 | B12: 電子硬件與EMS/連接器 | C12: 6 | D12: =SUMIFS(明細對照!$E$2:$E$610,明細對照!$A$2:$A$610,"子板塊",明細對照!$B$2:$B$610,$B12) -> 123328 | E12: =SUMIFS(明細對照!$F$2:$F$610,明細對照!$A$2:$A$610,"子板塊",明細對照!$B$2:$B$610,$B12) -> 37224 | F12: =IF(N(D12)=0,"",E12/D12) -> 0.30182927 | G12: =COUNTIFS(明細對照!$A$2:$A$610,"子板塊",明細對照!$B$2:$B$610,$B12,明細對照!$F$2:$F$610,">0") -> 3 | H12: =COUNTIFS(明細對照!$A$2:$A$610,"子板塊",明細對照!$B$2:$B$610,$B12)-COUNTIFS(明細對照!$A$2:$A$610,"子板塊",明細對照!$B$2:$B$610,$B12,明細對照!$D$2:$D$610,"USD") -> 0 | I12: 0.55 | J12: AAPL、DELL、FLEX、JBL、APH、TEL
A13: 12 | B13: 機械與重工 | C13: 5 | D13: =SUMIFS(明細對照!$E$2:$E$610,明細對照!$A$2:$A$610,"子板塊",明細對照!$B$2:$B$610,$B13) -> 58558.7 | E13: =SUMIFS(明細對照!$F$2:$F$610,明細對照!$A$2:$A$610,"子板塊",明細對照!$B$2:$B$610,$B13) -> 10295.2 | F13: =IF(N(D13)=0,"",E13/D13) -> 0.17580991 | G13: =COUNTIFS(明細對照!$A$2:$A$610,"子板塊",明細對照!$B$2:$B$610,$B13,明細對照!$F$2:$F$610,">0") -> 5 | H13: =COUNTIFS(明細對照!$A$2:$A$610,"子板塊",明細對照!$B$2:$B$610,$B13)-COUNTIFS(明細對照!$A$2:$A$610,"子板塊",明細對照!$B$2:$B$610,$B13,明細對照!$D$2:$D$610,"USD") -> 0 | I13: 0.52 | J13: CAT、DE、CMI、PCAR、HON
... A112: 111 | B112: 食品加工 | C112: 4 | D112: =SUMIFS(明細對照!$E$2:$E$610,明細對照!$A$2:$A$610,"子板塊",明細對照!$B$2:$B$610,$B112) -> 16541.006 | E112: =SUMIFS(明細對照!$F$2:$F$610,明細對照!$A$2:$A$610,"子板塊",明細對照!$B$2:$B$610,$B112) -> 2582.156 | F112: =IF(N(D112)=0,"",E112/D112) -> 0.15610635 | G112: =COUNTIFS(明細對照!$A$2:$A$610,"子板塊",明細對照!$B$2:$B$610,$B112,明細對照!$F$2:$F$610,">0") -> 4 | H112: =COUNTIFS(明細對照!$A$2:$A$610,"子板塊",明細對照!$B$2:$B$610,$B112)-COUNTIFS(明細對照!$A$2:$A$610,"子板塊",明細對照!$B$2:$B$610,$B112,明細對照!$D$2:$D$610,"USD") -> 0 | I112: -0.87 | J112: GIS、KHC、HSY、CAG

Sheet AI小群組彙總
A1: # | B1: 群組 | C1: 成分股數 | D1: 營收 Q0 合計 (百萬美元) | E1: 營業利益 Q0 合計 (百萬美元) | F1: 合計營業利益率 % | G1: 盈利成分股數 (營業利益 > 0) | H1: 非美元呈報 (不計入合計) | I1: R5.00 5日資金流向 z | J1: 成分股
A2: 1 | B2: AA1 Neo | C2: 4 | D2: =SUMIFS(明細對照!$E$2:$E$610,明細對照!$A$2:$A$610,"AI 小群組",明細對照!$B$2:$B$610,$B2) -> 3553.274 | E2: =SUMIFS(明細對照!$F$2:$F$610,明細對照!$A$2:$A$610,"AI 小群組",明細對照!$B$2:$B$610,$B2) -> -490.279 | F2: =IF(N(D2)=0,"",E2/D2) -> -0.13797951 | G2: =COUNTIFS(明細對照!$A$2:$A$610,"AI 小群組",明細對照!$B$2:$B$610,$B2,明細對照!$F$2:$F$610,">0") -> 0 | H2: =COUNTIFS(明細對照!$A$2:$A$610,"AI 小群組",明細對照!$B$2:$B$610,$B2)-COUNTIFS(明細對照!$A$2:$A$610,"AI 小群組",明細對照!$B$2:$B$610,$B2,明細對照!$D$2:$D$610,"USD") -> 0 | I2: 0.77 | J2: APLD、IREN、NBIS、CRWV
A3: 2 | B3: C1 HBM | C3: 1 | D3: =SUMIFS(明細對照!$E$2:$E$610,明細對照!$A$2:$A$610,"AI 小群組",明細對照!$B$2:$B$610,$B3) -> 41456 | E3: =SUMIFS(明細對照!$F$2:$F$610,明細對照!$A$2:$A$610,"AI 小群組",明細對照!$B$2:$B$610,$B3) -> 33318 | F3: =IF(N(D3)=0,"",E3/D3) -> 0.80369548 | G3: =COUNTIFS(明細對照!$A$2:$A$610,"AI 小群組",明細對照!$B$2:$B$610,$B3,明細對照!$F$2:$F$610,">0") -> 1 | H3: =COUNTIFS(明細對照!$A$2:$A$610,"AI 小群組",明細對照!$B$2:$B$610,$B3)-COUNTIFS(明細對照!$A$2:$A$610,"AI 小群組",明細對照!$B$2:$B$610,$B3,明細對照!$D$2:$D$610,"USD") -> 0 | I3: 0.69 | J3: MU
A4: 3 | B4: F2 散熱液冷 | C4: 3 | D4: =SUMIFS(明細對照!$E$2:$E$610,明細對照!$A$2:$A$610,"AI 小群組",明細對照!$B$2:$B$610,$B4) -> 8292.965 | E4: =SUMIFS(明細對照!$F$2:$F$610,明細對照!$A$2:$A$610,"AI 小群組",明細對照!$B$2:$B$610,$B4) -> 1485.237 | F4: =IF(N(D4)=0,"",E4/D4) -> 0.17909602 | G4: =COUNTIFS(明細對照!$A$2:$A$610,"AI 小群組",明細對照!$B$2:$B$610,$B4,明細對照!$F$2:$F$610,">0") -> 3 | H4: =COUNTIFS(明細對照!$A$2:$A$610,"AI 小群組",明細對照!$B$2:$B$610,$B4)-COUNTIFS(明細對照!$A$2:$A$610,"AI 小群組",明細對照!$B$2:$B$610,$B4,明細對照!$D$2:$D$610,"USD") -> 0 | I4: 0.65 | J4: TT、MOD、BE
A5: 4 | B5: G1 其他雲平台 | C5: 2 | D5: =SUMIFS(明細對照!$E$2:$E$610,明細對照!$A$2:$A$610,"AI 小群組",明細對照!$B$2:$B$610,$B5) -> 79985 | E5: =SUMIFS(明細對照!$F$2:$F$610,明細對照!$A$2:$A$610,"AI 小群組",明細對照!$B$2:$B$610,$B5) -> 25730 | F5: =IF(N(D5)=0,"",E5/D5) -> 0.32168532 | G5: =COUNTIFS(明細對照!$A$2:$A$610,"AI 小群組",明細對照!$B$2:$B$610,$B5,明細對照!$F$2:$F$610,">0") -> 2 | H5: =COUNTIFS(明細對照!$A$2:$A$610,"AI 小群組",明細對照!$B$2:$B$610,$B5)-COUNTIFS(明細對照!$A$2:$A$610,"AI 小群組",明細對照!$B$2:$B$610,$B5,明細對照!$D$2:$D$610,"USD") -> 0 | I5: 0.61 | J5: META、ORCL
A6: 5 | B6: E1 Server | C6: 3 | D6: =SUMIFS(明細對照!$E$2:$E$610,明細對照!$A$2:$A$610,"AI 小群組",明細對照!$B$2:$B$610,$B6) -> 11119.777 | E6: =SUMIFS(明細對照!$F$2:$F$610,明細對照!$A$2:$A$610,"AI 小群組",明細對照!$B$2:$B$610,$B6) -> 1488.064 | F6: =IF(N(D6)=0,"",E6/D6) -> 0.13382139 | G6: =COUNTIFS(明細對照!$A$2:$A$610,"AI 小群組",明細對照!$B$2:$B$610,$B6,明細對照!$F$2:$F$610,">0") -> 1 | H6: =COUNTIFS(明細對照!$A$2:$A$610,"AI 小群組",明細對照!$B$2:$B$610,$B6)-COUNTIFS(明細對照!$A$2:$A$610,"AI 小群組",明細對照!$B$2:$B$610,$B6,明細對照!$D$2:$D$610,"USD") -> 0 | I6: 0.52 | J6: SMCI、DELL、HPE
A7: 6 | B7: F3 能源 | C7: 10 | D7: =SUMIFS(明細對照!$E$2:$E$610,明細對照!$A$2:$A$610,"AI 小群組",明細對照!$B$2:$B$610,$B7) -> 21040.224 | E7: =SUMIFS(明細對照!$F$2:$F$610,明細對照!$A$2:$A$610,"AI 小群組",明細對照!$B$2:$B$610,$B7) -> 1547.4945 | F7: =IF(N(D7)=0,"",E7/D7) -> 0.073549338 | G7: =COUNTIFS(明細對照!$A$2:$A$610,"AI 小群組",明細對照!$B$2:$B$610,$B7,明細對照!$F$2:$F$610,">0") -> 5 | H7: =COUNTIFS(明細對照!$A$2:$A$610,"AI 小群組",明細對照!$B$2:$B$610,$B7)-COUNTIFS(明細對照!$A$2:$A$610,"AI 小群組",明細對照!$B$2:$B$610,$B7,明細對照!$D$2:$D$610,"USD") -> 1 | I7: 0.5 | J7: OKLO、NNE、LEU、BWXT、SMR、NRG、CEG、VST、TLN、CCJ
A8: 7 | B8: D5 連接器 | C8: 2 | D8: =SUMIFS(明細對照!$E$2:$E$610,明細對照!$A$2:$A$610,"AI 小群組",明細對照!$B$2:$B$610,$B8) -> 5160 | E8: =SUMIFS(明細對照!$F$2:$F$610,明細對照!$A$2:$A$610,"AI 小群組",明細對照!$B$2:$B$610,$B8) -> 1073 | F8: =IF(N(D8)=0,"",E8/D8) -> 0.20794574 | G8: =COUNTIFS(明細對照!$A$2:$A$610,"AI 小群組",明細對照!$B$2:$B$610,$B8,明細對照!$F$2:$F$610,">0") -> 1 | H8: =COUNTIFS(明細對照!$A$2:$A$610,"AI 小群組",明細對照!$B$2:$B$610,$B8)-COUNTIFS(明細對照!$A$2:$A$610,"AI 小群組",明細對照!$B$2:$B$610,$B8,明細對照!$D$2:$D$610,"USD") -> 0 | I8: 0.49 | J8: APH、TEL
A9: 8 | B9: A1 GPU | C9: 3 | D9: =SUMIFS(明細對照!$E$2:$E$610,明細對照!$A$2:$A$610,"AI 小群組",明細對照!$B$2:$B$610,$B9) -> 123885 | E9: =SUMIFS(明細對照!$F$2:$F$610,明細對照!$A$2:$A$610,"AI 小群組",明細對照!$B$2:$B$610,$B9) -> 67690 | F9: =IF(N(D9)=0,"",E9/D9) -> 0.54639383 | G9: =COUNTIFS(明細對照!$A$2:$A$610,"AI 小群組",明細對照!$B$2:$B$610,$B9,明細對照!$F$2:$F$610,">0") -> 3 | H9: =COUNTIFS(明細對照!$A$2:$A$610,"AI 小群組",明細對照!$B$2:$B$610,$B9)-COUNTIFS(明細對照!$A$2:$A$610,"AI 小群組",明細對照!$B$2:$B$610,$B9,明細對照!$D$2:$D$610,"USD") -> 0 | I9: 0.49 | J9: NVDA、AMD、INTC
A10: 9 | B10: F1 電源 | C10: 7 | D10: =SUMIFS(明細對照!$E$2:$E$610,明細對照!$A$2:$A$610,"AI 小群組",明細對照!$B$2:$B$610,$B10) -> 33506.807 | E10: =SUMIFS(明細對照!$F$2:$F$610,明細對照!$A$2:$A$610,"AI 小群組",明細對照!$B$2:$B$610,$B10) -> 3193.064 | F10: =IF(N(D10)=0,"",E10/D10) -> 0.09529598 | G10: =COUNTIFS(明細對照!$A$2:$A$610,"AI 小群組",明細對照!$B$2:$B$610,$B10,明細對照!$F$2:$F$610,">0") -> 5 | H10: =COUNTIFS(明細對照!$A$2:$A$610,"AI 小群組",明細對照!$B$2:$B$610,$B10)-COUNTIFS(明細對照!$A$2:$A$610,"AI 小群組",明細對照!$B$2:$B$610,$B10,明細對照!$D$2:$D$610,"USD") -> 1 | I10: 0.41 | J10: PWR、VRT、ETN、SBGSY、GEV、GNRC、CMI
A11: 10 | B11: D6 光纖 | C11: 1 | D11: =SUMIFS(明細對照!$E$2:$E$610,明細對照!$A$2:$A$610,"AI 小群組",明細對照!$B$2:$B$610,$B11) -> 4505 | E11: =SUMIFS(明細對照!$F$2:$F$610,明細對照!$A$2:$A$610,"AI 小群組",明細對照!$B$2:$B$610,$B11) -> 698 | F11: =IF(N(D11)=0,"",E11/D11) -> 0.15493896 | G11: =COUNTIFS(明細對照!$A$2:$A$610,"AI 小群組",明細對照!$B$2:$B$610,$B11,明細對照!$F$2:$F$610,">0") -> 1 | H11: =COUNTIFS(明細對照!$A$2:$A$610,"AI 小群組",明細對照!$B$2:$B$610,$B11)-COUNTIFS(明細對照!$A$2:$A$610,"AI 小群組",明細對照!$B$2:$B$610,$B11,明細對照!$D$2:$D$610,"USD") -> 0 | I11: 0.28 | J11: GLW
A12: 11 | B12: C2 NAND | C12: 3 | D12: =SUMIFS(明細對照!$E$2:$E$610,明細對照!$A$2:$A$610,"AI 小群組",明細對照!$B$2:$B$610,$B12) -> 16341 | E12: =SUMIFS(明細對照!$F$2:$F$610,明細對照!$A$2:$A$610,"AI 小群組",明細對照!$B$2:$B$610,$B12) -> 10206 | F12: =IF(N(D12)=0,"",E12/D12) -> 0.62456398 | G12: =COUNTIFS(明細對照!$A$2:$A$610,"AI 小群組",明細對照!$B$2:$B$610,$B12,明細對照!$F$2:$F$610,">0") -> 3 | H12: =COUNTIFS(明細對照!$A$2:$A$610,"AI 小群組",明細對照!$B$2:$B$610,$B12)-COUNTIFS(明細對照!$A$2:$A$610,"AI 小群組",明細對照!$B$2:$B$610,$B12,明細對照!$D$2:$D$610,"USD") -> 0 | I12: 0.2 | J12: SNDK、WDC、STX
A13: 12 | B13: B1 Foundry | C13: 2 | D13: =SUMIFS(明細對照!$E$2:$E$610,明細對照!$A$2:$A$610,"AI 小群組",明細對照!$B$2:$B$610,$B13) -> 1786 | E13: =SUMIFS(明細對照!$F$2:$F$610,明細對照!$A$2:$A$610,"AI 小群組",明細對照!$B$2:$B$610,$B13) -> 174 | F13: =IF(N(D13)=0,"",E13/D13) -> 0.097424412 | G13: =COUNTIFS(明細對照!$A$2:$A$610,"AI 小群組",明細對照!$B$2:$B$610,$B13,明細對照!$F$2:$F$610,">0") -> 1 | H13: =COUNTIFS(明細對照!$A$2:$A$610,"AI 小群組",明細對照!$B$2:$B$610,$B13)-COUNTIFS(明細對照!$A$2:$A$610,"AI 小群組",明細對照!$B$2:$B$610,$B13,明細對照!$D$2:$D$610,"USD") -> 1 | I13: 0.2 | J13: TSM、GFS
... A34: 33 | B34: B5 EDA | C34: 2 | D34: =SUMIFS(明細對照!$E$2:$E$610,明細對照!$A$2:$A$610,"AI 小群組",明細對照!$B$2:$B$610,$B34) -> 4061.273 | E34: =SUMIFS(明細對照!$F$2:$F$610,明細對照!$A$2:$A$610,"AI 小群組",明細對照!$B$2:$B$610,$B34) -> 809.618 | F34: =IF(N(D34)=0,"",E34/D34) -> 0.19935079 | G34: =COUNTIFS(明細對照!$A$2:$A$610,"AI 小群組",明細對照!$B$2:$B$610,$B34,明細對照!$F$2:$F$610,">0") -> 2 | H34: =COUNTIFS(明細對照!$A$2:$A$610,"AI 小群組",明細對照!$B$2:$B$610,$B34)-COUNTIFS(明細對照!$A$2:$A$610,"AI 小群組",明細對照!$B$2:$B$610,$B34,明細對照!$D$2:$D$610,"USD") -> 0 | I34: -1.37 | J34: SNPS、CDNS

Sheet 分級彙總
A1: 級 | B1: 定義（營業利益口徑） | C1: 數量 | D1: 佔比 | E1: Tickers
A2: A | B2: 四季營業利益全部為正 —— 持續盈利 | C2: =COUNTIF(觀察名單!$AA$2:$AA$533,$A2) -> 350 | D2: =IF(N($C$7)=0,"",C2/$C$7) -> 0.65789474 | E2: A、AAON、AAPL、ABBV、ACN、ADBE、ADI、ADM、ADP、AEM、AEP、AFL、AFRM、AG、AIG、AJG、ALAB、AMAT、AMD、AMG、AMGN、AMH、AMKR、AMT、ANET、AON、APD、APO、APTV、ARES、ARM、ASML、ASX、ATO、AU、AWK、AWR、BC、BE、BEN、BG、BIDU、BIIB、BJ、BKR、BLK、BMY、BRO、BWXT、BXP、CAG、CAH、CAMT、CARR、CAT、CB、CBOE、CBRE、CCI、CCJ、CCL、CDE、CDNS、CELH、CENX、CF、CHEF、CHTR、CHWY、CI、CIEN、CL、CLH、CMCSA、CME、CMG、CMI、COHR、COP、COR、COST、CRCL、CRDO、CRM、CSCO、CSX、CTAS、CTSH、CVS、CVX、CWST、CWT、DAL、DE、DECK、DHI、DHR、DIS、DOC、DOCS、DRI、DUOL、DVN、EBAY、ECL、EE、EGP、EHC、EL、ELV、EME、EPAM、EPD、EQIX、ET、FANG、FCX、FDX、FN、FR、FRT、FSLR、FTNT、FWONK、GD、GEV、GFS、GILD、GIS、GLNG、GLPI、GLW、GOLD、GOOGL、HAL、HBM、HCA、HCC、HD、HLT、HON、HOOD、HSY、HTO、HUBB、IBM、ICE、INFY、INGR、INTC、INVH、IPGP、ISRG、JBHT、JBL、JCI、JEF、JLL、JNJ、KALU、KDP、KGC、KHC、KIM、KKR、KLAC、KMB、KMI、KO、LAMR、LEA、LEN、LHX、LII、LIN、LITE、LLY、LMT、LOW、LRCX、LRN、LULU、LUV、LVS、MA、MAA、MAN、MAR、MCD、MCK、MDT、MET、META、MGA、MGM、MLM、MNST、MO、MOD、MPC、MPWR、MRVL、MSFT、MTCH、MTSI、MTZ、MU、NCLH、NDAQ、NDSN、NE、NEE、NEM、NFLX、NI、NJR、NKE、NOC、NOW、NRG、NSC、NTR、NUE、NVDA、NVO、NVR、NWSA、NXPI、NXT、O、ODFL、OHI、OKE、ON、ONON、ONTO、ORCL、OWL、OXY、PAAS、PAYX、PCAR、PEP、PFE、PFGC、PG、PGR、PHM、PKG、PLD、PLTR、PM、POOL、PSA、PSX、PWR、PYPL、QCOM、RCL、RDDT、REGN、RGLD、RIG、RL、RMBS、RNR、ROK、ROKU、ROST、RS、RSG、RTX、SBAC、SBUX、SCCO、SCI、SHOP、SHW、SIMO、SLB、SMCI、SMTC、SNDK、SNPS、SO、SPG、SPGI、STAG、STLD、STX、STZ、SYK、SYY、T、TAP、TDW、TECK、TEL、TER、THC、TJX、TMO、TMUS、TOL、TOST、TPB、TROW、TRV、TSEM、TSLA、TSM、TSN、TT、TXN、UAL、UHS、UMC、UNH、UNP、UPS、USFD、V、VAL、VG、VIAV、VICI、VLO、VMC、VNO、VRT、VRTX、VST、VTR、VZ、W、WBD、WCN、WDAY、WDC、WFRD、WHR、WM、WMB、WMT、WTRG、WTW、XEL、XOM、XPO、YUM
A3: B | B3: 最新季營業利益為正，但四季之中有負 —— 剛轉正或有波動 | C3: =COUNTIF(觀察名單!$AA$2:$AA$533,$A3) -> 41 | D3: =IF(N($C$7)=0,"",C3/$C$7) -> 0.077067669 | E3: AA、AAL、ACI、ALB、ARVN、AVAV、AXTI、BABA、CNC、CNR、COMP、CRH、DDOG、DOW、ENPH、F、FLR、GM、GNRC、GPN、HRB、HUM、IP、J、KR、LEGN、LEU、LNC、LNG、LYB、LYV、MDB、OSCR、PLTK、RUN、SLG、SR、SYM、TEAM、TLN、Z
A4: C | B4: 最新季營業利益為負，但較 Q-3 收窄 —— 虧損收窄 | C4: =COUNTIF(觀察名單!$AA$2:$AA$533,$A4) -> 33 | D4: =IF(N($C$7)=0,"",C4/$C$7) -> 0.062030075 | E4: AEHR、ALEC、BEAM、CLF、CRSP、CRWD、DKNG、DNLI、DNN、DTIL、EQH、FATE、FLUT、IONS、IOVA、LASR、LPTH、MDGL、MP、PARA、PL、RBLX、RDW、RIVN、RKLB、RXT、S、SMR、SOUN、TDOC、TTWO、UUUU、ZS
A5: D | B5: 最新季營業利益為負且較 Q-3 擴大（或由正轉負） —— 惡化 | C5: =COUNTIF(觀察名單!$AA$2:$AA$533,$A5) -> 54 | D5: =IF(N($C$7)=0,"",C5/$C$7) -> 0.10150376 | E5: AAOI、ACM、ALLO、ALOY、ALT、AMR、AMS、APLD、ASPI、ASTS、BTU、CEG、COIN、CRVS、CRWV、HIMS、IONQ、IREN、KTOS、LCID、LUNR、LWLG、MARA、METC、MOS、MRK、NB、NBIS、NET、NFE、NKTX、NNE、NTLA、OKLO、ONDS、OPEN、PANW、PINS、POET、PRIM、QBTS、QUBT、RCAT、RGTI、RHI、RIOT、RVMD、SANA、SNAP、TMC、UEC、USAR、VECO、VKTX
A6: — | B6: 四季營業利益唔齊，無法判定 | C6: =COUNTIF(觀察名單!$AA$2:$AA$533,$A6) -> 54 | D6: =IF(N($C$7)=0,"",C6/$C$7) -> 0.10150376 | E6: ABT、AI、AMZN、APH、AVGO、AXP、BA、BAC、BBY、BF.B、BSX、BX、C、CHD、COF、CTVA、D、DELL、DEO、DINO、DLR、DUK、EMR、EOG、ETN、EVR、EXR、FLEX、FORM、GS、HIW、HL、HPE、ILMN、JPM、LAZ、MHK、MS、MTB、NTAP、PNC、PRU、REG、SBGSY、SNOW、SOFI、SYF、TCEHY、TFC、UPST、USB、WELL、WFC、ZION
B7: 合計 | C7: =SUM(C2:C6) -> 532

Sheet 圖表連結
A1: # | B1: 美股 | C1: 公司 | D1: 級 | E1: 純文字 URL
A2: 1 | B2: A | C2: Agilent Technologies, Inc. | D2: =IFERROR(INDEX(觀察名單!$AA$2:$AA$533,MATCH($B2,觀察名單!$B$2:$B$533,0)),"") -> A | E2: https://www.tradingview.com/chart/Q1c5VWwD/?symbol=a
A3: 2 | B3: AA | C3: Alcoa Corporation | D3: =IFERROR(INDEX(觀察名單!$AA$2:$AA$533,MATCH($B3,觀察名單!$B$2:$B$533,0)),"") -> B | E3: https://www.tradingview.com/chart/Q1c5VWwD/?symbol=aa
A4: 3 | B4: AAL | C4: American Airlines Group Inc. | D4: =IFERROR(INDEX(觀察名單!$AA$2:$AA$533,MATCH($B4,觀察名單!$B$2:$B$533,0)),"") -> B | E4: https://www.tradingview.com/chart/Q1c5VWwD/?symbol=aal
A5: 4 | B5: AAOI | C5: Applied Optoelectronics, Inc. | D5: =IFERROR(INDEX(觀察名單!$AA$2:$AA$533,MATCH($B5,觀察名單!$B$2:$B$533,0)),"") -> D | E5: https://www.tradingview.com/chart/Q1c5VWwD/?symbol=aaoi
A6: 5 | B6: AAON | C6: AAON, Inc. | D6: =IFERROR(INDEX(觀察名單!$AA$2:$AA$533,MATCH($B6,觀察名單!$B$2:$B$533,0)),"") -> A | E6: https://www.tradingview.com/chart/Q1c5VWwD/?symbol=aaon
A7: 6 | B7: AAPL | C7: Apple Inc. | D7: =IFERROR(INDEX(觀察名單!$AA$2:$AA$533,MATCH($B7,觀察名單!$B$2:$B$533,0)),"") -> A | E7: https://www.tradingview.com/chart/Q1c5VWwD/?symbol=aapl
A8: 7 | B8: ABBV | C8: AbbVie Inc. | D8: =IFERROR(INDEX(觀察名單!$AA$2:$AA$533,MATCH($B8,觀察名單!$B$2:$B$533,0)),"") -> A | E8: https://www.tradingview.com/chart/Q1c5VWwD/?symbol=abbv
A9: 8 | B9: ABT | C9: Abbott Laboratories | D9: =IFERROR(INDEX(觀察名單!$AA$2:$AA$533,MATCH($B9,觀察名單!$B$2:$B$533,0)),"") -> — | E9: https://www.tradingview.com/chart/Q1c5VWwD/?symbol=abt
A10: 9 | B10: ACI | C10: Albertsons Companies, Inc. | D10: =IFERROR(INDEX(觀察名單!$AA$2:$AA$533,MATCH($B10,觀察名單!$B$2:$B$533,0)),"") -> B | E10: https://www.tradingview.com/chart/Q1c5VWwD/?symbol=aci
A11: 10 | B11: ACM | C11: AECOM | D11: =IFERROR(INDEX(觀察名單!$AA$2:$AA$533,MATCH($B11,觀察名單!$B$2:$B$533,0)),"") -> D | E11: https://www.tradingview.com/chart/Q1c5VWwD/?symbol=acm
A12: 11 | B12: ACN | C12: Accenture plc | D12: =IFERROR(INDEX(觀察名單!$AA$2:$AA$533,MATCH($B12,觀察名單!$B$2:$B$533,0)),"") -> A | E12: https://www.tradingview.com/chart/Q1c5VWwD/?symbol=acn
A13: 12 | B13: ADBE | C13: Adobe Inc. | D13: =IFERROR(INDEX(觀察名單!$AA$2:$AA$533,MATCH($B13,觀察名單!$B$2:$B$533,0)),"") -> A | E13: https://www.tradingview.com/chart/Q1c5VWwD/?symbol=adbe
... A533: 532 | B533: ZS | C533: Zscaler, Inc. | D533: =IFERROR(INDEX(觀察名單!$AA$2:$AA$533,MATCH($B533,觀察名單!$B$2:$B$533,0)),"") -> C | E533: https://www.tradingview.com/chart/Q1c5VWwD/?symbol=zs

Sheet 資料來源
A1: 類別 | B1: 來源 | C1: 用途 | D1: 備註 / 連結
A2: 財報數字 | B2: Yahoo Finance（yfinance income_stmt / quarterly_income_stmt） | C2: 營收、毛利、營業利益、淨利、年度數字 | D2: 由 GitHub Actions runner 拉取（研究容器無法連 Yahoo），檔案 data/yahoo/fundamentals_income.csv
A3: 公司資料 | B3: Yahoo Finance（yfinance info） | C3: 公司名稱、呈報幣別、行業分類 | D3: data/yahoo/fundamentals_profile.csv
A4: 成分股名單 | B4: Sub-Sector 資金流向 Watchlist R4.00 | C4: C 欄子板塊歸屬（491 隻） | D4: 計分視窗至 2026-09-04 收盤；data/subsector_flow4.json
A5: 成分股名單 | B5: AI Sector 資金流向 Watchlist R5.00 | C5: E 欄 AI 小群組歸屬（111 隻） | D5: 計分視窗至 2026-09-04 收盤；data/ai_flow5.json
A6: 圖表 | B6: TradingView | C6: B 欄與「圖表連結」分頁 | D6: 沿用 layout /chart/Q1c5VWwD/
A7: 免責 | B7: — | C7: — | D7: 本表為公開資料整理與研究參考，非投資建議；財務數據以各公司正式公告為準。
